Workbook

Sheet Summary
A1: Regulated Sportsbooks & the Underserved Spanish-Speaking Bettor — A Structural-Access Thesis
A2: Equity research support model | Regulated (non-tribal) OSB industry, with DraftKings as a labeled subset | Prediction Markets & FIFA World Cup 2026
A4: THESIS
A5: The under-representation of Spanish-speaking consumers in U.S. sportsbooks is an INDUSTRY-WIDE structural-access problem, not a DraftKings-specific one. The largest Hispanic states — California and Texas (no legal OSB) and Florida (a tribal Seminole/Hard Rock compact, outside the regulated commercial market) — leave the majority of the U.S. Hispanic population beyond the reach of any regulated, non-tribal online sportsbook. CFTC-regulated Prediction markets (≈nationwide) plus newly launched Spanish-language apps are the first vehicles into this base, with FIFA World Cup 2026 — co-hosted across high-Hispanic U.S. metros — as the catalyst. Counter-case: 72% English proficiency shrinks the incremental Spanish-only TAM, and soccer/Spanish-dominant cohorts may monetize below the NFL-driven core. Both sides quantified herein.
A10: KEY FINDINGS (calculated live from 'State Detail')
A11: Metric | B11: Hispanic Population | C11: % of U.S. Hispanic Pop. | D11: Read-through
A12: Total U.S. Hispanic population | B12: ='State Detail'!$B$55 -> 64759437 | C12: — | D12: Census ACS 2024 (~64.8m; Pew cites ~68m broader basis).
A13: Reachable by ANY regulated (non-tribal) OSB | B13: ='State Detail'!$L$55 -> 23970649 | C13: ='State Detail'!$L$55/'State Detail'!$B$55 -> 0.37014913 | D13: Whole industry reaches only ~1/3 of Hispanics.
A14: UNREACHABLE by regulated OSB — Predictions/Spanish wedge | B14: ='State Detail'!$M$55 -> 40788788 | C14: ='State Detail'!$M$55/'State Detail'!$B$55 -> 0.62985087 | D14: Core opportunity set; served only via Predictions + Spanish app.
A15: Of which: California + Texas + Florida | B15: ='State Detail'!$B$4+'State Detail'!$B$5+'State Detail'!$B$6 -> 33916660 | C15: =('State Detail'!$B$4+'State Detail'!$B$5+'State Detail'!$B$6)/'State Detail'!$B$55 -> 0.52373309 | D15: 3 largest Hispanic states — none in the regulated commercial market.
A16: Subset: reachable by DraftKings specifically | B16: =SUMIF('State Detail'!$G$4:$G$54,1,'State Detail'!$B$4:$B$54) -> 22638178 | C16: =SUMIF('State Detail'!$G$4:$G$54,1,'State Detail'!$B$4:$B$54)/'State Detail'!$B$55 -> 0.34957342 | D16: DK ⊂ industry; gap is ~industry-wide, not DK-specific.
A17: Reachable by DK iCasino (online casino) | B17: =SUMIF('State Detail'!$I$4:$I$54,1,'State Detail'!$B$4:$B$54) -> 4526971 | C17: =SUMIF('State Detail'!$I$4:$I$54,1,'State Detail'!$B$4:$B$54)/'State Detail'!$B$55 -> 0.069904422 | D17: Confirms '~90% of country not present for iGaming'.
A18: Live in a World Cup 2026 U.S. host state | B18: =SUMIF('State Detail'!$K$4:$K$54,"<>",'State Detail'!$B$4:$B$54) -> 40740362 | C18: =SUMIF('State Detail'!$K$4:$K$54,"<>",'State Detail'!$B$4:$B$54)/'State Detail'!$B$55 -> 0.62910309 | D18: WC reaches the Hispanic base at unprecedented scale.
A19: Live in a WC host state with NO regulated OSB | B19: =SUMIFS('State Detail'!$B$4:$B$54,'State Detail'!$K$4:$K$54,"<>",'State Detail'!$F$4:$F$54,0) -> 36244890 | C19: =SUMIFS('State Detail'!$B$4:$B$54,'State Detail'!$K$4:$K$54,"<>",'State Detail'!$F$4:$F$54,0)/'State Detail'!$B$55 -> 0.55968507 | D19: Bullseye: WC engagement in Predictions-only territory.
A21: TAB GUIDE
A22: • State Detail — 51-row workhorse. 'Reg. OSB' flag (non-tribal mobile market) drives all headline math; 'DK OSB' flag retained as the operator subset.
A23: • Spanish-App TAM Funnel — sizes the INCREMENTAL Spanish-only TAM after the 72% English-proficiency haircut. Yellow cells are flexible assumptions.
A24: • Factors & Counter-Analysis — every supporting vs. challenging analysis with data point + source.
A25: • Representation Index — Hispanic share of the regulated-OSB footprint vs. national (coverage, evidenced) and a placeholder for customer-mix (participation, needs data).
A26: • Sources — citations with publishers, dates, URLs, plus the OSB classification rules.
A28: Color key: blue = input/assumption • black = formula • green = cross-tab link. Built for analyst use; not investment advice.

Sheet State Detail
A1: State-Level Detail — Hispanic Population vs. Regulated (Non-Tribal) OSB Access, DraftKings Footprint & World Cup 2026
A2: Hispanic & total population: Census ACS 2024 (via World Population Review). 'Regulated OSB' = legal statewide-mobile commercial/lottery online sportsbook, EXCLUDING tribal-compact markets (incl. Florida), tribal-on-land-only, and retail/on-premise-only states. 'DK OSB' = DraftKings operates there. Flags: 1=yes,0=no. See Sources.
A3: State | B3: Hispanic Pop. 2024 | C3: Total Pop. 2024 | D3: Hispanic % of State | E3: OSB Market Type (regulated = non-tribal mobile) | F3: Reg. OSB | G3: DK OSB | H3: iGaming Legal | I3: DK iCasino | J3: Predictions Access | K3: World Cup 2026 U.S. Host City | L3: Hispanic Pop. Reachable via Regulated OSB | M3: Hispanic Pop. Unreachable (Predictions-only)
A4: California | B4: 15779000 | C4: 39287400 | D4: =B4/C4 -> 0.40163004 | E4: Not legalized (excluded) | F4: 0 | G4: 0 | H4: 0 | I4: 0 | J4: Yes (national, CFTC) | K4: Los Angeles; SF Bay Area | L4: =IF(F4=1,B4,0) -> 0 | M4: =IF(F4=0,B4,0) -> 15779000
A5: Texas | B5: 11991500 | C5: 30188400 | D5: =B5/C5 -> 0.39722211 | E5: Not legalized (excluded) | F5: 0 | G5: 0 | H5: 0 | I5: 0 | J5: Yes (national, CFTC) | K5: Dallas; Houston | L5: =IF(F5=1,B5,0) -> 0 | M5: =IF(F5=0,B5,0) -> 11991500
A6: Florida | B6: 6146160 | C6: 22416100 | D6: =B6/C6 -> 0.27418507 | E6: Tribal compact – Hard Rock (excluded as tribal) | F6: 0 | G6: 0 | H6: 0 | I6: 0 | J6: Yes (national, CFTC) | K6: Miami | L6: =IF(F6=1,B6,0) -> 0 | M6: =IF(F6=0,B6,0) -> 6146160
A7: New York | B7: 3936080 | C7: 19852400 | D7: =B7/C7 -> 0.19826721 | E7: Open commercial (statewide mobile) | F7: 1 | G7: 1 | H7: 0 | I7: 0 | J7: Yes (national, CFTC) | L7: =IF(F7=1,B7,0) -> 3936080 | M7: =IF(F7=0,B7,0) -> 0
A8: Illinois | B8: 2387050 | C8: 12694800 | D8: =B8/C8 -> 0.18803368 | E8: Open commercial (statewide mobile) | F8: 1 | G8: 1 | H8: 0 | I8: 0 | J8: Yes (national, CFTC) | L8: =IF(F8=1,B8,0) -> 2387050 | M8: =IF(F8=0,B8,0) -> 0
A9: Arizona | B9: 2313810 | C9: 7378840 | D9: =B9/C9 -> 0.31357368 | E9: Open commercial (statewide mobile) | F9: 1 | G9: 1 | H9: 0 | I9: 0 | J9: Yes (national, CFTC) | L9: =IF(F9=1,B9,0) -> 2313810 | M9: =IF(F9=0,B9,0) -> 0
A10: New Jersey | B10: 2098960 | C10: 9343810 | D10: =B10/C10 -> 0.22463642 | E10: Open commercial (statewide mobile) | F10: 1 | G10: 1 | H10: 1 | I10: 1 | J10: Yes (national, CFTC) | K10: New York/New Jersey | L10: =IF(F10=1,B10,0) -> 2098960 | M10: =IF(F10=0,B10,0) -> 0
A11: Colorado | B11: 1320940 | C11: 5862190 | D11: =B11/C11 -> 0.22533217 | E11: Open commercial (statewide mobile) | F11: 1 | G11: 1 | H11: 0 | I11: 0 | J11: Yes (national, CFTC) | L11: =IF(F11=1,B11,0) -> 1320940 | M11: =IF(F11=0,B11,0) -> 0
A12: North Carolina | B12: 1213850 | C12: 10730400 | D12: =B12/C12 -> 0.11312253 | E12: Open commercial (statewide mobile) | F12: 1 | G12: 1 | H12: 0 | I12: 0 | J12: Yes (national, CFTC) | L12: =IF(F12=1,B12,0) -> 1213850 | M12: =IF(F12=0,B12,0) -> 0
A13: Georgia | B13: 1204620 | C13: 10940400 | D13: =B13/C13 -> 0.11010749 | E13: Not legalized (excluded) | F13: 0 | G13: 0 | H13: 0 | I13: 0 | J13: Yes (national, CFTC) | K13: Atlanta | L13: =IF(F13=1,B13,0) -> 0 | M13: =IF(F13=0,B13,0) -> 1204620
A14: Pennsylvania | B14: 1135280 | C14: 13018600 | D14: =B14/C14 -> 0.087204461 | E14: Open commercial (statewide mobile) | F14: 1 | G14: 1 | H14: 1 | I14: 1 | J14: Yes (national, CFTC) | K14: Philadelphia | L14: =IF(F14=1,B14,0) -> 1135280 | M14: =IF(F14=0,B14,0) -> 0
A15: Washington | B15: 1123610 | C15: 7816120 | D15: =B15/C15 -> 0.14375547 | E15: Tribal – on-land only (excluded) | F15: 0 | G15: 0 | H15: 0 | I15: 0 | J15: Yes (national, CFTC) | K15: Seattle | L15: =IF(F15=1,B15,0) -> 0 | M15: =IF(F15=0,B15,0) -> 1123610
A16: New Mexico | B16: 1026610 | C16: 2120250 | D16: =B16/C16 -> 0.4841929 | E16: Tribal – on-land only (excluded) | F16: 0 | G16: 0 | H16: 0 | I16: 0 | J16: Yes (national, CFTC) | L16: =IF(F16=1,B16,0) -> 0 | M16: =IF(F16=0,B16,0) -> 1026610
A17: Virginia | B17: 959089 | C17: 8705170 | D17: =B17/C17 -> 0.11017464 | E17: Open commercial (statewide mobile) | F17: 1 | G17: 1 | H17: 0 | I17: 0 | J17: Yes (national, CFTC) | L17: =IF(F17=1,B17,0) -> 959089 | M17: =IF(F17=0,B17,0) -> 0
A18: Nevada | B18: 943569 | C18: 3184610 | D18: =B18/C18 -> 0.29629028 | E18: Open commercial (in-person registration) | F18: 1 | G18: 0 | H18: 0 | I18: 0 | J18: Yes (national, CFTC) | L18: =IF(F18=1,B18,0) -> 943569 | M18: =IF(F18=0,B18,0) -> 0
A19: Massachusetts | B19: 936853 | C19: 7044060 | D19: =B19/C19 -> 0.13299901 | E19: Open commercial (statewide mobile) | F19: 1 | G19: 1 | H19: 0 | I19: 0 | J19: Yes (national, CFTC) | K19: Boston (Foxborough) | L19: =IF(F19=1,B19,0) -> 936853 | M19: =IF(F19=0,B19,0) -> 0
A20: Maryland | B20: 774946 | C20: 6206010 | D20: =B20/C20 -> 0.12487025 | E20: Open commercial (statewide mobile) | F20: 1 | G20: 1 | H20: 0 | I20: 0 | J20: Yes (national, CFTC) | L20: =IF(F20=1,B20,0) -> 774946 | M20: =IF(F20=0,B20,0) -> 0
A21: Connecticut | B21: 662511 | C21: 3624510 | D21: =B21/C21 -> 0.18278636 | E21: Open commercial (statewide mobile) | F21: 1 | G21: 1 | H21: 1 | I21: 1 | J21: Yes (national, CFTC) | L21: =IF(F21=1,B21,0) -> 662511 | M21: =IF(F21=0,B21,0) -> 0
A22: Oregon | B22: 624598 | C22: 4254290 | D22: =B22/C22 -> 0.14681604 | E22: Lottery-operated mobile (commercial) | F22: 1 | G22: 1 | H22: 0 | I22: 0 | J22: Yes (national, CFTC) | L22: =IF(F22=1,B22,0) -> 624598 | M22: =IF(F22=0,B22,0) -> 0
A23: Michigan | B23: 592045 | C23: 10077800 | D23: =B23/C23 -> 0.058747445 | E23: Open commercial (statewide mobile) | F23: 1 | G23: 1 | H23: 1 | I23: 1 | J23: Yes (national, CFTC) | L23: =IF(F23=1,B23,0) -> 592045 | M23: =IF(F23=0,B23,0) -> 0
A24: Indiana | B24: 590348 | C24: 6851070 | D24: =B24/C24 -> 0.08616873 | E24: Open commercial (statewide mobile) | F24: 1 | G24: 1 | H24: 0 | I24: 0 | J24: Yes (national, CFTC) | L24: =IF(F24=1,B24,0) -> 590348 | M24: =IF(F24=0,B24,0) -> 0
A25: Ohio | B25: 562740 | C25: 11810300 | D25: =B25/C25 -> 0.047648239 | E25: Open commercial (statewide mobile) | F25: 1 | G25: 1 | H25: 0 | I25: 0 | J25: Yes (national, CFTC) | L25: =IF(F25=1,B25,0) -> 562740 | M25: =IF(F25=0,B25,0) -> 0
A26: Utah | B26: 539620 | C26: 3392330 | D26: =B26/C26 -> 0.15907061 | E26: All gambling banned (excluded) | F26: 0 | G26: 0 | H26: 0 | I26: 0 | J26: Yes (national, CFTC) | L26: =IF(F26=1,B26,0) -> 0 | M26: =IF(F26=0,B26,0) -> 539620
A27: Tennessee | B27: 523528 | C27: 7066380 | D27: =B27/C27 -> 0.074087156 | E27: Open commercial (statewide mobile) | F27: 1 | G27: 1 | H27: 0 | I27: 0 | J27: Yes (national, CFTC) | L27: =IF(F27=1,B27,0) -> 523528 | M27: =IF(F27=0,B27,0) -> 0
A28: Oklahoma | B28: 510804 | C28: 4028630 | D28: =B28/C28 -> 0.12679348 | E28: Not legalized (excluded) | F28: 0 | G28: 0 | H28: 0 | I28: 0 | J28: Yes (national, CFTC) | L28: =IF(F28=1,B28,0) -> 0 | M28: =IF(F28=0,B28,0) -> 510804
A29: Wisconsin | B29: 471930 | C29: 5914870 | D29: =B29/C29 -> 0.079787045 | E29: Tribal – on-land only (excluded) | F29: 0 | G29: 0 | H29: 0 | I29: 0 | J29: Yes (national, CFTC) | L29: =IF(F29=1,B29,0) -> 0 | M29: =IF(F29=0,B29,0) -> 471930
A30: Kansas | B30: 400018 | C30: 2947200 | D30: =B30/C30 -> 0.13572815 | E30: Open commercial (statewide mobile) | F30: 1 | G30: 1 | H30: 0 | I30: 0 | J30: Yes (national, CFTC) | L30: =IF(F30=1,B30,0) -> 400018 | M30: =IF(F30=0,B30,0) -> 0
A31: South Carolina | B31: 390376 | C31: 5296220 | D31: =B31/C31 -> 0.073708418 | E31: Not legalized (excluded) | F31: 0 | G31: 0 | H31: 0 | I31: 0 | J31: Yes (national, CFTC) | L31: =IF(F31=1,B31,0) -> 0 | M31: =IF(F31=0,B31,0) -> 390376
... A33: Louisiana | B33: 332716 | C33: 4611960 | D33: =B33/C33 -> 0.072141996 | E33: Open commercial (statewide mobile) | F33: 1 | G33: 1 | H33: 0 | I33: 0 | J33: Yes (national, CFTC) | L33: =IF(F33=1,B33,0) -> 332716 | M33: =IF(F33=0,B33,0) -> 0
A34: Missouri | B34: 324379 | C34: 6191810 | D34: =B34/C34 -> 0.052388397 | E34: Open commercial (launched Dec 2025) | F34: 1 | G34: 1 | H34: 0 | I34: 0 | J34: Yes (national, CFTC) | K34: Kansas City | L34: =IF(F34=1,B34,0) -> 324379 | M34: =IF(F34=0,B34,0) -> 0
A35: Alabama | B35: 284135 | C35: 5086770 | D35: =B35/C35 -> 0.055857646 | E35: Not legalized (excluded) | F35: 0 | G35: 0 | H35: 0 | I35: 0 | J35: Yes (national, CFTC) | L35: =IF(F35=1,B35,0) -> 0 | M35: =IF(F35=0,B35,0) -> 284135
A36: Arkansas | B36: 275571 | C36: 3049390 | D36: =B36/C36 -> 0.090369221 | E36: Open commercial (launched 2026) | F36: 1 | G36: 1 | H36: 0 | I36: 0 | J36: Yes (national, CFTC) | L36: =IF(F36=1,B36,0) -> 275571 | M36: =IF(F36=0,B36,0) -> 0
A37: Idaho | B37: 263935 | C37: 1934260 | D37: =B37/C37 -> 0.1364527 | E37: Not legalized (excluded) | F37: 0 | G37: 0 | H37: 0 | I37: 0 | J37: Yes (national, CFTC) | L37: =IF(F37=1,B37,0) -> 0 | M37: =IF(F37=0,B37,0) -> 263935
A38: Nebraska | B38: 252023 | C38: 1978710 | D38: =B38/C38 -> 0.12736733 | E38: Retail/on-premise only (excluded) | F38: 0 | G38: 0 | H38: 0 | I38: 0 | J38: Yes (national, CFTC) | L38: =IF(F38=1,B38,0) -> 0 | M38: =IF(F38=0,B38,0) -> 252023
A39: Iowa | B39: 233706 | C39: 3210510 | D39: =B39/C39 -> 0.072794042 | E39: Open commercial (statewide mobile) | F39: 1 | G39: 1 | H39: 0 | I39: 0 | J39: Yes (national, CFTC) | L39: =IF(F39=1,B39,0) -> 233706 | M39: =IF(F39=0,B39,0) -> 0
A40: Kentucky | B40: 226744 | C40: 4534820 | D40: =B40/C40 -> 0.050000662 | E40: Open commercial (statewide mobile) | F40: 1 | G40: 1 | H40: 0 | I40: 0 | J40: Yes (national, CFTC) | L40: =IF(F40=1,B40,0) -> 226744 | M40: =IF(F40=0,B40,0) -> 0
A41: Rhode Island | B41: 194915 | C41: 1101800 | D41: =B41/C41 -> 0.17690597 | E41: Lottery-operated mobile – Bally's (commercial) | F41: 1 | G41: 0 | H41: 1 | I41: 0 | J41: Yes (national, CFTC) | L41: =IF(F41=1,B41,0) -> 194915 | M41: =IF(F41=0,B41,0) -> 0
...

Sheet Spanish-App TAM Funnel
A1: Spanish-Language App — Incremental Addressable Market (language counter-analysis)
A2: Separates the bullish '68m Hispanics' headline from the realistic incremental reach of a Spanish-NATIVE app. Most U.S. Hispanics are English-proficient and can already use English apps, so the app's unique ACCESS value concentrates in the Spanish-dependent segment. Yellow = flexible assumptions.
A4: Funnel step | B4: Value | C4: Source / Logic
A5: Total U.S. Hispanic population | B5: ='State Detail'!$B$55 -> 64759437 | C5: Link to State Detail (Census ACS 2024).
A6: x Betting-eligible age (21+) share | B6: 0.62 | C6: Analyst assumption — Hispanics skew young (median age ~31).
A7: ≡ Betting-age (21+) Hispanic adults | B7: =B5*B6 -> 40150851 | C7: Calc.
A8: x English-proficient share | B8: 0.72 | C8: Pew/ACS 2021: 72% all / 91% U.S.-born / 38% foreign-born.
A9: ≡ English-capable adults (already addressable in English) | B9: =B7*B8 -> 28908613 | C9: Do NOT need a Spanish app for ACCESS — preference lever only.
A10: ≡ Spanish-dependent adults [LOW / access-driven TAM] | B10: =B7*(1-B8) -> 11242238 | C10: Incremental ACCESS market the Spanish app uniquely unlocks.
A11: Memo: 'mainly-Spanish' language-use share | B11: 0.38 | C11: Pew: 38% mainly Spanish / 36% bilingual / 25% mainly English.
A12: ≡ Spanish-preferring adults [HIGH / preference TAM] | B12: =B7*B11 -> 15257323 | C12: Upper bound incl. bilinguals preferring Spanish UX.
A13: Incremental Spanish-only TAM as % of '68m headline' | B13: =B10/B5 -> 0.1736 | C13: Reality-check on the bullish framing.
A15: STRATEGIC WEDGE — Spanish-dependent bettors reachable ONLY via Predictions + Spanish app
A16: Hispanic pop. in states with NO regulated OSB | B16: ='State Detail'!$M$55 -> 40788788 | C16: Link to State Detail (Predictions-only).
A17: x 21+ share x Spanish-dependent share | B17: =B6*(1-B8) -> 0.1736 | C17: Same two haircuts.
A18: ≡ Spanish-dependent betting-age Hispanics, Predictions-only | B18: =B16*B17 -> 7080933.6 | C18: Intersection the combo uniquely serves.
A20: Interpretation: the access-driven incremental TAM is a fraction of the 68m headline, so a Spanish app is best read as a conversion/retention enhancer on the Predictions base (the real unlock = nationwide Prediction-market legality), not a fix for a representation deficit. Attribution between the two will be hard to isolate.

Sheet Factors & Counter-Analysis
A1: Analytical Factors — Supports vs. Challenges the 'Underserved Spanish Bettor' Thesis (industry-wide)
A2: Analysis / Factor | B2: Direction | C2: Key data point | D2: Implication for the note | E2: Src #
A3: Legalization geography (industry) | B3: SUPPORTS | C3: ~63% of U.S. Hispanics live in states with no regulated non-tribal OSB; CA+TX+FL ≈52%. | D3: Backbone of the thesis; not DK-specific. Lead with this. | E3: 1,2,3
A4: DK vs. industry footprint | B4: SUPPORTS | C4: DK reaches ~35% of Hispanics; whole regulated industry only ~37%. | D4: The gap is structural/legal, not a DK execution miss. | E4: 3,7
A5: iGaming access gap | B5: SUPPORTS | C5: Only ~7% of Hispanics in DK-iCasino states. | D5: Validates '~90% not present for iGaming' — second underserved layer. | E5: 4
A6: World Cup host-city overlap | B6: SUPPORTS | C6: 7 of 11 U.S. host cities sit in non-regulated-OSB states (LA, SF, Dallas, Houston, Atlanta, Miami, Seattle). | D6: Engagement mega-event lands in Predictions-only territory. | E6: 5,6
A7: Spanish-language product gap | B7: SUPPORTS | C7: Robins frames the Spanish app as a 'differentiator' (implies incumbents lack one). | D7: Product-level underservice independent of geography. VERIFY peers. | E7: 7
A8: Sport-mix mismatch | B8: SUPPORTS | C8: Soccer is #1 for U.S. Hispanics but small share of U.S. handle (NFL/NBA dominate). | D8: Favorite sport under-weighted; WC 2026 flips it for one window. | E8: 5,6
A9: Spanish-language media underspend | B9: SUPPORTS (soft) | C9: Industry ad spend on Telemundo/Univision historically low vs. pop. share. | D9: Directional; quantify if data available. | E9: —
A10: English proficiency | B10: CHALLENGES | C10: 72% of Hispanics English-proficient (91% U.S.-born). | D10: Shrinks Spanish-only incremental TAM; app is conversion lever. | E10: 8,9
A11: Within-legal-state participation | B11: CHALLENGES | C11: If Hispanic participation in legal states tracks pop. share, gap is pure geography. | D11: Reframes thesis as ACCESS, not language. Test w/ customer-mix data. | E11: —
A12: Income constraint | B12: CHALLENGES | C12: Hispanic median HH income $70,950 vs. U.S. $83,730 (2024); ratio to non-Hisp. White ~0.74. | D12: Lower disposable income caps spend/LTV. | E12: 10,11
A13: Age / eligibility | B13: CHALLENGES | C13: Hispanic median age ~31; large under-21 (ineligible) share. | D13: Betting-age base smaller than headline pop. | E13: 12
... A15: Predictions vs. app attribution | B15: CHALLENGES | C15: Real legal unlock = CFTC Prediction structure, not language. | D15: Hard to isolate Spanish-app ROI from Predictions-access ROI. | E15: 7

Sheet Representation Index
A1: Hispanic Representation Index — Coverage (evidenced) vs. Participation (requires data)
A2: Section A (coverage) is fully evidenced by the state data, measured on the REGULATED non-tribal OSB footprint, with DK shown as a subset. Section B (participation) is NOT in the data — it needs operators' actual customer mix. Keep the two distinct in the note.
A4: A. COVERAGE / ACCESS REPRESENTATION — EVIDENCED
A5: Metric | B5: Value | C5: Note / Source
A6: National Hispanic share of population | B6: ='State Detail'!$B$55/'State Detail'!$C$55 -> 0.19335645 | C6: Census ACS 2024: ~64.8m of ~334.9m.
A7: Hispanic share of REGULATED (non-tribal) OSB footprint | B7: =SUMIF('State Detail'!$F$4:$F$54,1,'State Detail'!$B$4:$B$54)/SUMIF('State Detail'!$F$4:$F$54,1,'State Detail'!$C$4:$C$54) -> 0.13254746 | C7: Pop-weighted across all regulated non-tribal mobile states.
A8: Hispanic share of NON-regulated-OSB states | B8: =SUMIF('State Detail'!$F$4:$F$54,0,'State Detail'!$B$4:$B$54)/SUMIF('State Detail'!$F$4:$F$54,0,'State Detail'!$C$4:$C$54) -> 0.26473028 | C8: States with no regulated OSB are far more Hispanic.
A9: REPRESENTATION INDEX — industry (footprint ÷ national) | B9: =B7/B6 -> 0.68550835 | C9: Below 1.00x = regulated market under-indexes Hispanics.
A10: Memo: Hispanic share of DraftKings footprint | B10: =SUMIF('State Detail'!$G$4:$G$54,1,'State Detail'!$B$4:$B$54)/SUMIF('State Detail'!$G$4:$G$54,1,'State Detail'!$C$4:$C$54) -> 0.1294669 | C10: DK subset of the regulated market.
A11: Memo: REPRESENTATION INDEX — DraftKings only | B11: =B10/B6 -> 0.66957629 | C11: Nearly identical to industry — confirms gap is structural.
A13: Read: the regulated non-tribal OSB market is ~13% Hispanic vs. ~19% nationally (~0.69x), essentially the same as DK alone (~0.67x) — because CA/TX/FL sit outside it. This is a COVERAGE deficit (where Hispanics live vs. where regulated OSB is legal), NOT evidence that operators serve Hispanic customers worse where they run.
A16: B. PARTICIPATION / CUSTOMER-MIX REPRESENTATION — REQUIRES DATA
A17: Metric | B17: Value | C17: Note / Source
A18: Hispanic share of regulated-OSB CUSTOMERS (enter actual) | B18: 0.132 | C18: PLACEHOLDER (illustrative = footprint share). REPLACE with operator disclosures / 3rd-party panel.
A19: Expected if proportional to footprint | B19: =B7 -> 0.13254746 | C19: Benchmark = Hispanic share of regulated-OSB footprint (Section A).
A20: PARTICIPATION INDEX (actual ÷ expected) | B20: =IFERROR(B18/B19,"—") -> 0.99586968 | C20: >1.00x = Hispanics over-index among customers; <1.00x = under-index; =1.00x = proportional (no language/product gap).
A22: Sensitivity — participation index at various assumed Hispanic customer shares
A23: Scenario | B23: Assumed Hisp. customer % | C23: Participation index
A24: Deeply under-indexed | B24: 0.08 | C24: =B24/$B$7 -> 0.60355738
A25: Mild under-index | B25: 0.1 | C25: =B25/$B$7 -> 0.75444673
A26: Proportional to footprint | B26: 0.132 | C26: =B26/$B$7 -> 0.99586968
A27: Above footprint | B27: 0.16 | C27: =B27/$B$7 -> 1.2071148
A28: At national pop. share | B28: 0.193 | C28: =B28/$B$7 -> 1.4560822
A30: To populate Section B you need operators' actual Hispanic customer share within the regulated footprint. Sources: investor disclosures; consumer panels (comScore, MRI-Simmons, Nielsen Scarborough); or geolocated handle by ZIP mapped to ACS tracts. Until then, claim only the COVERAGE deficit (~0.69x industry / ~0.67x DK) and treat any language/product 'underservice' as a hypothesis.

Sheet Sources
A1: Sources & Classification Rules
A2: # | B2: Publisher | C2: Date | D2: Data used in model | E2: URL
A3: 1 | B3: World Population Review | C3: 2026 (ACS 2024 est.) | D3: Hispanic & total population by state | E3: https://worldpopulationreview.com/state-rankings/hispanic-population-by-state
A4: 2 | B4: Pew Research Center | C4: Oct 2025 | D4: U.S. Hispanic ~68m; CA 16.1m, TX 12.6m, FL 6.7m | E4: https://www.pewresearch.org/short-reads/2025/10/22/key-facts-about-us-latinos/
A5: 3 | B5: Legal Sports Report | C5: Nov 2025 | D5: OSB legal status / mobile vs tribal vs retail by state | E5: https://www.legalsportsreport.com/sports-betting-states/
A6: 4 | B6: CasinoBeats / SportsLine | C6: 2026 | D6: iGaming legal states; DK iCasino footprint | E6: https://casinobeats.com/features/us-online-casino-gambling-legal-tracker/
A7: 5 | B7: Al Jazeera | C7: Jun 2026 | D7: FIFA World Cup 2026 U.S. host cities & venues | E7: https://www.aljazeera.com/sports/2026/6/3/fifa-world-cup-2026-stadiums-matches-us-canada-mexico
A8: 6 | B8: CBS Sports | C8: 2024 | D8: World Cup 2026 host-city/state list | E8: https://www.cbssports.com/soccer/news/fifa-world-cup-2026-host-cities-los-angeles-new-york-new-jersey-among-top-venues-washington-d-c-snubbed
A9: 7 | B9: DraftKings Q1 2026 Earnings Call | C9: May 8, 2026 | D9: Mgmt commentary: Spanish app, Predictions, World Cup, iGaming | E9: Company transcript (S&P Global Market Intelligence)
A10: 8 | B10: Pew Research Center | C10: 2021 ACS | D10: Hispanic English proficiency 72% / 91% U.S.-born / 38% foreign-born | E10: https://www.pewresearch.org/chart/us-hispanics-english-proficiency/
A11: 9 | B11: Pew Research Center | C11: 2015 Nat'l Survey of Latinos | D11: Language use 36% bilingual / 25% mainly English / 38% mainly Spanish | E11: https://www.pewresearch.org/short-reads/2015/03/24/a-majority-of-english-speaking-hispanics-in-the-u-s-are-bilingual/
A12: 10 | B12: U.S. Census Bureau | C12: Sep 2025 | D12: Hispanic median HH income $70,950 (2024) | E12: https://www.census.gov/library/stories/2025/09/median-household-income.html
A13: 11 | B13: U.S. Census Bureau | C13: Sep 2024 | D13: U.S. median HH income $83,730; Hisp/White ratio 0.74 | E13: https://www.census.gov/library/stories/2024/09/household-income-race-hispanic.html
A14: 12 | B14: U.S. Census Bureau | C14: 2024 | D14: Hispanic median age ~31 | E14: https://www.census.gov/newsroom/facts-for-features/2024/hispanic-heritage-month.html
A16: CLASSIFICATION RULES — 'Regulated (non-tribal) OSB'
A17: • INCLUDED (Reg. OSB = 1): states with a legal, statewide-mobile online sportsbook run under a state commercial or lottery framework — open multi-operator markets, plus single/lottery-operator mobile markets (OR, DE, RI, NH, DC) and Nevada.
A18: • EXCLUDED — tribal: Florida (Seminole/Hard Rock compact) and on-land-only tribal markets (Washington, New Mexico, North Dakota, Wisconsin).
A19: • EXCLUDED — retail/on-premise only: Nebraska, South Dakota, Mississippi, Montana.
A20: • EXCLUDED — no legal OSB: California, Texas, Georgia, Alabama, Alaska, Hawaii, Idaho, Minnesota, Oklahoma, South Carolina, Utah.
A21: • Judgment calls that swing the result: Florida (largest excluded state — flip to included if you count tribal mobile) and the lottery-mobile states (OR/DE/RI/NH/DC — flip to excluded under a stricter 'open commercial only' definition).
