Workbook

Sheet Dashboard
B1: DraftKings Predictions - Dashboard
B2: Summary. Edit inputs on the three build tabs (blue). Reconciliation ties to disclosures + DKeX actuals.
B4: REVENUE & MARGIN (from builds)
B5: Metric | C5: FY2026 | D5: FY2030
B6: Consumer volume ($M) | C6: ='Revenue Build'!O40 -> 3526.6337 | D6: ='Revenue Build'!S40 -> 23112.146
B7: Total volume traded ($M) | C7: ='Revenue Build'!O42 -> 11462.058 | D7: ='Revenue Build'!S42 -> 76270.083
B8: DKeX volume ($M) | C8: ='Revenue Build'!O44 -> 160.31241 | D8: ='Revenue Build'!S44 -> 30508.033
B9: DKeX % of DK total | C9: ='Revenue Build'!O46 -> 0.013986355 | D9: ='Revenue Build'!S46 -> 0.4
B10: Net Predictions revenue ($M) | C10: ='Revenue Build'!O54 -> 65.970084 | D10: ='Revenue Build'!S54 -> 758.64239
B11: Distribution | C11: ='Revenue Build'!O47 -> 70.532673 | D11: ='Revenue Build'!S47 -> 462.24293
B12: Exchange | C12: ='Revenue Build'!O48 -> 0.80156205 | D12: ='Revenue Build'!S48 -> 152.54017
B13: FCM | C13: ='Revenue Build'!O49 -> 2.371806 | D13: ='Revenue Build'!S49 -> 23.112146
B14: Market-making | C14: ='Revenue Build'!O50 -> 12.035161 | D14: ='Revenue Build'!S50 -> 80.083587
B15: Adjusted EBITDA ($M) | C15: ='Margin Build'!O25 -> -310.17568 | D15: ='Margin Build'!S25 -> 294.17838
B16: EBITDA margin | C16: ='Margin Build'!O26 -> -4.7017627 | D16: ='Margin Build'!S26 -> 0.38776951
B18: VALUATION 2030E SOTP EV ($M)
C19: Bear | D19: Base | E19: Bull | F19: Uber-bull
B20: Enterprise value | C20: ='Valuation Build'!C48 -> 1372.7067 | D20: ='Valuation Build'!D48 -> 4807.7145 | E20: ='Valuation Build'!E48 -> 9424.2479 | F20: ='Valuation Build'!F48 -> 46624.203
B21: Valuation #2 (1x monthly vol, $B) | C21: ='Valuation #2 (Volume)'!C10 -> 1.5 | D21: ='Valuation #2 (Volume)'!D10 -> 2.5 | E21: ='Valuation #2 (Volume)'!E10 -> 3

Sheet Revenue Build
B1: Revenue Build
B2: Assumptions (blue) at top; build below. Consumer funnel -> DKeX ramp -> revenue by layer.
B4: ASSUMPTIONS
B5: Starting funded customers (000s) | C5: 120
B6: CAC per new customer ($) | C6: 120
B7: Monthly volume per active customer ($000) | C7: 0.25
B8: Monthly churn (%) | C8: 0.03
B9: Total 2026 Predictions investment / CAC ($M) | C9: 250
B10: MM gross-up multiple (x) | C10: 3.3
B11: Average contract price ($) | C11: 0.48
B12: Distribution gross take (% consumer notional) | C12: 0.02
B13: Exchange take (% DKeX notional) | C13: 0.005
B14: FCM take (% consumer notional) | C14: 0.001
B15: MM participation (% of total volume) | C15: 0.3
B16: MM net captured spread (bps) | C16: 50
... B22: July ramp uplift vs 7-day actual (x) | C22: 2.5
B24: MONTHLY PROFILES (blue)
C25: Jan-26 | D25: Feb-26 | E25: Mar-26 | F25: Apr-26 | G25: May-26 | H25: Jun-26 | I25: Jul-26 | J25: Aug-26 | K25: Sep-26 | L25: Oct-26 | M25: Nov-26 | N25: Dec-26 | O25: FY2026 | P25: FY2027 | Q25: FY2028 | R25: FY2029 | S25: FY2030
B26: CAC spend weight (%) | C26: 0.02 | D26: 0.02 | E26: 0.03 | F26: 0.04 | G26: 0.05 | H26: 0.1 | I26: 0.08 | J26: 0.06 | K26: 0.14 | L26: 0.16 | M26: 0.15 | N26: 0.15
B27: Consumer seasonality (x) | C27: 0.7 | D27: 0.7 | E27: 0.9 | F27: 0.85 | G27: 0.95 | H27: 1.6 | I27: 1.8 | J27: 1 | K27: 1.3 | L27: 1.5 | M27: 1.6 | N27: 1.6
B28: DK disclosed consumer vol, ann. ($M) | F28: 1000 | G28: 1300 | H28: 3400
B29: DK disclosed total vol, ann. ($M) | F29: 2300 | G29: 3100 | H29: 11300
B30: Kalshi-analog DKeX growth (MoM 2026) | J30: 0.55 | K30: 0.7 | L30: 0.55 | M30: 0.45 | N30: 0.4
B31: DKeX sports seasonality (x) | C31: 0 | D31: 0 | E31: 0 | F31: 0 | G31: 0 | H31: 0.3 | I31: 1 | J31: 0.6 | K31: 1.2 | L31: 1.5 | M31: 1.6 | N31: 1.6
B32: DKeX out-year migration (% of total) | P32: 0.1 | Q32: 0.2 | R32: 0.3 | S32: 0.4
B33: Promo intensity (% of Distribution) | C33: 0.25 | D33: 0.25 | E33: 0.3 | F33: 0.28 | G33: 0.3 | H33: 0.42 | I33: 0.4 | J33: 0.25 | K33: 0.4 | L33: 0.36 | M33: 0.34 | N33: 0.34 | P33: 0.28 | Q33: 0.22 | R33: 0.18 | S33: 0.15
B35: REVENUE BUILD
C36: Jan-26 | D36: Feb-26 | E36: Mar-26 | F36: Apr-26 | G36: May-26 | H36: Jun-26 | I36: Jul-26 | J36: Aug-26 | K36: Sep-26 | L36: Oct-26 | M36: Nov-26 | N36: Dec-26 | O36: FY2026 | P36: FY2027 | Q36: FY2028 | R36: FY2029 | S36: FY2030
B37: CAC spend | C37: =$C$9*C26 -> 5 | D37: =$C$9*D26 -> 5 | E37: =$C$9*E26 -> 7.5 | F37: =$C$9*F26 -> 10 | G37: =$C$9*G26 -> 12.5 | H37: =$C$9*H26 -> 25 | I37: =$C$9*I26 -> 20 | J37: =$C$9*J26 -> 15 | ... N37: =$C$9*N26 -> 37.5 | O37: =SUM(C37:N37) -> 250
B38: New customers (000s) | C38: =C37*1000/$C$6 -> 41.666667 | D38: =D37*1000/$C$6 -> 41.666667 | E38: =E37*1000/$C$6 -> 62.5 | F38: =F37*1000/$C$6 -> 83.333333 | G38: =G37*1000/$C$6 -> 104.16667 | H38: =H37*1000/$C$6 -> 208.33333 | I38: =I37*1000/$C$6 -> 166.66667 | J38: =J37*1000/$C$6 -> 125 | ... N38: =N37*1000/$C$6 -> 312.5 | O38: =SUM(C38:N38) -> 2083.3333
B39: Cumulative customers (000s) | C39: =$C$5*(1-$C$8)+C38 -> 158.06667 | D39: =C39*(1-$C$8)+D38 -> 194.99133 | E39: =D39*(1-$C$8)+E38 -> 251.64159 | F39: =E39*(1-$C$8)+F38 -> 327.42568 | G39: =F39*(1-$C$8)+G38 -> 421.76958 | H39: =G39*(1-$C$8)+H38 -> 617.44982 | I39: =H39*(1-$C$8)+I38 -> 765.59299 | J39: =I39*(1-$C$8)+J38 -> 867.6252 | K39: =J39*(1-$C$8)+K38 -> 1133.2631 | ... N39: =M39*(1-$C$8)+N38 -> 1963.557 | O39: =N39 -> 1963.557
B40: Consumer volume | C40: =IF(C28>0,C28/12,C39*$C$7*C27*(1-$C$19)) -> 27.661667 | D40: =IF(D28>0,D28/12,D39*$C$7*D27*(1-$C$19)) -> 34.123483 | E40: =IF(E28>0,E28/12,E39*$C$7*E27*(1-$C$19)) -> 56.619358 | F40: =IF(F28>0,F28/12,F39*$C$7*F27*(1-$C$19)) -> 83.333333 | G40: =IF(G28>0,G28/12,G39*$C$7*G27*(1-$C$19)) -> 108.33333 | H40: =IF(H28>0,H28/12,H39*$C$7*H27*(1-$C$19)) -> 283.33333 | I40: =IF(I28>0,I28/12,I39*$C$7*I27*(1-$C$19)) -> 344.51685 | J40: =IF(J28>0,J28/12,J39*$C$7*J27*(1-$C$19)) -> 216.9063 | ... N40: =IF(N28>0,N28/12,N39*$C$7*N27*(1-$C$19)) -> 785.42279 | O40: =SUM(C40:N40) -> 3526.6337 | P40: =O40*(1+$C$18) -> 5642.6139 | Q40: =P40*(1+$C$18) -> 9028.1822 | R40: =Q40*(1+$C$18) -> 14445.091 | S40: =R40*(1+$C$18) -> 23112.146
B41: Consumer contracts (M) | C41: =C40/$C$11 -> 57.628472 | D41: =D40/$C$11 -> 71.09059 | E41: =E40/$C$11 -> 117.957 | F41: =F40/$C$11 -> 173.61111 | G41: =G40/$C$11 -> 225.69444 | H41: =H40/$C$11 -> 590.27778 | I41: =I40/$C$11 -> 717.74343 | J41: =J40/$C$11 -> 451.88813 | ... N41: =N40/$C$11 -> 1636.2975 | O41: =SUM(C41:N41) -> 7347.1535 | P41: =P40/$C$11 -> 11755.446 | Q41: =Q40/$C$11 -> 18808.713 | R41: =R40/$C$11 -> 30093.941 | S41: =S40/$C$11 -> 48150.305
B42: Total volume traded | C42: =IF(C29>0,C29/12,C40*$C$10) -> 91.2835 | D42: =IF(D29>0,D29/12,D40*$C$10) -> 112.6075 | E42: =IF(E29>0,E29/12,E40*$C$10) -> 186.84388 | F42: =IF(F29>0,F29/12,F40*$C$10) -> 191.66667 | G42: =IF(G29>0,G29/12,G40*$C$10) -> 258.33333 | H42: =IF(H29>0,H29/12,H40*$C$10) -> 941.66667 | I42: =IF(I29>0,I29/12,I40*$C$10) -> 1136.9056 | J42: =IF(J29>0,J29/12,J40*$C$10) -> 715.79079 | ... N42: =IF(N29>0,N29/12,N40*$C$10) -> 2591.8952 | O42: =SUM(C42:N42) -> 11462.058 | P42: =P40*$C$10 -> 18620.626 | Q42: =Q40*$C$10 -> 29793.001 | R42: =R40*$C$10 -> 47668.802 | S42: =S40*$C$10 -> 76270.083
B43: DKeX underlying trend ($M) | C43: =0 -> 0 | D43: =0 -> 0 | E43: =0 -> 0 | F43: =0 -> 0 | G43: =0 -> 0 | H43: =0 -> 0 | I43: =DKeX_Actuals!$C$37*$C$22 -> 4.720697 | J43: =I43*(1+J30*$C$20) -> 7.3170803 | K43: =J43*(1+K30*$C$20) -> 12.439037 | L43: =K43*(1+L30*$C$20) -> 19.280507 | M43: =L43*(1+M30*$C$20) -> 27.956735 | N43: =M43*(1+N30*$C$20) -> 39.139428
B44: DKeX volume | C44: =C43*C31 -> 0 | D44: =D43*D31 -> 0 | E44: =E43*E31 -> 0 | F44: =F43*F31 -> 0 | G44: =G43*G31 -> 0 | H44: =H43*H31 -> 0 | I44: =I43*I31 -> 4.720697 | J44: =J43*J31 -> 4.3902482 | ... N44: =N43*N31 -> 62.623085 | O44: =SUM(C44:N44) -> 160.31241 | P44: =P42*P32 -> 1862.0626 | Q44: =Q42*Q32 -> 5958.6002 | R44: =R42*R32 -> 14300.641 | S44: =S42*S32 -> 30508.033
B45: DKeX contracts (M) | C45: =C44/$C$11 -> 0 | D45: =D44/$C$11 -> 0 | E45: =E44/$C$11 -> 0 | F45: =F44/$C$11 -> 0 | G45: =G44/$C$11 -> 0 | H45: =H44/$C$11 -> 0 | I45: =I44/$C$11 -> 9.8347854 | J45: =J44/$C$11 -> 9.1463504 | ... N45: =N44/$C$11 -> 130.46476 | O45: =SUM(C45:N45) -> 333.98419 | P45: =P44/$C$11 -> 3879.297 | Q45: =Q44/$C$11 -> 12413.75 | R45: =R44/$C$11 -> 29793.001 | S45: =S44/$C$11 -> 63558.402
B46: DKeX % of DK total | C46: =IF(C42=0,0,C44/C42) -> 0 | D46: =IF(D42=0,0,D44/D42) -> 0 | E46: =IF(E42=0,0,E44/E42) -> 0 | F46: =IF(F42=0,0,F44/F42) -> 0 | G46: =IF(G42=0,0,G44/G42) -> 0 | H46: =IF(H42=0,0,H44/H42) -> 0 | I46: =IF(I42=0,0,I44/I42) -> 0.004152233 | J46: =IF(J42=0,0,J44/J42) -> 0.0061334237 | ... S46: =IF(S42=0,0,S44/S42) -> 0.4
B47: Distribution revenue | C47: =C40*$C$12 -> 0.55323333 | D47: =D40*$C$12 -> 0.68246967 | E47: =E40*$C$12 -> 1.1323872 | F47: =F40*$C$12 -> 1.6666667 | G47: =G40*$C$12 -> 2.1666667 | H47: =H40*$C$12 -> 5.6666667 | I47: =I40*$C$12 -> 6.8903369 | J47: =J40*$C$12 -> 4.338126 | ... N47: =N40*$C$12 -> 15.708456 | O47: =SUM(C47:N47) -> 70.532673 | P47: =P40*$C$12 -> 112.85228 | Q47: =Q40*$C$12 -> 180.56364 | R47: =R40*$C$12 -> 288.90183 | S47: =S40*$C$12 -> 462.24293
B48: Exchange revenue | C48: =C44*$C$13 -> 0 | D48: =D44*$C$13 -> 0 | E48: =E44*$C$13 -> 0 | F48: =F44*$C$13 -> 0 | G48: =G44*$C$13 -> 0 | H48: =H44*$C$13 -> 0 | I48: =I44*$C$13 -> 0.023603485 | J48: =J44*$C$13 -> 0.021951241 | ... N48: =N44*$C$13 -> 0.31311543 | O48: =SUM(C48:N48) -> 0.80156205 | P48: =P44*$C$13 -> 9.3103129 | Q48: =Q44*$C$13 -> 29.793001 | R48: =R44*$C$13 -> 71.503203 | S48: =S44*$C$13 -> 152.54017
...

Sheet Margin Build
B1: Margin Build
B2: Pulls revenue from Revenue Build; subtracts costs (assumptions below) to Adj. EBITDA.
B4: ASSUMPTIONS
B5: Product & tech (2026, $M) | C5: 45
B6: G&A / compliance (2026, $M) | C6: 35
B7: Lobbying / advocacy (2026, $M) | C7: 26
B8: MM capital cost (2026, $M) | C8: 15
B9: Broker cost per contract, pre-FCM ($) | C9: 0.002
B10: Clearing cost per contract ($) | C10: 0.001
B11: Out-year opex growth (%/yr) | C11: 0.2
B12: Sportsbook 'Sports' revenue (2026, $M) | C12: 4600
B14: MARGIN BUILD
C15: Jan-26 | D15: Feb-26 | E15: Mar-26 | F15: Apr-26 | G15: May-26 | H15: Jun-26 | I15: Jul-26 | J15: Aug-26 | K15: Sep-26 | L15: Oct-26 | M15: Nov-26 | N15: Dec-26 | O15: FY2026 | P15: FY2027 | Q15: FY2028 | R15: FY2029 | S15: FY2030
B16: Total Predictions revenue | C16: ='Revenue Build'!C54 -> 0.51077268 | D16: ='Revenue Build'!D54 -> 0.63009012 | E16: ='Revenue Build'!E54 -> 0.9888571 | F16: ='Revenue Build'!F54 -> 1.40125 | G16: ='Revenue Build'!G54 -> 1.7879167 | H16: ='Revenue Build'!H54 -> 4.2754167 | I16: ='Revenue Build'!I54 -> 5.3515565 | J16: ='Revenue Build'!J54 -> 4.0271261 | ... S16: ='Revenue Build'!S54 -> 758.64239
B17: CAC | C17: ='Revenue Build'!C37 -> 5 | D17: ='Revenue Build'!D37 -> 5 | E17: ='Revenue Build'!E37 -> 7.5 | F17: ='Revenue Build'!F37 -> 10 | G17: ='Revenue Build'!G37 -> 12.5 | H17: ='Revenue Build'!H37 -> 25 | I17: ='Revenue Build'!I37 -> 20 | J17: ='Revenue Build'!J37 -> 15 | ... O17: ='Revenue Build'!O37 -> 250 | P17: 250 | Q17: 250 | R17: 200 | S17: 150
B18: Product & tech | C18: =$C$5/12 -> 3.75 | D18: =$C$5/12 -> 3.75 | E18: =$C$5/12 -> 3.75 | F18: =$C$5/12 -> 3.75 | G18: =$C$5/12 -> 3.75 | H18: =$C$5/12 -> 3.75 | I18: =$C$5/12 -> 3.75 | J18: =$C$5/12 -> 3.75 | ... N18: =$C$5/12 -> 3.75 | O18: =$C$5 -> 45 | P18: =O18*(1+$C$11) -> 54 | Q18: =P18*(1+$C$11) -> 64.8 | R18: =Q18*(1+$C$11) -> 77.76 | S18: =R18*(1+$C$11) -> 93.312
B19: G&A / compliance | C19: =$C$6/12 -> 2.9166667 | D19: =$C$6/12 -> 2.9166667 | E19: =$C$6/12 -> 2.9166667 | F19: =$C$6/12 -> 2.9166667 | G19: =$C$6/12 -> 2.9166667 | H19: =$C$6/12 -> 2.9166667 | I19: =$C$6/12 -> 2.9166667 | J19: =$C$6/12 -> 2.9166667 | ... N19: =$C$6/12 -> 2.9166667 | O19: =$C$6 -> 35 | P19: =O19*(1+$C$11) -> 42 | Q19: =P19*(1+$C$11) -> 50.4 | R19: =Q19*(1+$C$11) -> 60.48 | S19: =R19*(1+$C$11) -> 72.576
B20: Lobbying / advocacy | C20: =$C$7/12 -> 2.1666667 | D20: =$C$7/12 -> 2.1666667 | E20: =$C$7/12 -> 2.1666667 | F20: =$C$7/12 -> 2.1666667 | G20: =$C$7/12 -> 2.1666667 | H20: =$C$7/12 -> 2.1666667 | I20: =$C$7/12 -> 2.1666667 | J20: =$C$7/12 -> 2.1666667 | ... N20: =$C$7/12 -> 2.1666667 | O20: =$C$7 -> 26 | P20: =O20*(1+$C$11) -> 31.2 | Q20: =P20*(1+$C$11) -> 37.44 | R20: =Q20*(1+$C$11) -> 44.928 | S20: =R20*(1+$C$11) -> 53.9136
B21: MM capital cost | C21: =$C$8/12 -> 1.25 | D21: =$C$8/12 -> 1.25 | E21: =$C$8/12 -> 1.25 | F21: =$C$8/12 -> 1.25 | G21: =$C$8/12 -> 1.25 | H21: =$C$8/12 -> 1.25 | I21: =$C$8/12 -> 1.25 | J21: =$C$8/12 -> 1.25 | ... N21: =$C$8/12 -> 1.25 | O21: =$C$8 -> 15 | P21: =O21*(1+$C$11) -> 18 | Q21: =P21*(1+$C$11) -> 21.6 | R21: =Q21*(1+$C$11) -> 25.92 | S21: =R21*(1+$C$11) -> 31.104
B22: Broker cost (pre-FCM) | C22: =IF(1>='Revenue Build'!$C$21,0,'Revenue Build'!C41*$C$9) -> 0.11525694 | D22: =IF(2>='Revenue Build'!$C$21,0,'Revenue Build'!D41*$C$9) -> 0.14218118 | E22: =IF(3>='Revenue Build'!$C$21,0,'Revenue Build'!E41*$C$9) -> 0.23591399 | F22: =IF(4>='Revenue Build'!$C$21,0,'Revenue Build'!F41*$C$9) -> 0.34722222 | G22: =IF(5>='Revenue Build'!$C$21,0,'Revenue Build'!G41*$C$9) -> 0.45138889 | H22: =IF(6>='Revenue Build'!$C$21,0,'Revenue Build'!H41*$C$9) -> 1.1805556 | I22: =IF(7>='Revenue Build'!$C$21,0,'Revenue Build'!I41*$C$9) -> 1.4354869 | J22: =IF(8>='Revenue Build'!$C$21,0,'Revenue Build'!J41*$C$9) -> 0.90377625 | K22: =IF(9>='Revenue Build'!$C$21,0,'Revenue Build'!K41*$C$9) -> 0 | L22: =IF(10>='Revenue Build'!$C$21,0,'Revenue Build'!L41*$C$9) -> 0 | M22: =IF(11>='Revenue Build'!$C$21,0,'Revenue Build'!M41*$C$9) -> 0 | N22: =IF(12>='Revenue Build'!$C$21,0,'Revenue Build'!N41*$C$9) -> 0 | O22: =SUM(C22:N22) -> 4.8117819 | P22: =0 -> 0 | Q22: =0 -> 0 | R22: =0 -> 0 | S22: =0 -> 0
B23: Clearing cost | C23: ='Revenue Build'!C45*$C$10 -> 0 | D23: ='Revenue Build'!D45*$C$10 -> 0 | E23: ='Revenue Build'!E45*$C$10 -> 0 | F23: ='Revenue Build'!F45*$C$10 -> 0 | G23: ='Revenue Build'!G45*$C$10 -> 0 | H23: ='Revenue Build'!H45*$C$10 -> 0 | I23: ='Revenue Build'!I45*$C$10 -> 0.0098347854 | J23: ='Revenue Build'!J45*$C$10 -> 0.0091463504 | ... S23: ='Revenue Build'!S45*$C$10 -> 63.558402
B24: Total costs | C24: =SUM(C17:C23) -> 15.19859 | D24: =SUM(D17:D23) -> 15.225515 | E24: =SUM(E17:E23) -> 17.819247 | F24: =SUM(F17:F23) -> 20.430556 | G24: =SUM(G17:G23) -> 23.034722 | H24: =SUM(H17:H23) -> 36.263889 | I24: =SUM(I17:I23) -> 31.528655 | J24: =SUM(J17:J23) -> 25.996256 | ... S24: =SUM(S17:S23) -> 464.464
B25: Adjusted EBITDA | C25: =C16-C24 -> -14.687818 | D25: =D16-D24 -> -14.595424 | E25: =E16-E24 -> -16.83039 | F25: =F16-F24 -> -19.029306 | G25: =G16-G24 -> -21.246806 | H25: =H16-H24 -> -31.988472 | I25: =I16-I24 -> -26.177098 | J25: =J16-J24 -> -21.96913 | ... S25: =S16-S24 -> 294.17838
B26: EBITDA margin | C26: =IF(C16=0,0,C25/C16) -> -28.756075 | D26: =IF(D16=0,0,D25/D16) -> -23.164027 | E26: =IF(E16=0,0,E25/E16) -> -17.020043 | F26: =IF(F16=0,0,F25/F16) -> -13.580236 | G26: =IF(G16=0,0,G25/G16) -> -11.883555 | H26: =IF(H16=0,0,H25/H16) -> -7.4819543 | I26: =IF(I16=0,0,I25/I16) -> -4.8914925 | J26: =IF(J16=0,0,J25/J16) -> -5.4552873 | ... S26: =IF(S16=0,0,S25/S16) -> 0.38776951
B27: Sportsbook 'Sports' revenue | C27: =$C$12/12 -> 383.33333 | D27: =$C$12/12 -> 383.33333 | E27: =$C$12/12 -> 383.33333 | F27: =$C$12/12 -> 383.33333 | G27: =$C$12/12 -> 383.33333 | H27: =$C$12/12 -> 383.33333 | I27: =$C$12/12 -> 383.33333 | J27: =$C$12/12 -> 383.33333 | ... N27: =$C$12/12 -> 383.33333 | O27: =$C$12 -> 4600 | P27: =O27*(1+$C$11) -> 5520 | Q27: =P27*(1+$C$11) -> 6624 | R27: =Q27*(1+$C$11) -> 7948.8 | S27: =R27*(1+$C$11) -> 9538.56
B28: Sports Predictions revenue | C28: =C16 -> 0.51077268 | D28: =D16 -> 0.63009012 | E28: =E16 -> 0.9888571 | F28: =F16 -> 1.40125 | G28: =G16 -> 1.7879167 | H28: =H16 -> 4.2754167 | I28: =I16 -> 5.3515565 | J28: =J16 -> 4.0271261 | ... S28: =S16 -> 758.64239
B29: Combined 'Sports' revenue line | C29: =C27+C28 -> 383.84411 | D29: =D27+D28 -> 383.96342 | E29: =E27+E28 -> 384.32219 | F29: =F27+F28 -> 384.73458 | G29: =G27+G28 -> 385.12125 | H29: =H27+H28 -> 387.60875 | I29: =I27+I28 -> 388.68489 | J29: =J27+J28 -> 387.36046 | ... S29: =S27+S28 -> 10297.202

Sheet Valuation Build
B1: Valuation Build - 2030E Sum-of-the-Parts
B2: Four cases across the columns. Bear/Base/Bull vary DK's own capture; Uber-bull = DKeX is the compliant rail every OSB operator must plug into.
B4: ASSUMPTIONS
C5: Bear | D5: Base | E5: Bull | F5: Uber-bull
B6: Category total PM volume ($B) | C6: 1000
B7: Category revenue opportunity ($B) | C7: 10
B8: Distribution gross take (% consumer notional) | C8: 0.02
B9: Promo intensity, 2030E (% of Distribution) | C9: ='Revenue Build'!S33 -> 0.15
B10: Exchange take (% DKeX notional) | C10: 0.005
B11: FCM take (% intermediated notional) | C11: 0.001
B12: MM gross-up (total/consumer) | C12: 3.3
B14: Per case inputs:
B15: DK total volume 2030 ($M) | C15: ='Revenue Build'!S42*0.75 -> 57202.562 | D15: ='Revenue Build'!S42 -> 76270.083 | E15: ='Revenue Build'!S42*1.3 -> 99151.108 | F15: ='Revenue Build'!S42*1.6 -> 122032.13
B16: DKeX migration (% of DK total) | C16: 0.2 | D16: 0.4 | E16: 0.6
B17: OSB share of category (uber-bull) | F17: 0.45
B18: Routing through DKeX (uber-bull) | F18: 0.9
B19: MM, data and other revenue ($M) | C19: 120 | D19: 180 | E19: 300 | F19: 800
B21: Revenue multiples by layer:
B22: Distribution | C22: 2 | D22: 5 | E22: 6 | F22: 8
B23: Exchange | C23: 5 | D23: 10 | E23: 12 | F23: 15
B24: FCM | C24: 1 | D24: 2.5 | E24: 3 | F24: 4
B25: MM, data and other | C25: 4 | D25: 7 | E25: 9 | F25: 12
B27: VALUATION BUILD (2030E)
C28: Bear | D28: Base | E28: Bull | F28: Uber-bull
B29: DKeX-routed volume ($M) | C29: =C15*C16 -> 11440.512 | D29: =D15*D16 -> 30508.033 | E29: =E15*E16 -> 59490.665 | F29: =$C$6*1000*F17*F18 -> 405000
B30: Consumer notional ($M) | C30: =C15/$C$12 -> 17334.11 | D30: =D15/$C$12 -> 23112.146 | E30: =E15/$C$12 -> 30045.79 | F30: =F15/$C$12 -> 36979.434
B32: Revenue by layer ($M)
B33: Distribution gross | C33: =C30*$C$8 -> 346.6822 | D33: =D30*$C$8 -> 462.24293 | E33: =E30*$C$8 -> 600.9158 | F33: =F30*$C$8 -> 739.58868
B34: Less: promo | C34: =-C33*$C$9 -> -52.002329 | D34: =-D33*$C$9 -> -69.336439 | E34: =-E33*$C$9 -> -90.137371 | F34: =-F33*$C$9 -> -110.9383
B35: Distribution net | C35: =C33+C34 -> 294.67987 | D35: =D33+D34 -> 392.90649 | E35: =E33+E34 -> 510.77843 | F35: =F33+F34 -> 628.65038
B36: Exchange | C36: =C29*$C$10 -> 57.202562 | D36: =D29*$C$10 -> 152.54017 | E36: =E29*$C$10 -> 297.45332 | F36: =F29*$C$10 -> 2025
B37: FCM | C37: =C30*$C$11 -> 17.33411 | D37: =D30*$C$11 -> 23.112146 | E37: =E30*$C$11 -> 30.04579 | F37: =F29*$C$11 -> 405
B38: MM, data and other line | C38: =C19 -> 120 | D38: =D19 -> 180 | E38: =E19 -> 300 | F38: =F19 -> 800
B39: TOTAL net revenue | C39: =C35+C36+C37+C38 -> 489.21654 | D39: =D35+D36+D37+D38 -> 748.5588 | E39: =E35+E36+E37+E38 -> 1138.2775 | F39: =F35+F36+F37+F38 -> 3858.6504
B40: Implied share of $10B category | C40: =C39/($C$7*1000) -> 0.048921654 | D40: =D39/($C$7*1000) -> 0.07485588 | E40: =E39/($C$7*1000) -> 0.11382775 | F40: =F39/($C$7*1000) -> 0.38586504
B42: SUM-OF-THE-PARTS EV ($M)
C43: Bear | D43: Base | E43: Bull | F43: Uber-bull
B44: Distribution | C44: =C35*C22 -> 589.35973 | D44: =D35*D22 -> 1964.5324 | E44: =E35*E22 -> 3064.6706 | F44: =F35*F22 -> 5029.203
B45: Exchange | C45: =C36*C23 -> 286.01281 | D45: =D36*D23 -> 1525.4017 | E45: =E36*E23 -> 3569.4399 | F45: =F36*F23 -> 30375
B46: FCM | C46: =C37*C24 -> 17.33411 | D46: =D37*D24 -> 57.780366 | E46: =E37*E24 -> 90.137371 | F46: =F37*F24 -> 1620
...

Sheet Valuation #2 (Volume)
B1: Valuation #2 - 1x Monthly Volume
B2: Heuristic cross-check: DK Predictions incremental value to core OSB ~ multiple x forward monthly TOTAL volume.
B4: INPUTS
C5: Bear | D5: Base | E5: Bull
B6: Forward monthly total volume, ~1yr out ($B) | C6: 2 | D6: 2.5 | E6: 3
B7: Value multiple (x monthly volume) | C7: 0.75 | D7: 1 | E7: 1
B9: IMPLIED INCREMENTAL VALUE
B10: Incremental value to core OSB ($B) | C10: =C6*C7 -> 1.5 | D10: =D6*D7 -> 2.5 | E10: =E6*E7 -> 3
B12: MODEL CROSS-CHECK
B13: Revenue Build implied monthly total volume, 2027 ($B) | C13: ='Revenue Build'!P42/12/1000 -> 1.5517188
B14: Compare your forward view above to this model-implied figure.

Sheet DKeX_Actuals
B1: DKeX Actuals - from your Railbird daily files
B2: Anchors the July point of the Kalshi-follow ramp (Revenue Build).
B4: Date | C4: MLB $ | D4: KBO $ | E4: NPB $ | F4: PGA $ | G4: Total $ | H4: Contracts | I4: Avg px | J4: Cum $
B5: 2026-06-11 | C5: 0.5 | D5: 0 | E5: 0 | F5: 0 | G5: =SUM(C5:F5) -> 0.5 | H5: 1 | I5: =IF(H5=0,0,G5/H5) -> 0.5 | J5: =G5 -> 0.5
B6: 2026-06-12 | C6: 0 | D6: 0 | E6: 0 | F6: 0 | G6: =SUM(C6:F6) -> 0 | H6: 0 | I6: =IF(H6=0,0,G6/H6) -> 0 | J6: =J5+G6 -> 0.5
B7: 2026-06-13 | C7: 0 | D7: 0 | E7: 0 | F7: 0 | G7: =SUM(C7:F7) -> 0 | H7: 0 | I7: =IF(H7=0,0,G7/H7) -> 0 | J7: =J6+G7 -> 0.5
B8: 2026-06-14 | C8: 0 | D8: 0 | E8: 0 | F8: 0 | G8: =SUM(C8:F8) -> 0 | H8: 0 | I8: =IF(H8=0,0,G8/H8) -> 0 | J8: =J7+G8 -> 0.5
B9: 2026-06-15 | C9: 0 | D9: 0 | E9: 0 | F9: 0 | G9: =SUM(C9:F9) -> 0 | H9: 0 | I9: =IF(H9=0,0,G9/H9) -> 0 | J9: =J8+G9 -> 0.5
B10: 2026-06-16 | C10: 0 | D10: 0 | E10: 0 | F10: 0 | G10: =SUM(C10:F10) -> 0 | H10: 0 | I10: =IF(H10=0,0,G10/H10) -> 0 | J10: =J9+G10 -> 0.5
B11: 2026-06-17 | C11: 0 | D11: 0 | E11: 0 | F11: 0 | G11: =SUM(C11:F11) -> 0 | H11: 0 | I11: =IF(H11=0,0,G11/H11) -> 0 | J11: =J10+G11 -> 0.5
B12: 2026-06-18 | C12: 0 | D12: 0 | E12: 0 | F12: 0 | G12: =SUM(C12:F12) -> 0 | H12: 25 | I12: =IF(H12=0,0,G12/H12) -> 0 | J12: =J11+G12 -> 0.5
B13: 2026-06-19 | C13: 0 | D13: 0 | E13: 0 | F13: 0 | G13: =SUM(C13:F13) -> 0 | H13: 0 | I13: =IF(H13=0,0,G13/H13) -> 0 | J13: =J12+G13 -> 0.5
B14: 2026-06-20 | C14: 0 | D14: 0 | E14: 0 | F14: 0 | G14: =SUM(C14:F14) -> 0 | H14: 0 | I14: =IF(H14=0,0,G14/H14) -> 0 | J14: =J13+G14 -> 0.5
B15: 2026-06-21 | C15: 0 | D15: 0 | E15: 0 | F15: 0 | G15: =SUM(C15:F15) -> 0 | H15: 0 | I15: =IF(H15=0,0,G15/H15) -> 0 | J15: =J14+G15 -> 0.5
B16: 2026-06-22 | C16: 0 | D16: 0 | E16: 0 | F16: 0 | G16: =SUM(C16:F16) -> 0 | H16: 0 | I16: =IF(H16=0,0,G16/H16) -> 0 | J16: =J15+G16 -> 0.5
B17: 2026-06-23 | C17: 0 | D17: 0 | E17: 0 | F17: 0 | G17: =SUM(C17:F17) -> 0 | H17: 0 | I17: =IF(H17=0,0,G17/H17) -> 0 | J17: =J16+G17 -> 0.5
... B30: 2026-07-06 | C30: 63440 | D30: 219.88 | E30: 160.38 | F30: 0 | G30: =SUM(C30:F30) -> 63820.26 | H30: 98526 | I30: =IF(H30=0,0,G30/H30) -> 0.64775044 | J30: =J29+G30 -> 438506.57
B32: CALIBRATION
B33: Period total notional ($) | C33: =SUM(G5:G30) -> 438506.57
B34: Implied avg contract price ($) | C34: =IF(SUM(H5:H30)=0,0,C33/SUM(H5:H30)) -> 0.48258916
B35: Last-7-day daily avg notional ($) | C35: =AVERAGE(G24:G30) -> 62080.399
B36: Annualized DKeX run-rate ($M) | C36: =C35*365/1000000 -> 22.659345
B37: July monthly anchor ($M) | C37: =C36/12 -> 1.8882788

Sheet Reconciliation
B1: Reconciliation - to disclosures & DKeX actuals
B4: Check | C4: Modeled | D4: Disclosed/target | E4: Variance
B5: April consumer vol annualized ($B) | C5: ='Revenue Build'!F40*12/1000 -> 1 | D5: 1 | E5: =IF(D5=0,0,C5/D5-1) -> 0
B6: May consumer vol annualized ($B) | C6: ='Revenue Build'!G40*12/1000 -> 1.3 | D6: 1.3 | E6: =IF(D6=0,0,C6/D6-1) -> 0
B7: June consumer vol annualized ($B) | C7: ='Revenue Build'!H40*12/1000 -> 3.4 | D7: 3.4 | E7: =IF(D7=0,0,C7/D7-1) -> 0
B8: June total vol annualized ($B) | C8: ='Revenue Build'!H42*12/1000 -> 11.3 | D8: 11.3 | E8: =IF(D8=0,0,C8/D8-1) -> 0
B9: FY2026 Predictions investment ($M) | C9: ='Margin Build'!O17 -> 250 | D9: 250 | E9: =IF(D9=0,0,C9/D9-1) -> 0
B10: FY2026 Predictions EBITDA ($M) | C10: ='Margin Build'!O25 -> -310.17568 | D10: -300 | E10: =IF(D10=0,0,C10/D10-1) -> 0.033918941
B11: FY2030 total volume ($B) | C11: ='Revenue Build'!S42/1000 -> 76.270083 | D11: 67.5 | E11: =IF(D11=0,0,C11/D11-1) -> 0.12992715
B12: FY2030 EBITDA margin | C12: ='Margin Build'!S26 -> 0.38776951 | D12: 0.3 | E12: =IF(D12=0,0,C12/D12-1) -> 0.29256502
B13: DKeX July vol annualized ($M) vs actual | C13: ='Revenue Build'!I44*12 -> 56.648364 | D13: =DKeX_Actuals!C36 -> 22.659345 | E13: =IF(D13=0,0,C13/D13-1) -> 1.5
B15: Apr/May/Jun consumer & total are locked to DK disclosures (Revenue Build profiles).
