Workbook

Sheet EV-EBITDA Walk
A1: FWONK — LOOK THROUGH THE NOISE: 2028E VALUATION ANCHORS REGARDLESS OF ME OUTCOME
A2: EV = $25.2B (static) | Bernstein 2026E | Revenue retention: promo 100% lost, media ~5%, spon ~25%, other ~70%
B4: 2026E | C4: 2027E | D4: 2028E | E4: 26E uFCF/EV | F4: 27E uFCF/EV | G4: 28E uFCF/EV | H4: 26E lFCF/Eq | I4: 27E lFCF/Eq | J4: 28E lFCF/Eq
A5: FWONK Consolidated OIBDA — Base Case | B5: =Assumptions!B66 -> 1200 | C5: =Assumptions!C66 -> 1338 | D5: =Assumptions!D66 -> 1485
A6: Base Case EV / OIBDA | B6: =Assumptions!B61/B5 -> 21 | C6: =Assumptions!B61/C5 -> 18.834081 | D6: =Assumptions!B61/D5 -> 16.969697 | E6: =(B5-Assumptions!B69)/Assumptions!B61 -> 0.043055556 | F6: =(C5-Assumptions!C69)/Assumptions!B61 -> 0.048333333 | G6: =(D5-Assumptions!D69)/Assumptions!B61 -> 0.053968254 | H6: =(B5-Assumptions!B69-Assumptions!B71-MAX(0,Assumptions!B72*(B5-Assumptions!B70-Assumptions!B71)))/Assumptions!B59 -> 0.035880952 | I6: =(C5-Assumptions!C69-Assumptions!C71-MAX(0,Assumptions!C72*(C5-Assumptions!C70-Assumptions!C71)))/Assumptions!B59 -> 0.040801905 | J6: =(D5-Assumptions!D69-Assumptions!D71-MAX(0,Assumptions!D72*(D5-Assumptions!D70-Assumptions!D71)))/Assumptions!B59 -> 0.046480952
A8: 2026 SCENARIOS
B9: 2026E | C9: 2027E | D9: 2028E | E9: 26E uFCF/EV | F9: 27E uFCF/EV | G9: 28E uFCF/EV | H9: 26E lFCF/Eq | I9: 27E lFCF/Eq | J9: 28E lFCF/Eq
A10: A) BH+SA cancelled (confirmed); rest runs | B10: ='2026 Scenarios'!C8 -> 1093.8989 | C10: =Assumptions!C66 -> 1338 | D10: =Assumptions!D66 -> 1485
A11: EV / OIBDA | B11: =Assumptions!B61/B10 -> 23.036863 | C11: =Assumptions!B61/C10 -> 18.834081 | D11: =Assumptions!B61/D10 -> 16.969697 | E11: =(B10-Assumptions!B69)/Assumptions!B61 -> 0.038845195 | F11: =(C10-Assumptions!C69)/Assumptions!B61 -> 0.048333333 | G11: =(D10-Assumptions!D69)/Assumptions!B61 -> 0.053968254 | H11: =(B10-Assumptions!B69-Assumptions!B71-MAX(0,Assumptions!B72*(B10-Assumptions!B70-Assumptions!B71)))/Assumptions!B59 -> 0.031586385 | I11: =(C10-Assumptions!C69-Assumptions!C71-MAX(0,Assumptions!C72*(C10-Assumptions!C70-Assumptions!C71)))/Assumptions!B59 -> 0.040801905 | J11: =(D10-Assumptions!D69-Assumptions!D71-MAX(0,Assumptions!D72*(D10-Assumptions!D70-Assumptions!D71)))/Assumptions!B59 -> 0.046480952
A12: B) Full ME out; EU repl. for AZE/QAT/ABU | B12: ='2026 Scenarios'!C15 -> 1150.2989 | C12: =Assumptions!C66 -> 1338 | D12: =Assumptions!D66 -> 1485
A13: EV / OIBDA | B13: =Assumptions!B61/B12 -> 21.907349 | C13: =Assumptions!B61/C12 -> 18.834081 | D13: =Assumptions!B61/D12 -> 16.969697 | E13: =(B12-Assumptions!B69)/Assumptions!B61 -> 0.04108329 | F13: =(C12-Assumptions!C69)/Assumptions!B61 -> 0.048333333 | G13: =(D12-Assumptions!D69)/Assumptions!B61 -> 0.053968254 | H13: =(B12-Assumptions!B69-Assumptions!B71-MAX(0,Assumptions!B72*(B12-Assumptions!B70-Assumptions!B71)))/Assumptions!B59 -> 0.033869242 | I13: =(C12-Assumptions!C69-Assumptions!C71-MAX(0,Assumptions!C72*(C12-Assumptions!C70-Assumptions!C71)))/Assumptions!B59 -> 0.040801905 | J13: =(D12-Assumptions!D69-Assumptions!D71-MAX(0,Assumptions!D72*(D12-Assumptions!D70-Assumptions!D71)))/Assumptions!B59 -> 0.046480952
A14: C) Full ME out; NO replacements | B14: ='2026 Scenarios'!C21 -> 934.7473 | C14: =Assumptions!C66 -> 1338 | D14: =Assumptions!D66 -> 1485
A15: EV / OIBDA | B15: =Assumptions!B61/B14 -> 26.959158 | C15: =Assumptions!B61/C14 -> 18.834081 | D15: =Assumptions!B61/D14 -> 16.969697 | E15: =(B14-Assumptions!B69)/Assumptions!B61 -> 0.032529655 | F15: =(C14-Assumptions!C69)/Assumptions!B61 -> 0.048333333 | G15: =(D14-Assumptions!D69)/Assumptions!B61 -> 0.053968254 | H15: =(B14-Assumptions!B69-Assumptions!B71-MAX(0,Assumptions!B72*(B14-Assumptions!B70-Assumptions!B71)))/Assumptions!B59 -> 0.025144534 | I15: =(C14-Assumptions!C69-Assumptions!C71-MAX(0,Assumptions!C72*(C14-Assumptions!C70-Assumptions!C71)))/Assumptions!B59 -> 0.040801905 | J15: =(D14-Assumptions!D69-Assumptions!D71-MAX(0,Assumptions!D72*(D14-Assumptions!D70-Assumptions!D71)))/Assumptions!B59 -> 0.046480952
A17: 2026 + 2027 COMBINED SCENARIOS (Conflict Persists Through 2027)
B18: 2026E | C18: 2027E | D18: 2028E | E18: 26E uFCF/EV | F18: 27E uFCF/EV | G18: 28E uFCF/EV | H18: 26E lFCF/Eq | I18: 27E lFCF/Eq | J18: 28E lFCF/Eq
A19: B+D) '26: EU repl AZE/QAT/ABU | '27: No repl | B19: ='2026 Scenarios'!C15 -> 1150.2989 | C19: ='2027 Scenarios'!C7 -> 1072.7473 | D19: =Assumptions!D66 -> 1485
A20: EV / OIBDA | B20: =Assumptions!B61/B19 -> 21.907349 | C20: =Assumptions!B61/C19 -> 23.491087 | D20: =Assumptions!B61/D19 -> 16.969697 | E20: =(B19-Assumptions!B69)/Assumptions!B61 -> 0.04108329 | F20: =(C19-Assumptions!C69)/Assumptions!B61 -> 0.037807433 | G20: =(D19-Assumptions!D69)/Assumptions!B61 -> 0.053968254 | H20: =(B19-Assumptions!B69-Assumptions!B71-MAX(0,Assumptions!B72*(B19-Assumptions!B70-Assumptions!B71)))/Assumptions!B59 -> 0.033869242 | I20: =(C19-Assumptions!C69-Assumptions!C71-MAX(0,Assumptions!C72*(C19-Assumptions!C70-Assumptions!C71)))/Assumptions!B59 -> 0.030318108 | J20: =(D19-Assumptions!D69-Assumptions!D71-MAX(0,Assumptions!D72*(D19-Assumptions!D70-Assumptions!D71)))/Assumptions!B59 -> 0.046480952
A21: B+E) '26: EU repl AZE/QAT/ABU | '27: EU repl all 5 | B21: ='2026 Scenarios'!C15 -> 1150.2989 | C21: ='2027 Scenarios'!C13 -> 1432 | D21: =Assumptions!D66 -> 1485
A22: EV / OIBDA | B22: =Assumptions!B61/B21 -> 21.907349 | C22: =Assumptions!B61/C21 -> 17.597765 | D22: =Assumptions!B61/D21 -> 16.969697 | E22: =(B21-Assumptions!B69)/Assumptions!B61 -> 0.04108329 | F22: =(C21-Assumptions!C69)/Assumptions!B61 -> 0.052063492 | G22: =(D21-Assumptions!D69)/Assumptions!B61 -> 0.053968254 | H22: =(B21-Assumptions!B69-Assumptions!B71-MAX(0,Assumptions!B72*(B21-Assumptions!B70-Assumptions!B71)))/Assumptions!B59 -> 0.033869242 | I22: =(C21-Assumptions!C69-Assumptions!C71-MAX(0,Assumptions!C72*(C21-Assumptions!C70-Assumptions!C71)))/Assumptions!B59 -> 0.044517143 | J22: =(D21-Assumptions!D69-Assumptions!D71-MAX(0,Assumptions!D72*(D21-Assumptions!D70-Assumptions!D71)))/Assumptions!B59 -> 0.046480952
A23: C+D) '26: No repl | '27: No repl [WORST CASE] | B23: ='2026 Scenarios'!C21 -> 934.7473 | C23: ='2027 Scenarios'!C7 -> 1072.7473 | D23: =Assumptions!D66 -> 1485
A24: EV / OIBDA | B24: =Assumptions!B61/B23 -> 26.959158 | C24: =Assumptions!B61/C23 -> 23.491087 | D24: =Assumptions!B61/D23 -> 16.969697 | E24: =(B23-Assumptions!B69)/Assumptions!B61 -> 0.032529655 | F24: =(C23-Assumptions!C69)/Assumptions!B61 -> 0.037807433 | G24: =(D23-Assumptions!D69)/Assumptions!B61 -> 0.053968254 | H24: =(B23-Assumptions!B69-Assumptions!B71-MAX(0,Assumptions!B72*(B23-Assumptions!B70-Assumptions!B71)))/Assumptions!B59 -> 0.025144534 | I24: =(C23-Assumptions!C69-Assumptions!C71-MAX(0,Assumptions!C72*(C23-Assumptions!C70-Assumptions!C71)))/Assumptions!B59 -> 0.030318108 | J24: =(D23-Assumptions!D69-Assumptions!D71-MAX(0,Assumptions!D72*(D23-Assumptions!D70-Assumptions!D71)))/Assumptions!B59 -> 0.046480952
A25: C+E) '26: No repl | '27: EU repl all 5 | B25: ='2026 Scenarios'!C21 -> 934.7473 | C25: ='2027 Scenarios'!C13 -> 1432 | D25: =Assumptions!D66 -> 1485
A26: EV / OIBDA | B26: =Assumptions!B61/B25 -> 26.959158 | C26: =Assumptions!B61/C25 -> 17.597765 | D26: =Assumptions!B61/D25 -> 16.969697 | E26: =(B25-Assumptions!B69)/Assumptions!B61 -> 0.032529655 | F26: =(C25-Assumptions!C69)/Assumptions!B61 -> 0.052063492 | G26: =(D25-Assumptions!D69)/Assumptions!B61 -> 0.053968254 | H26: =(B25-Assumptions!B69-Assumptions!B71-MAX(0,Assumptions!B72*(B25-Assumptions!B70-Assumptions!B71)))/Assumptions!B59 -> 0.025144534 | I26: =(C25-Assumptions!C69-Assumptions!C71-MAX(0,Assumptions!C72*(C25-Assumptions!C70-Assumptions!C71)))/Assumptions!B59 -> 0.044517143 | J26: =(D25-Assumptions!D69-Assumptions!D71-MAX(0,Assumptions!D72*(D25-Assumptions!D70-Assumptions!D71)))/Assumptions!B59 -> 0.046480952
A28: Notes:
A29: 1. Static EV ($25.2B) assumed throughout — multiples expand on lower EBITDA, all else equal
A30: 2. Revenue retention per Ian Moore: promo 100% lost, media ~5%, spon ~25%, other ~70% → ~55% of allocated rev retained
A31: 3. Net EBITDA hit per replaced race = hosting fee shortfall only (~$17M); media/spon/other revenue fully recovered
A32: 4. BH+SA confirmed cancelled 3/14/2026 with no replacement → 22-race calendar. AZE (Sept), QAT (Nov), ABU (Dec) at risk
A33: 5. Team payment reduction assumed at 40% of per-race allocation (Concorde partially adjusts to lower profitability)
A34: 5. Team payment reduction assumed at 40% of per-race allocation (Concorde partially adjusts)
A35: 6. FCF assumptions are placeholders — link to financial model via Assumptions tab cells B69:D73
A36: 7. uFCF/EV = (OIBDA - Capex) / EV. lFCF/Eq = (OIBDA - Capex - Int - Taxes) / Mkt Cap
A38: THE LOOK-THROUGH: 2028E MULTIPLE IS 17.0x IN EVERY SCENARIO
A39: 2028E OIBDA is unaffected by ME disruption — all scenarios revert to full 24-race calendar
A41: Implied Share Price at Target 2028E EV/OIBDA | B41: Multiple | C41: Implied EV ($M) | D41: Implied Equity ($M) | E41: Implied $/sh | F41: % vs Current | G41: uFCF/EV
A42: Current (spot) | B42: =Assumptions!B61/Assumptions!D66 -> 16.969697 | C42: =B42*Assumptions!D66 -> 25200 | D42: =C42-Assumptions!B60 -> 21000 | E42: =D42/Assumptions!B58 -> 84 | F42: =(E42/Assumptions!B57)-1 -> 0 | G42: =(Assumptions!D66-Assumptions!D69)/C42 -> 0.053968254
A43: 15.0x | B43: 15 | C43: =B43*Assumptions!D66 -> 22275 | D43: =C43-Assumptions!B60 -> 18075 | E43: =D43/Assumptions!B58 -> 72.3 | F43: =(E43/Assumptions!B57)-1 -> -0.13928571 | G43: =(Assumptions!D66-Assumptions!D69)/C43 -> 0.061054994
A44: 17.5x | B44: 17.5 | C44: =B44*Assumptions!D66 -> 25987.5 | D44: =C44-Assumptions!B60 -> 21787.5 | E44: =D44/Assumptions!B58 -> 87.15 | F44: =(E44/Assumptions!B57)-1 -> 0.0375 | G44: =(Assumptions!D66-Assumptions!D69)/C44 -> 0.052332852
A45: 20.0x | B45: 20 | C45: =B45*Assumptions!D66 -> 29700 | D45: =C45-Assumptions!B60 -> 25500 | E45: =D45/Assumptions!B58 -> 102 | F45: =(E45/Assumptions!B57)-1 -> 0.21428571 | G45: =(Assumptions!D66-Assumptions!D69)/C45 -> 0.045791246
A46: 22.5x | B46: 22.5 | C46: =B46*Assumptions!D66 -> 33412.5 | D46: =C46-Assumptions!B60 -> 29212.5 | E46: =D46/Assumptions!B58 -> 116.85 | F46: =(E46/Assumptions!B57)-1 -> 0.39107143 | G46: =(Assumptions!D66-Assumptions!D69)/C46 -> 0.04070333
...

Sheet Assumptions
A1: FWONK — ME Disruption Model: Assumptions & Per-Race Economics
A2: Anchored to Bernstein 2026E F1 estimates from per-race EBITDA model (March 2026)
A4: Bernstein 2026E F1 Estimates | B4: Value | G4: Source / Note
A5: Total F1 Revenue ($M) | B5: 4254 | G5: Bernstein 2026E
A6: Number of Races (Original Calendar) | B6: 24
A7: Adjusted OIBDA ($M) | B7: 1148 | G7: Bernstein 2026E
A8: Race Promotion Revenue ($M) | B8: 1106
A9: Media Rights Revenue ($M) | B9: 1329
A10: Sponsorship Revenue ($M) | B10: 957
A11: Other Revenue ($M) | B11: 861
A13: Cost Structure | B13: Value | G13: Note
A14: Total Costs ($M) | B14: =B5-B7 -> 3106
A15: Team Payments ($M) | B15: 1450 | G15: Concorde Agreement; 11 teams in 2026 incl. Cadillac
A16: Variable OpEx ($M) | B16: 1200 | G16: Logistics, hospitality COGS, commissions; ~38% of non-promo rev
A17: Fixed Overhead ($M) [plug] | B17: =B14-B15-B16 -> 456 | G17: SGA, personnel, D&A; non-scalable with # of races
A19: Derived Rates | B19: Value
A20: Variable Cost Rate (% of non-promo rev) | B20: =B16/(B9+B10+B11) -> 0.38131554
A21: Fixed Cost per Race ($M) | B21: =B17/B6 -> 19
A22: Team Payment per Race ($M) | B22: =B15/B6 -> 60.416667
A23: Avg Revenue per Race ($M) | B23: =B5/B6 -> 177.25
A25: ME Race-Level Economics | B25: Hosting Fee | C25: Non-Promo Rev | D25: Total Rev | E25: Alloc EBITDA | F25: Status
A26: Bahrain GP | B26: 60 | C26: 128 | D26: =B26+C26 -> 188 | E26: =D26 - (B$20*C26) - B$21 - B$22 -> 59.774944 | F26: Cancelled — confirmed 3/14
A27: Saudi Arabia GP | B27: 55 | C27: 137 | D27: =B27+C27 -> 192 | E27: =D27 - (B$20*C27) - B$21 - B$22 -> 60.343105 | F27: Cancelled — confirmed 3/14
A28: Azerbaijan GP (Baku) | B28: 57 | C28: 133 | D28: =B28+C28 -> 190 | E28: =D28 - (B$20*C28) - B$21 - B$22 -> 59.868367 | F28: At risk — Sept 26; Iran struck Baku
A29: Qatar GP (Lusail) | B29: 55 | C29: 133 | D29: =B29+C29 -> 188 | E29: =D29 - (B$20*C29) - B$21 - B$22 -> 57.868367 | F29: At risk — Nov 29; Doha airport closed
A30: Abu Dhabi GP (Yas Marina) | B30: 42 | C30: 133 | D30: =B30+C30 -> 175 | E30: =D30 - (B$20*C30) - B$21 - B$22 -> 44.868367 | F30: At risk — Dec 6; UAE struck by Iran
A31: Total All 5 ME Races | B31: =SUM(B26:B30) -> 269 | C31: =SUM(C26:C30) -> 664 | D31: =SUM(D26:D30) -> 933 | E31: =SUM(E26:E30) -> 282.72315
A32: % of F1 Total | D32: =D31/B5 -> 0.21932299 | E32: =E31/B7 -> 0.24627452
A34: Revenue Retention on Cancellation (No Repl) | B34: % Lost | C34: % Retained | D34: Avg $/Race | E34: $ Lost/Race | G34: Rationale
A35: Race Promotion Fee | B35: 1 | C35: =1-B35 -> 0 | D35: =B31/5 -> 53.8 | E35: =B35*D35 -> 53.8 | G35: Hosting fee zero if no race. Full loss.
A36: Media Rights | B36: 0.05 | C36: =1-B36 -> 0.95 | D36: =B9/B6 -> 55.375 | E36: =B36*D36 -> 2.76875 | G36: Annual contracts (Sky/ESPN/Netflix). Small rebate for fewer races.
A37: Sponsorship | B37: 0.25 | C37: =1-B37 -> 0.75 | D37: =B10/B6 -> 39.875 | E37: =B37*D37 -> 9.96875 | G37: Season commitments; per-race activation + regional sponsors (Aramco) lost.
A38: Other (Paddock Club, freight, F2/F3) | B38: 0.7 | C38: =1-B38 -> 0.3 | D38: =B11/B6 -> 35.875 | E38: =B38*D38 -> 25.1125 | G38: Hospitality + freight + support series largely event-driven.
A39: Total Revenue Lost per Cancelled Race | E39: =SUM(E35:E38) -> 91.65
A40: Memo: Full Allocated Rev/Race | E40: =D31/5 -> 186.6
A41: Revenue Retention Rate | E41: =1-(E39/E40) -> 0.50884244
A43: Revised Net EBITDA Hit per Cancelled Race (No Repl) | B43: $M
A44: Revenue Lost | B44: =E39 -> 91.65
A45: Less: Variable Costs Avoided | B45: =-B20*(E36+E37+E38) -> -14.432793 | G45: VCR applied to non-promo revenue lost only
A46: Team Payment Reduction Assumption | B46: 0.4
...

Sheet 2026 Scenarios
A1: FWONK — 2026 ME Disruption Scenarios
A2: BH + SA already confirmed cancelled with no replacement. Scenarios vary treatment of AZE/QAT/ABU.
A4: SCENARIO A: BH + SA Cancelled Only (confirmed) | B4: Races | C4: EBITDA Hit ($M)
A5: BH + SA Net EBITDA Impact (no replacement, confirmed) | B5: 2 | C5: =Assumptions!B48*2 -> 106.10108
A6: AZE / QAT / ABU → Assumed to run as scheduled | B6: 0 | C6: 0
A7: Total 2026 EBITDA Haircut — Scenario A | C7: =C5+C6 -> 106.10108
A8: Adjusted FWONK 2026E OIBDA | C8: =Assumptions!B66-C7 -> 1093.8989
A9: EV / Adjusted OIBDA | C9: =Assumptions!B61/C8 -> 23.036863
A11: SCENARIO B: Full 2026 ME Out — EU Replacements for 3 remaining | B11: Races | C11: EBITDA Hit ($M)
A12: BH + SA Net EBITDA Impact (no replacement) | B12: 2 | C12: =Assumptions!B48*2 -> 106.10108
A13: AZE + QAT + ABU → Cancelled, replaced with EU races | B13: 3 | C13: =Assumptions!B54*3 -> -56.4 | F13: Only hosting fee shortfall vs ME; media/spon recovered
A14: Total 2026 EBITDA Haircut — Scenario B | C14: =C12+C13 -> 49.70108
A15: Adjusted FWONK 2026E OIBDA | C15: =Assumptions!B66-C14 -> 1150.2989
A16: EV / Adjusted OIBDA | C16: =Assumptions!B61/C15 -> 21.907349
A18: SCENARIO C: Full 2026 ME Out — NO Replacements | B18: Races | C18: EBITDA Hit ($M)
A19: All 5 ME Races Net EBITDA Impact (no replacement) | B19: 5 | C19: =Assumptions!B48*5 -> 265.2527
A20: Total 2026 EBITDA Haircut — Scenario C | C20: =C19 -> 265.2527
A21: Adjusted FWONK 2026E OIBDA | C21: =Assumptions!B66-C20 -> 934.7473
A22: EV / Adjusted OIBDA | C22: =Assumptions!B61/C21 -> 26.959158

Sheet 2027 Scenarios
A1: FWONK — 2027 ME Disruption Scenarios (Conflict Persists)
A2: Assumes full 2027 ME calendar also disrupted. 2028 reverts to normal.
A4: SCENARIO D: Full 2027 ME Out — NO Replacements | B4: Races | C4: EBITDA Hit ($M)
A5: All 5 ME Races Net EBITDA Impact (no replacement) | B5: 5 | C5: =Assumptions!B48*5 -> 265.2527 | F5: Same per-race mechanics; slight conservatism (no fee escalators)
A6: Total 2027 EBITDA Haircut — Scenario D | C6: =C5 -> 265.2527
A7: Adjusted FWONK 2027E OIBDA | C7: =Assumptions!C66-C6 -> 1072.7473
A8: EV / Adjusted OIBDA | C8: =Assumptions!B61/C7 -> 23.491087
A10: SCENARIO E: Full 2027 ME Out — EU Replacements for all 5 | B10: Races | C10: EBITDA Hit ($M)
A11: All 5 ME Races → Replaced with EU circuits | B11: 5 | C11: =Assumptions!B54*5 -> -94 | F11: Only hosting fee shortfall; media/spon/other fully recovered
A12: Total 2027 EBITDA Haircut — Scenario E | C12: =C11 -> -94
A13: Adjusted FWONK 2027E OIBDA | C13: =Assumptions!C66-C12 -> 1432
A14: EV / Adjusted OIBDA | C14: =Assumptions!B61/C13 -> 17.597765
