Workbook

Sheet Summary
A1: The K-pop boom is a Live Nation story
A2: Joint note · LYV section · the geographic case + the moat. Source: Pollstar Data Cloud (Boxoffice), Asian Pop, pulled Jun-2026.
A4: US = largest K-pop market | D4: LN share of US K-pop | G4: LN share of Western K-pop | J4: Self-promotion risk
A5: =Analysis_Geographic!B11/1000 -> 1.0147558 | D5: =Analysis_Geographic!D11 -> 0.45216031 | G5: =Analysis_Geographic!D6 -> 0.50200042 | J5: HYBE only
A8: Two exhibits, two jobs
A9: EX 1 (Geography) — assert the thesis.
A10: The US is the single largest K-pop touring market in the world (~$1.0bn, ahead of Japan) and Spotify's #1 K-pop streaming market. LN promotes ~45% of US K-pop, ~80% of Mexico via OCESA, ~59% of France/UK — and ~50% of all Western K-pop gross, vs ~2% in Asia. The boom is Western; the West is LN's.
A13: EX 2 (Segmentation) — defend it.
A14: Promoter tracks the agency, not the genre. JYP's touring is ~95-97% Live Nation (Stray Kids, TWICE); the other majors largely ride LN or AEG. Self-promotion — the one structural threat — is contained to HYBE alone.
A17: Precision (what the exhibits don't say).
A18: LN's Western share is sticky, not rising — ~half across the cycle but lumpy year to year on tour timing. The geographic claim is that the US is the largest and highest-ARPU market, not that the West is taking share from a still-growing Asia. Even HYBE co-promotes ~35% of its US grosses with LN.
A22: Tabs: Exhibit_1_Geography · Exhibit_2_Segmentation · Analysis_Geographic · Analysis_ActSegmentation · Data_AsianPop (1,629 boxscores). All figures live SUMIFS over the data.

Sheet Exhibit_1_Geography
A1: Exhibit 1 — The K-pop boom is migrating into Live Nation's markets
A2: K-pop touring gross by market ($mm, tracked lifetime); Live Nation share noted. US is the largest market; ~half is LN. Source: Pollstar Data Cloud.
A4: Market | B4: LN ($mm) | C4: Other ($mm)
A5: United States | B5: =SUMIFS(Data_AsianPop!$V$2:$V$1630,Data_AsianPop!$H$2:$H$1630,A5,Data_AsianPop!$X$2:$X$1630,1)/1000000 -> 458.8323 | C5: =(SUMIFS(Data_AsianPop!$V$2:$V$1630,Data_AsianPop!$H$2:$H$1630,A5)-SUMIFS(Data_AsianPop!$V$2:$V$1630,Data_AsianPop!$H$2:$H$1630,A5,Data_AsianPop!$X$2:$X$1630,1))/1000000 -> 555.9235
A6: Japan | B6: =SUMIFS(Data_AsianPop!$V$2:$V$1630,Data_AsianPop!$H$2:$H$1630,A6,Data_AsianPop!$X$2:$X$1630,1)/1000000 -> 0 | C6: =(SUMIFS(Data_AsianPop!$V$2:$V$1630,Data_AsianPop!$H$2:$H$1630,A6)-SUMIFS(Data_AsianPop!$V$2:$V$1630,Data_AsianPop!$H$2:$H$1630,A6,Data_AsianPop!$X$2:$X$1630,1))/1000000 -> 734.47539
A7: China | B7: =SUMIFS(Data_AsianPop!$V$2:$V$1630,Data_AsianPop!$H$2:$H$1630,A7,Data_AsianPop!$X$2:$X$1630,1)/1000000 -> 4.4031176 | C7: =(SUMIFS(Data_AsianPop!$V$2:$V$1630,Data_AsianPop!$H$2:$H$1630,A7)-SUMIFS(Data_AsianPop!$V$2:$V$1630,Data_AsianPop!$H$2:$H$1630,A7,Data_AsianPop!$X$2:$X$1630,1))/1000000 -> 144.35296
A8: Mexico | B8: =SUMIFS(Data_AsianPop!$V$2:$V$1630,Data_AsianPop!$H$2:$H$1630,A8,Data_AsianPop!$X$2:$X$1630,1)/1000000 -> 115.38847 | C8: =(SUMIFS(Data_AsianPop!$V$2:$V$1630,Data_AsianPop!$H$2:$H$1630,A8)-SUMIFS(Data_AsianPop!$V$2:$V$1630,Data_AsianPop!$H$2:$H$1630,A8,Data_AsianPop!$X$2:$X$1630,1))/1000000 -> 27.956869
A9: South Korea | B9: =SUMIFS(Data_AsianPop!$V$2:$V$1630,Data_AsianPop!$H$2:$H$1630,A9,Data_AsianPop!$X$2:$X$1630,1)/1000000 -> 0 | C9: =(SUMIFS(Data_AsianPop!$V$2:$V$1630,Data_AsianPop!$H$2:$H$1630,A9)-SUMIFS(Data_AsianPop!$V$2:$V$1630,Data_AsianPop!$H$2:$H$1630,A9,Data_AsianPop!$X$2:$X$1630,1))/1000000 -> 135.13456
A10: Hong Kong | B10: =SUMIFS(Data_AsianPop!$V$2:$V$1630,Data_AsianPop!$H$2:$H$1630,A10,Data_AsianPop!$X$2:$X$1630,1)/1000000 -> 6.8391455 | C10: =(SUMIFS(Data_AsianPop!$V$2:$V$1630,Data_AsianPop!$H$2:$H$1630,A10)-SUMIFS(Data_AsianPop!$V$2:$V$1630,Data_AsianPop!$H$2:$H$1630,A10,Data_AsianPop!$X$2:$X$1630,1))/1000000 -> 122.37408
A11: France | B11: =SUMIFS(Data_AsianPop!$V$2:$V$1630,Data_AsianPop!$H$2:$H$1630,A11,Data_AsianPop!$X$2:$X$1630,1)/1000000 -> 52.039415 | C11: =(SUMIFS(Data_AsianPop!$V$2:$V$1630,Data_AsianPop!$H$2:$H$1630,A11)-SUMIFS(Data_AsianPop!$V$2:$V$1630,Data_AsianPop!$H$2:$H$1630,A11,Data_AsianPop!$X$2:$X$1630,1))/1000000 -> 36.182069
A12: United Kingdom | B12: =SUMIFS(Data_AsianPop!$V$2:$V$1630,Data_AsianPop!$H$2:$H$1630,A12,Data_AsianPop!$X$2:$X$1630,1)/1000000 -> 50.247136 | C12: =(SUMIFS(Data_AsianPop!$V$2:$V$1630,Data_AsianPop!$H$2:$H$1630,A12)-SUMIFS(Data_AsianPop!$V$2:$V$1630,Data_AsianPop!$H$2:$H$1630,A12,Data_AsianPop!$X$2:$X$1630,1))/1000000 -> 35.143145
A13: Australia | B13: =SUMIFS(Data_AsianPop!$V$2:$V$1630,Data_AsianPop!$H$2:$H$1630,A13,Data_AsianPop!$X$2:$X$1630,1)/1000000 -> 14.416621 | C13: =(SUMIFS(Data_AsianPop!$V$2:$V$1630,Data_AsianPop!$H$2:$H$1630,A13)-SUMIFS(Data_AsianPop!$V$2:$V$1630,Data_AsianPop!$H$2:$H$1630,A13,Data_AsianPop!$X$2:$X$1630,1))/1000000 -> 60.324753

Sheet Exhibit_2_Segmentation
A1: Exhibit 2 — Promoter tracks the agency: the moat is broad, the risk is named
A2: Lifetime tracked gross by act, split by promoter, clustered by agency. JYP rides Live Nation (~95%); self-promotion is contained to HYBE. Source: Pollstar Data Cloud.
A4: Act | B4: LN ($mm) | C4: Other ($mm)
A5: BTS (HYBE) | B5: =SUMIFS(Data_AsianPop!$V$2:$V$1630,Data_AsianPop!$C$2:$C$1630,"BTS",Data_AsianPop!$X$2:$X$1630,1)/1000000 -> 138.55167 | C5: =(SUMIFS(Data_AsianPop!$V$2:$V$1630,Data_AsianPop!$C$2:$C$1630,"BTS")-SUMIFS(Data_AsianPop!$V$2:$V$1630,Data_AsianPop!$C$2:$C$1630,"BTS",Data_AsianPop!$X$2:$X$1630,1))/1000000 -> 287.51612
A6: SEVENTEEN (HYBE) | B6: =SUMIFS(Data_AsianPop!$V$2:$V$1630,Data_AsianPop!$C$2:$C$1630,"SEVENTEEN",Data_AsianPop!$X$2:$X$1630,1)/1000000 -> 60.960052 | C6: =(SUMIFS(Data_AsianPop!$V$2:$V$1630,Data_AsianPop!$C$2:$C$1630,"SEVENTEEN")-SUMIFS(Data_AsianPop!$V$2:$V$1630,Data_AsianPop!$C$2:$C$1630,"SEVENTEEN",Data_AsianPop!$X$2:$X$1630,1))/1000000 -> 341.60145
A7: TXT (HYBE) | B7: =SUMIFS(Data_AsianPop!$V$2:$V$1630,Data_AsianPop!$C$2:$C$1630,"TOMORROW X TOGETHER",Data_AsianPop!$X$2:$X$1630,1)/1000000 -> 20.204609 | C7: =(SUMIFS(Data_AsianPop!$V$2:$V$1630,Data_AsianPop!$C$2:$C$1630,"TOMORROW X TOGETHER")-SUMIFS(Data_AsianPop!$V$2:$V$1630,Data_AsianPop!$C$2:$C$1630,"TOMORROW X TOGETHER",Data_AsianPop!$X$2:$X$1630,1))/1000000 -> 217.59703
A8: ENHYPEN (HYBE) | B8: =SUMIFS(Data_AsianPop!$V$2:$V$1630,Data_AsianPop!$C$2:$C$1630,"ENHYPEN",Data_AsianPop!$X$2:$X$1630,1)/1000000 -> 0 | C8: =(SUMIFS(Data_AsianPop!$V$2:$V$1630,Data_AsianPop!$C$2:$C$1630,"ENHYPEN")-SUMIFS(Data_AsianPop!$V$2:$V$1630,Data_AsianPop!$C$2:$C$1630,"ENHYPEN",Data_AsianPop!$X$2:$X$1630,1))/1000000 -> 192.90105
A9: j-hope (HYBE) | B9: =SUMIFS(Data_AsianPop!$V$2:$V$1630,Data_AsianPop!$C$2:$C$1630,"j-hope",Data_AsianPop!$X$2:$X$1630,1)/1000000 -> 34.2336 | C9: =(SUMIFS(Data_AsianPop!$V$2:$V$1630,Data_AsianPop!$C$2:$C$1630,"j-hope")-SUMIFS(Data_AsianPop!$V$2:$V$1630,Data_AsianPop!$C$2:$C$1630,"j-hope",Data_AsianPop!$X$2:$X$1630,1))/1000000 -> 44.948614
A10: Stray Kids (JYP) | B10: =SUMIFS(Data_AsianPop!$V$2:$V$1630,Data_AsianPop!$C$2:$C$1630,"Stray Kids",Data_AsianPop!$X$2:$X$1630,1)/1000000 -> 210.61829 | C10: =(SUMIFS(Data_AsianPop!$V$2:$V$1630,Data_AsianPop!$C$2:$C$1630,"Stray Kids")-SUMIFS(Data_AsianPop!$V$2:$V$1630,Data_AsianPop!$C$2:$C$1630,"Stray Kids",Data_AsianPop!$X$2:$X$1630,1))/1000000 -> 5.7073576
A11: TWICE (JYP) | B11: =SUMIFS(Data_AsianPop!$V$2:$V$1630,Data_AsianPop!$C$2:$C$1630,"TWICE",Data_AsianPop!$X$2:$X$1630,1)/1000000 -> 129.31251 | C11: =(SUMIFS(Data_AsianPop!$V$2:$V$1630,Data_AsianPop!$C$2:$C$1630,"TWICE")-SUMIFS(Data_AsianPop!$V$2:$V$1630,Data_AsianPop!$C$2:$C$1630,"TWICE",Data_AsianPop!$X$2:$X$1630,1))/1000000 -> 6.692779
A12: BLACKPINK (YG) | B12: =SUMIFS(Data_AsianPop!$V$2:$V$1630,Data_AsianPop!$C$2:$C$1630,"BLACKPINK",Data_AsianPop!$X$2:$X$1630,1)/1000000 -> 21.129327 | C12: =(SUMIFS(Data_AsianPop!$V$2:$V$1630,Data_AsianPop!$C$2:$C$1630,"BLACKPINK")-SUMIFS(Data_AsianPop!$V$2:$V$1630,Data_AsianPop!$C$2:$C$1630,"BLACKPINK",Data_AsianPop!$X$2:$X$1630,1))/1000000 -> 64.239779
A13: ATEEZ (KQ) | B13: =SUMIFS(Data_AsianPop!$V$2:$V$1630,Data_AsianPop!$C$2:$C$1630,"ATEEZ",Data_AsianPop!$X$2:$X$1630,1)/1000000 -> 3.7668679 | C13: =(SUMIFS(Data_AsianPop!$V$2:$V$1630,Data_AsianPop!$C$2:$C$1630,"ATEEZ")-SUMIFS(Data_AsianPop!$V$2:$V$1630,Data_AsianPop!$C$2:$C$1630,"ATEEZ",Data_AsianPop!$X$2:$X$1630,1))/1000000 -> 75.253525
E26: HYBE acts (pink) self-promote — mostly 'Other'. JYP acts (teal) ride Live Nation — mostly 'LN'.

Sheet Analysis_Geographic
A1: Geographic analysis — where the K-pop boom lands, and who promotes it
A2: Source: Pollstar Data Cloud (Boxoffice), Asian Pop genre. OCESA grouped into Live Nation. 2026 = on-sales. Live SUMIFS over Data_AsianPop.
A4: Region rollup
A5: Region | B5: Total ($mm) | C5: LN ($mm) | D5: LN share | E5: % of all K-pop
A6: Americas + Europe + ANZ | B6: =SUMIFS(Data_AsianPop!$V$2:$V$1630,Data_AsianPop!$Y$2:$Y$1630,A6)/1000000 -> 1599.7059 | C6: =SUMIFS(Data_AsianPop!$V$2:$V$1630,Data_AsianPop!$Y$2:$Y$1630,A6,Data_AsianPop!$X$2:$X$1630,1)/1000000 -> 803.05302 | D6: =IFERROR(C6/B6,0) -> 0.50200042 | E6: =B6/($B$6+$B$7) -> 0.52803374
A7: Asia / home markets | B7: =SUMIFS(Data_AsianPop!$V$2:$V$1630,Data_AsianPop!$Y$2:$Y$1630,A7)/1000000 -> 1429.8465 | C7: =SUMIFS(Data_AsianPop!$V$2:$V$1630,Data_AsianPop!$Y$2:$Y$1630,A7,Data_AsianPop!$X$2:$X$1630,1)/1000000 -> 25.448444 | D7: =IFERROR(C7/B7,0) -> 0.017798025 | E7: =B7/($B$6+$B$7) -> 0.47196626
A9: Top markets | F9: United States — LN share by year
A10: Country | B10: Total ($mm) | C10: LN ($mm) | D10: LN share | F10: Year | G10: US total ($mm) | H10: LN ($mm) | I10: LN share
A11: United States | B11: =SUMIFS(Data_AsianPop!$V$2:$V$1630,Data_AsianPop!$H$2:$H$1630,A11)/1000000 -> 1014.7558 | C11: =SUMIFS(Data_AsianPop!$V$2:$V$1630,Data_AsianPop!$H$2:$H$1630,A11,Data_AsianPop!$X$2:$X$1630,1)/1000000 -> 458.8323 | D11: =IFERROR(C11/B11,0) -> 0.45216031 | F11: 2019 | G11: =SUMIFS(Data_AsianPop!$V$2:$V$1630,Data_AsianPop!$H$2:$H$1630,"United States",Data_AsianPop!$U$2:$U$1630,F11)/1000000 -> 72.016506 | H11: =SUMIFS(Data_AsianPop!$V$2:$V$1630,Data_AsianPop!$H$2:$H$1630,"United States",Data_AsianPop!$U$2:$U$1630,F11,Data_AsianPop!$X$2:$X$1630,1)/1000000 -> 50.80566 | I11: =IFERROR(H11/G11,0) -> 0.70547244
A12: Japan | B12: =SUMIFS(Data_AsianPop!$V$2:$V$1630,Data_AsianPop!$H$2:$H$1630,A12)/1000000 -> 734.47539 | C12: =SUMIFS(Data_AsianPop!$V$2:$V$1630,Data_AsianPop!$H$2:$H$1630,A12,Data_AsianPop!$X$2:$X$1630,1)/1000000 -> 0 | D12: =IFERROR(C12/B12,0) -> 0 | F12: 2020 | G12: =SUMIFS(Data_AsianPop!$V$2:$V$1630,Data_AsianPop!$H$2:$H$1630,"United States",Data_AsianPop!$U$2:$U$1630,F12)/1000000 -> 3.5290402 | H12: =SUMIFS(Data_AsianPop!$V$2:$V$1630,Data_AsianPop!$H$2:$H$1630,"United States",Data_AsianPop!$U$2:$U$1630,F12,Data_AsianPop!$X$2:$X$1630,1)/1000000 -> 1.369149 | I12: =IFERROR(H12/G12,0) -> 0.38796639
A13: China | B13: =SUMIFS(Data_AsianPop!$V$2:$V$1630,Data_AsianPop!$H$2:$H$1630,A13)/1000000 -> 148.75608 | C13: =SUMIFS(Data_AsianPop!$V$2:$V$1630,Data_AsianPop!$H$2:$H$1630,A13,Data_AsianPop!$X$2:$X$1630,1)/1000000 -> 4.4031176 | D13: =IFERROR(C13/B13,0) -> 0.029599581 | F13: 2021 | G13: =SUMIFS(Data_AsianPop!$V$2:$V$1630,Data_AsianPop!$H$2:$H$1630,"United States",Data_AsianPop!$U$2:$U$1630,F13)/1000000 -> 34.389625 | H13: =SUMIFS(Data_AsianPop!$V$2:$V$1630,Data_AsianPop!$H$2:$H$1630,"United States",Data_AsianPop!$U$2:$U$1630,F13,Data_AsianPop!$X$2:$X$1630,1)/1000000 -> 0 | I13: =IFERROR(H13/G13,0) -> 0
A14: Mexico | B14: =SUMIFS(Data_AsianPop!$V$2:$V$1630,Data_AsianPop!$H$2:$H$1630,A14)/1000000 -> 143.34533 | C14: =SUMIFS(Data_AsianPop!$V$2:$V$1630,Data_AsianPop!$H$2:$H$1630,A14,Data_AsianPop!$X$2:$X$1630,1)/1000000 -> 115.38847 | D14: =IFERROR(C14/B14,0) -> 0.8049684 | F14: 2022 | G14: =SUMIFS(Data_AsianPop!$V$2:$V$1630,Data_AsianPop!$H$2:$H$1630,"United States",Data_AsianPop!$U$2:$U$1630,F14)/1000000 -> 156.02668 | H14: =SUMIFS(Data_AsianPop!$V$2:$V$1630,Data_AsianPop!$H$2:$H$1630,"United States",Data_AsianPop!$U$2:$U$1630,F14,Data_AsianPop!$X$2:$X$1630,1)/1000000 -> 43.577077 | I14: =IFERROR(H14/G14,0) -> 0.27929248
A15: South Korea | B15: =SUMIFS(Data_AsianPop!$V$2:$V$1630,Data_AsianPop!$H$2:$H$1630,A15)/1000000 -> 135.13456 | C15: =SUMIFS(Data_AsianPop!$V$2:$V$1630,Data_AsianPop!$H$2:$H$1630,A15,Data_AsianPop!$X$2:$X$1630,1)/1000000 -> 0 | D15: =IFERROR(C15/B15,0) -> 0 | F15: 2023 | G15: =SUMIFS(Data_AsianPop!$V$2:$V$1630,Data_AsianPop!$H$2:$H$1630,"United States",Data_AsianPop!$U$2:$U$1630,F15)/1000000 -> 194.03332 | H15: =SUMIFS(Data_AsianPop!$V$2:$V$1630,Data_AsianPop!$H$2:$H$1630,"United States",Data_AsianPop!$U$2:$U$1630,F15,Data_AsianPop!$X$2:$X$1630,1)/1000000 -> 107.13756 | I15: =IFERROR(H15/G15,0) -> 0.55216065
A16: Hong Kong | B16: =SUMIFS(Data_AsianPop!$V$2:$V$1630,Data_AsianPop!$H$2:$H$1630,A16)/1000000 -> 129.21322 | C16: =SUMIFS(Data_AsianPop!$V$2:$V$1630,Data_AsianPop!$H$2:$H$1630,A16,Data_AsianPop!$X$2:$X$1630,1)/1000000 -> 6.8391455 | D16: =IFERROR(C16/B16,0) -> 0.052929145 | F16: 2024 | G16: =SUMIFS(Data_AsianPop!$V$2:$V$1630,Data_AsianPop!$H$2:$H$1630,"United States",Data_AsianPop!$U$2:$U$1630,F16)/1000000 -> 133.06454 | H16: =SUMIFS(Data_AsianPop!$V$2:$V$1630,Data_AsianPop!$H$2:$H$1630,"United States",Data_AsianPop!$U$2:$U$1630,F16,Data_AsianPop!$X$2:$X$1630,1)/1000000 -> 48.470808 | I16: =IFERROR(H16/G16,0) -> 0.36426541
A17: France | B17: =SUMIFS(Data_AsianPop!$V$2:$V$1630,Data_AsianPop!$H$2:$H$1630,A17)/1000000 -> 88.221484 | C17: =SUMIFS(Data_AsianPop!$V$2:$V$1630,Data_AsianPop!$H$2:$H$1630,A17,Data_AsianPop!$X$2:$X$1630,1)/1000000 -> 52.039415 | D17: =IFERROR(C17/B17,0) -> 0.58987236 | F17: 2025 | G17: =SUMIFS(Data_AsianPop!$V$2:$V$1630,Data_AsianPop!$H$2:$H$1630,"United States",Data_AsianPop!$U$2:$U$1630,F17)/1000000 -> 238.47534 | H17: =SUMIFS(Data_AsianPop!$V$2:$V$1630,Data_AsianPop!$H$2:$H$1630,"United States",Data_AsianPop!$U$2:$U$1630,F17,Data_AsianPop!$X$2:$X$1630,1)/1000000 -> 143.42257 | I17: =IFERROR(H17/G17,0) -> 0.60141466
A18: United Kingdom | B18: =SUMIFS(Data_AsianPop!$V$2:$V$1630,Data_AsianPop!$H$2:$H$1630,A18)/1000000 -> 85.390281 | C18: =SUMIFS(Data_AsianPop!$V$2:$V$1630,Data_AsianPop!$H$2:$H$1630,A18,Data_AsianPop!$X$2:$X$1630,1)/1000000 -> 50.247136 | D18: =IFERROR(C18/B18,0) -> 0.58844093 | F18: 2026 | G18: =SUMIFS(Data_AsianPop!$V$2:$V$1630,Data_AsianPop!$H$2:$H$1630,"United States",Data_AsianPop!$U$2:$U$1630,F18)/1000000 -> 105.56774 | H18: =SUMIFS(Data_AsianPop!$V$2:$V$1630,Data_AsianPop!$H$2:$H$1630,"United States",Data_AsianPop!$U$2:$U$1630,F18,Data_AsianPop!$X$2:$X$1630,1)/1000000 -> 35.889313 | I18: =IFERROR(H18/G18,0) -> 0.33996477
A19: Australia | B19: =SUMIFS(Data_AsianPop!$V$2:$V$1630,Data_AsianPop!$H$2:$H$1630,A19)/1000000 -> 74.741375 | C19: =SUMIFS(Data_AsianPop!$V$2:$V$1630,Data_AsianPop!$H$2:$H$1630,A19,Data_AsianPop!$X$2:$X$1630,1)/1000000 -> 14.416621 | D19: =IFERROR(C19/B19,0) -> 0.19288676
A20: Thailand | B20: =SUMIFS(Data_AsianPop!$V$2:$V$1630,Data_AsianPop!$H$2:$H$1630,A20)/1000000 -> 61.481621 | C20: =SUMIFS(Data_AsianPop!$V$2:$V$1630,Data_AsianPop!$H$2:$H$1630,A20,Data_AsianPop!$X$2:$X$1630,1)/1000000 -> 2.3121519 | D20: =IFERROR(C20/B20,0) -> 0.037607206

Sheet Analysis_ActSegmentation
A1: Act-level promoter segmentation — agency determines the promoter
A2: Lifetime tracked gross by act, split LN vs other. Label = artist's agency (analyst-assigned). HYBE self-promotes; JYP rides Live Nation.
A4: Act | B4: Label | C4: Total ($mm) | D4: LN ($mm) | E4: Other ($mm) | F4: LN share
A5: BTS | B5: HYBE | C5: =SUMIFS(Data_AsianPop!$V$2:$V$1630,Data_AsianPop!$C$2:$C$1630,A5)/1000000 -> 426.06779 | D5: =SUMIFS(Data_AsianPop!$V$2:$V$1630,Data_AsianPop!$C$2:$C$1630,A5,Data_AsianPop!$X$2:$X$1630,1)/1000000 -> 138.55167 | E5: =C5-D5 -> 287.51612 | F5: =IFERROR(D5/C5,0) -> 0.32518691
A6: SEVENTEEN | B6: HYBE | C6: =SUMIFS(Data_AsianPop!$V$2:$V$1630,Data_AsianPop!$C$2:$C$1630,A6)/1000000 -> 402.5615 | D6: =SUMIFS(Data_AsianPop!$V$2:$V$1630,Data_AsianPop!$C$2:$C$1630,A6,Data_AsianPop!$X$2:$X$1630,1)/1000000 -> 60.960052 | E6: =C6-D6 -> 341.60145 | F6: =IFERROR(D6/C6,0) -> 0.15143041
A7: TOMORROW X TOGETHER | B7: HYBE | C7: =SUMIFS(Data_AsianPop!$V$2:$V$1630,Data_AsianPop!$C$2:$C$1630,A7)/1000000 -> 237.80164 | D7: =SUMIFS(Data_AsianPop!$V$2:$V$1630,Data_AsianPop!$C$2:$C$1630,A7,Data_AsianPop!$X$2:$X$1630,1)/1000000 -> 20.204609 | E7: =C7-D7 -> 217.59703 | F7: =IFERROR(D7/C7,0) -> 0.084964128
A8: ENHYPEN | B8: HYBE | C8: =SUMIFS(Data_AsianPop!$V$2:$V$1630,Data_AsianPop!$C$2:$C$1630,A8)/1000000 -> 192.90105 | D8: =SUMIFS(Data_AsianPop!$V$2:$V$1630,Data_AsianPop!$C$2:$C$1630,A8,Data_AsianPop!$X$2:$X$1630,1)/1000000 -> 0 | E8: =C8-D8 -> 192.90105 | F8: =IFERROR(D8/C8,0) -> 0
A9: j-hope | B9: HYBE | C9: =SUMIFS(Data_AsianPop!$V$2:$V$1630,Data_AsianPop!$C$2:$C$1630,A9)/1000000 -> 79.182215 | D9: =SUMIFS(Data_AsianPop!$V$2:$V$1630,Data_AsianPop!$C$2:$C$1630,A9,Data_AsianPop!$X$2:$X$1630,1)/1000000 -> 34.2336 | E9: =C9-D9 -> 44.948614 | F9: =IFERROR(D9/C9,0) -> 0.43233952
A10: Stray Kids | B10: JYP | C10: =SUMIFS(Data_AsianPop!$V$2:$V$1630,Data_AsianPop!$C$2:$C$1630,A10)/1000000 -> 216.32565 | D10: =SUMIFS(Data_AsianPop!$V$2:$V$1630,Data_AsianPop!$C$2:$C$1630,A10,Data_AsianPop!$X$2:$X$1630,1)/1000000 -> 210.61829 | E10: =C10-D10 -> 5.7073576 | F10: =IFERROR(D10/C10,0) -> 0.97361682
A11: TWICE | B11: JYP | C11: =SUMIFS(Data_AsianPop!$V$2:$V$1630,Data_AsianPop!$C$2:$C$1630,A11)/1000000 -> 136.00529 | D11: =SUMIFS(Data_AsianPop!$V$2:$V$1630,Data_AsianPop!$C$2:$C$1630,A11,Data_AsianPop!$X$2:$X$1630,1)/1000000 -> 129.31251 | E11: =C11-D11 -> 6.692779 | F11: =IFERROR(D11/C11,0) -> 0.9507903
A12: BLACKPINK | B12: YG | C12: =SUMIFS(Data_AsianPop!$V$2:$V$1630,Data_AsianPop!$C$2:$C$1630,A12)/1000000 -> 85.369106 | D12: =SUMIFS(Data_AsianPop!$V$2:$V$1630,Data_AsianPop!$C$2:$C$1630,A12,Data_AsianPop!$X$2:$X$1630,1)/1000000 -> 21.129327 | E12: =C12-D12 -> 64.239779 | F12: =IFERROR(D12/C12,0) -> 0.24750555
A13: ATEEZ | B13: KQ | C13: =SUMIFS(Data_AsianPop!$V$2:$V$1630,Data_AsianPop!$C$2:$C$1630,A13)/1000000 -> 79.020393 | D13: =SUMIFS(Data_AsianPop!$V$2:$V$1630,Data_AsianPop!$C$2:$C$1630,A13,Data_AsianPop!$X$2:$X$1630,1)/1000000 -> 3.7668679 | E13: =C13-D13 -> 75.253525 | F13: =IFERROR(D13/C13,0) -> 0.047669567

Sheet Data_AsianPop
A1: Event Date | B1: Shows | C1: Headliner | D1: Support | E1: Venue | F1: City | G1: State | H1: Country | I1: Market | J1: Venue Type | K1: Currency | L1: Promoter | M1: Genre | N1: Avg Tickets Sold | O1: Avg Gross (USD) | P1: Avg Event Capacity | Q1: Avg Capacity Sold | R1: Tkt Min (USD) | S1: Tkt Max (USD) | T1: Tkt Avg (USD) | U1: Year | V1: Total Gross (USD) | W1: Total Tickets | X1: LN | Y1: Region
A2: 46172 | B2: 1 | C2: i-dle | E2: Qudos Bank Arena | F2: Sydney | H2: Australia | J2: Arena | K2: Australian | L2: IME | M2: Asian Pop | N2: 4754 | O2: 807138.94 | P2: 5999 | Q2: 0.79 | R2: 78.41 | S2: 387.76 | T2: 169.78 | U2: =IFERROR(YEAR(A2),"") -> 2026 | V2: =IFERROR(O2*B2,0) -> 807138.94 | W2: =IFERROR(N2*B2,0) -> 4754 | X2: =IF(OR(ISNUMBER(SEARCH("live nation",L2)),ISNUMBER(SEARCH("ocesa",L2))),1,0) -> 0 | Y2: Americas + Europe + ANZ
A3: 46165 | B3: 1 | C3: "GOLDEN: A K-Pop Party!" | E3: Music Farm | F3: Charleston | G3: South Carolina | H3: United States | I3: Charleston, SC | J3: Club | K3: US DOLLAR | L3: Live Nation, NS2 | M3: Asian Pop, Dance / Electronic | N3: 615 | O3: 11047 | P3: 700 | Q3: 0.87 | R3: 15 | S3: 60 | T3: 17.96 | U3: =IFERROR(YEAR(A3),"") -> 2026 | V3: =IFERROR(O3*B3,0) -> 11047 | W3: =IFERROR(N3*B3,0) -> 615 | X3: =IF(OR(ISNUMBER(SEARCH("live nation",L3)),ISNUMBER(SEARCH("ocesa",L3))),1,0) -> 1 | Y3: Americas + Europe + ANZ
A4: 46152 | B4: 1 | C4: Kstyle PARTY | E4: K-Arena Yokohama | F4: Yokohama | H4: Japan | J4: Arena | K4: Yen | L4: Sogo Tokyo Corporation | M4: Asian Pop | N4: 18909 | O4: 1642995.8 | P4: 18909 | Q4: 1 | R4: 89.36 | S4: 89.36 | T4: 86.89 | U4: =IFERROR(YEAR(A4),"") -> 2026 | V4: =IFERROR(O4*B4,0) -> 1642995.8 | W4: =IFERROR(N4*B4,0) -> 18909 | X4: =IF(OR(ISNUMBER(SEARCH("live nation",L4)),ISNUMBER(SEARCH("ocesa",L4))),1,0) -> 0 | Y4: Asia / home markets
A5: 46151 | B5: 1 | C5: Kstyle PARTY | D5: EYES, TWS, Taemin, BOYNEXTDOOR | E5: K-Arena Yokohama | F5: Yokohama | H5: Japan | J5: Arena | K5: Yen | L5: Sogo Tokyo Corporation | M5: Asian Pop | N5: 18909 | O5: 1689758 | P5: 18909 | Q5: 1 | R5: 89.36 | S5: 89.36 | T5: 89.36 | U5: =IFERROR(YEAR(A5),"") -> 2026 | V5: =IFERROR(O5*B5,0) -> 1689758 | W5: =IFERROR(N5*B5,0) -> 18909 | X5: =IF(OR(ISNUMBER(SEARCH("live nation",L5)),ISNUMBER(SEARCH("ocesa",L5))),1,0) -> 0 | Y5: Asia / home markets
A6: 46150 | B6: 1 | C6: "Forever K-Pop" | E6: Gila River Resorts and Casinos - The Showroom at Wildhorse Pass | F6: Chandler | G6: Arizona | H6: United States | I6: Phoenix (Prescott) | J6: Auditorium / Theatre | K6: US DOLLAR | L6: (In-House Promotion) | M6: Asian Pop, Tribute Acts | N6: 782 | O6: 35900 | P6: 884 | Q6: 0.88 | R6: 29 | S6: 59 | T6: 45.91 | U6: =IFERROR(YEAR(A6),"") -> 2026 | V6: =IFERROR(O6*B6,0) -> 35900 | W6: =IFERROR(N6*B6,0) -> 782 | X6: =IF(OR(ISNUMBER(SEARCH("live nation",L6)),ISNUMBER(SEARCH("ocesa",L6))),1,0) -> 0 | Y6: Americas + Europe + ANZ
A7: 46150 | B7: 1 | C7: EVERGLOW | E7: L'Olympia | F7: Montreal | G7: Quebec | H7: Canada | J7: Club | K7: Canadian | L7: ADEM Company, Inc | M7: Asian Pop | N7: 511 | O7: 46092.88 | P7: 636 | Q7: 0.8 | R7: 65.66 | S7: 242.43 | T7: 90.2 | U7: =IFERROR(YEAR(A7),"") -> 2026 | V7: =IFERROR(O7*B7,0) -> 46092.88 | W7: =IFERROR(N7*B7,0) -> 511 | X7: =IF(OR(ISNUMBER(SEARCH("live nation",L7)),ISNUMBER(SEARCH("ocesa",L7))),1,0) -> 0 | Y7: Americas + Europe + ANZ
A8: 46149 | B8: 3 | C8: BTS | E8: Estadio GNP Seguros | F8: Mexico City | H8: Mexico | J8: Stadium | K8: Pesos | L8: OCESA | M8: Asian Pop | N8: 48587 | O8: 14492588 | P8: 48625 | Q8: 0.99 | R8: 115.95 | S8: 1014.55 | T8: 298.28 | U8: =IFERROR(YEAR(A8),"") -> 2026 | V8: =IFERROR(O8*B8,0) -> 43477766 | W8: =IFERROR(N8*B8,0) -> 145761 | X8: =IF(OR(ISNUMBER(SEARCH("live nation",L8)),ISNUMBER(SEARCH("ocesa",L8))),1,0) -> 1 | Y8: Americas + Europe + ANZ
A9: 46148 | B9: 1 | C9: SIXFONIA | E9: K-Arena Yokohama | F9: Yokohama | H9: Japan | J9: Arena | K9: Yen | L9: Sogo Tokyo Corporation | M9: Asian Pop | N9: 12534 | O9: 714967.72 | P9: 12534 | Q9: 1 | R9: 57.04 | S9: 57.04 | T9: 57.04 | U9: =IFERROR(YEAR(A9),"") -> 2026 | V9: =IFERROR(O9*B9,0) -> 714967.72 | W9: =IFERROR(N9*B9,0) -> 12534 | X9: =IF(OR(ISNUMBER(SEARCH("live nation",L9)),ISNUMBER(SEARCH("ocesa",L9))),1,0) -> 0 | Y9: Asia / home markets
A10: 46147 | B10: 1 | C10: SIXFONIA | E10: K-Arena Yokohama | F10: Yokohama | H10: Japan | J10: Arena | K10: Yen | L10: Sogo Tokyo Corporation | M10: Asian Pop | N10: 12534 | O10: 717282.53 | P10: 12534 | Q10: 1 | R10: 57.23 | S10: 57.23 | T10: 57.23 | U10: =IFERROR(YEAR(A10),"") -> 2026 | V10: =IFERROR(O10*B10,0) -> 717282.53 | W10: =IFERROR(N10*B10,0) -> 12534 | X10: =IF(OR(ISNUMBER(SEARCH("live nation",L10)),ISNUMBER(SEARCH("ocesa",L10))),1,0) -> 0 | Y10: Asia / home markets
A11: 46145 | B11: 1 | C11: HoYoFair Fan Concert | E11: Beacon Theatre | F11: New York | G11: New York | H11: United States | I11: New York | J11: Auditorium / Theatre | K11: US DOLLAR | L11: Mammoth | M11: Asian Pop | N11: 1899 | O11: 174121.1 | P11: 2744 | Q11: 0.69 | R11: 67 | S11: 147 | T11: 91.69 | U11: =IFERROR(YEAR(A11),"") -> 2026 | V11: =IFERROR(O11*B11,0) -> 174121.1 | W11: =IFERROR(N11*B11,0) -> 1899 | X11: =IF(OR(ISNUMBER(SEARCH("live nation",L11)),ISNUMBER(SEARCH("ocesa",L11))),1,0) -> 0 | Y11: Americas + Europe + ANZ
A12: 46144 | B12: 2 | C12: BTS | E12: Sun Bowl Stadium | F12: El Paso | G12: Texas | H12: United States | I12: El Paso (Las Cruces) | J12: Stadium | K12: US DOLLAR | L12: HYBE Co. Ltd. | M12: Asian Pop | N12: 48861 | O12: 10009328 | P12: 49115 | Q12: 0.99 | R12: 69.5 | S12: 649.5 | T12: 204.85 | U12: =IFERROR(YEAR(A12),"") -> 2026 | V12: =IFERROR(O12*B12,0) -> 20018656 | W12: =IFERROR(N12*B12,0) -> 97722 | X12: =IF(OR(ISNUMBER(SEARCH("live nation",L12)),ISNUMBER(SEARCH("ocesa",L12))),1,0) -> 0 | Y12: Americas + Europe + ANZ
A13: 46143 | B13: 3 | C13: ENHYPEN | E13: KSPO Dome | F13: Seoul | H13: South Korea | J13: Arena | K13: Won | L13: HYBE Co. Ltd. | M13: Asian Pop | N13: 10404 | O13: 1216289.5 | P13: 10511 | Q13: 0.98 | R13: 111.89 | S13: 171.56 | T13: 116.9 | U13: =IFERROR(YEAR(A13),"") -> 2026 | V13: =IFERROR(O13*B13,0) -> 3648868.6 | W13: =IFERROR(N13*B13,0) -> 31212 | X13: =IF(OR(ISNUMBER(SEARCH("live nation",L13)),ISNUMBER(SEARCH("ocesa",L13))),1,0) -> 0 | Y13: Asia / home markets
A14: 46141 | B14: 1 | C14: XLOV | E14: Pepsi Center Mexico | F14: Mexico City | H14: Mexico | J14: Auditorium / Theatre, Convention Center | K14: Pesos | L14: Ninshi | M14: Asian Pop | N14: 2266 | O14: 704439.31 | P14: 6486 | Q14: 0.34 | R14: 56.91 | S14: 344.35 | T14: 310.87 | U14: =IFERROR(YEAR(A14),"") -> 2026 | V14: =IFERROR(O14*B14,0) -> 704439.31 | W14: =IFERROR(N14*B14,0) -> 2266 | X14: =IF(OR(ISNUMBER(SEARCH("live nation",L14)),ISNUMBER(SEARCH("ocesa",L14))),1,0) -> 0 | Y14: Americas + Europe + ANZ
A15: 46140 | B15: 1 | C15: Jackson Wang | D15: Karen Paola | E15: Movistar Arena | F15: Santiago | H15: Chile | J15: Arena | K15: Peso | L15: DG Medios, Live Nation | M15: Asian Pop | N15: 7487 | O15: 533889.76 | P15: 11453 | Q15: 0.65 | R15: 44.69 | S15: 117.32 | T15: 71.31 | U15: =IFERROR(YEAR(A15),"") -> 2026 | V15: =IFERROR(O15*B15,0) -> 533889.76 | W15: =IFERROR(N15*B15,0) -> 7487 | X15: =IF(OR(ISNUMBER(SEARCH("live nation",L15)),ISNUMBER(SEARCH("ocesa",L15))),1,0) -> 1 | Y15: Americas + Europe + ANZ
A16: 46140 | B16: 1 | C16: "Forever K-Pop" | E16: State Theatre | F16: Minneapolis | G16: Minnesota | H16: United States | I16: Minneapolis-St. Paul | J16: Auditorium / Theatre | K16: US DOLLAR | L16: (In-House Promotion), Hennepin Arts | M16: Asian Pop, Tribute Acts | N16: 684 | O16: 27666.6 | P16: 1831 | Q16: 0.37 | R16: 27.5 | S16: 65 | T16: 40.45 | U16: =IFERROR(YEAR(A16),"") -> 2026 | V16: =IFERROR(O16*B16,0) -> 27666.6 | W16: =IFERROR(N16*B16,0) -> 684 | X16: =IF(OR(ISNUMBER(SEARCH("live nation",L16)),ISNUMBER(SEARCH("ocesa",L16))),1,0) -> 0 | Y16: Americas + Europe + ANZ
A17: 46137 | B17: 3 | C17: BTS | E17: Raymond James Stadium | F17: Tampa | G17: Florida | H17: United States | I17: Tampa-St. Petersburg (Sarasota) | J17: Stadium | K17: US DOLLAR | L17: HYBE Co. Ltd. | M17: Asian Pop | N17: 64778 | O17: 13578814 | P17: 64857 | Q17: 0.99 | R17: 69.5 | S17: 649.5 | T17: 209.62 | U17: =IFERROR(YEAR(A17),"") -> 2026 | V17: =IFERROR(O17*B17,0) -> 40736443 | W17: =IFERROR(N17*B17,0) -> 194334 | X17: =IF(OR(ISNUMBER(SEARCH("live nation",L17)),ISNUMBER(SEARCH("ocesa",L17))),1,0) -> 0 | Y17: Americas + Europe + ANZ
A18: 46137 | B18: 1 | C18: "K-Pop Forever" | E18: Unipol Forum | F18: Assago | H18: Italy | J18: Arena | K18: Euro | L18: Vivo Concerti | M18: Asian Pop, Tribute Acts | N18: 9951 | O18: 637578.12 | P18: 10062 | Q18: 0.98 | R18: 40.44 | S18: 107.84 | T18: 64.07 | U18: =IFERROR(YEAR(A18),"") -> 2026 | V18: =IFERROR(O18*B18,0) -> 637578.12 | W18: =IFERROR(N18*B18,0) -> 9951 | X18: =IF(OR(ISNUMBER(SEARCH("live nation",L18)),ISNUMBER(SEARCH("ocesa",L18))),1,0) -> 0 | Y18: Americas + Europe + ANZ
A19: 46130 | B19: 1 | C19: TWICE | E19: Moody Center | F19: Austin | G19: Texas | H19: United States | I19: Austin | J19: Arena | K19: US DOLLAR | L19: Live Nation | M19: Asian Pop | N19: 12997 | O19: 1682909.5 | P19: 12997 | Q19: 1 | R19: 33.5 | S19: 223.5 | T19: 129.48 | U19: =IFERROR(YEAR(A19),"") -> 2026 | V19: =IFERROR(O19*B19,0) -> 1682909.5 | W19: =IFERROR(N19*B19,0) -> 12997 | X19: =IF(OR(ISNUMBER(SEARCH("live nation",L19)),ISNUMBER(SEARCH("ocesa",L19))),1,0) -> 1 | Y19: Americas + Europe + ANZ
A20: 46130 | B20: 1 | C20: "Forever K-Pop" | E20: Embassy Theatre | F20: Fort Wayne | G20: Indiana | H20: United States | I20: Fort Wayne | J20: Auditorium / Theatre | K20: US DOLLAR | L20: (In-House Promotion) | M20: Asian Pop, Tribute Acts | N20: 1307 | O20: 70599 | P20: 1767 | Q20: 0.73 | R20: 37 | S20: 77 | T20: 54.02 | U20: =IFERROR(YEAR(A20),"") -> 2026 | V20: =IFERROR(O20*B20,0) -> 70599 | W20: =IFERROR(N20*B20,0) -> 1307 | X20: =IF(OR(ISNUMBER(SEARCH("live nation",L20)),ISNUMBER(SEARCH("ocesa",L20))),1,0) -> 0 | Y20: Americas + Europe + ANZ
A21: 46130 | B21: 1 | C21: TV Anime 'Detective Conan' 30th Anniversary Special Concert 2026 | D21: Mai Kuraki | E21: K-Arena Yokohama | F21: Yokohama | H21: Japan | J21: Arena | K21: Yen | L21: Kyodo Tokyo | M21: Asian Pop | N21: 10000 | O21: 441236.71 | P21: 10000 | Q21: 1 | R21: 44.12 | S21: 44.12 | T21: 44.12 | U21: =IFERROR(YEAR(A21),"") -> 2026 | V21: =IFERROR(O21*B21,0) -> 441236.71 | W21: =IFERROR(N21*B21,0) -> 10000 | X21: =IF(OR(ISNUMBER(SEARCH("live nation",L21)),ISNUMBER(SEARCH("ocesa",L21))),1,0) -> 0 | Y21: Asia / home markets
A22: 46129 | B22: 2 | C22: BTS | E22: Tokyo Dome | F22: Tokyo | H22: Japan | J22: Stadium | K22: Yen | L22: HYBE Co. Ltd. | M22: Asian Pop | N22: 48089 | O22: 9278360 | P22: 47589 | Q22: 1.01 | R22: 156.85 | S22: 282.33 | T22: 192.94 | U22: =IFERROR(YEAR(A22),"") -> 2026 | V22: =IFERROR(O22*B22,0) -> 18556720 | W22: =IFERROR(N22*B22,0) -> 96178 | X22: =IF(OR(ISNUMBER(SEARCH("live nation",L22)),ISNUMBER(SEARCH("ocesa",L22))),1,0) -> 0 | Y22: Asia / home markets
A23: 46129 | B23: 1 | C23: TWICE | E23: Moody Center | F23: Austin | G23: Texas | H23: United States | I23: Austin | J23: Arena | K23: US DOLLAR | L23: Live Nation | M23: Asian Pop | N23: 13362 | O23: 2146167 | P23: 13362 | Q23: 1 | R23: 33.5 | S23: 223.5 | T23: 160.62 | U23: =IFERROR(YEAR(A23),"") -> 2026 | V23: =IFERROR(O23*B23,0) -> 2146167 | W23: =IFERROR(N23*B23,0) -> 13362 | X23: =IF(OR(ISNUMBER(SEARCH("live nation",L23)),ISNUMBER(SEARCH("ocesa",L23))),1,0) -> 1 | Y23: Americas + Europe + ANZ
A24: 46129 | B24: 1 | C24: TV Anime 'Detective Conan' 30th Anniversary Special Concert 2026 | D24: Mai Kuraki | E24: K-Arena Yokohama | F24: Yokohama | H24: Japan | J24: Arena | K24: Yen | L24: Kyodo Tokyo | M24: Asian Pop | N24: 10000 | O24: 439181.26 | P24: 10000 | Q24: 1 | R24: 43.92 | S24: 43.92 | T24: 43.92 | U24: =IFERROR(YEAR(A24),"") -> 2026 | V24: =IFERROR(O24*B24,0) -> 439181.26 | W24: =IFERROR(N24*B24,0) -> 10000 | X24: =IF(OR(ISNUMBER(SEARCH("live nation",L24)),ISNUMBER(SEARCH("ocesa",L24))),1,0) -> 0 | Y24: Asia / home markets
A25: 46128 | B25: 1 | C25: Big Ocean | E25: Union Stage | F25: Washington | G25: District of Columbia | H25: United States | I25: Washington, D.C. (Hagerstown) | J25: Club | K25: US DOLLAR | L25: Union Stage Presents | M25: Asian Pop | N25: 359 | O25: 34975 | P25: 500 | Q25: 0.71 | R25: 40 | S25: 240 | T25: 97.42 | U25: =IFERROR(YEAR(A25),"") -> 2026 | V25: =IFERROR(O25*B25,0) -> 34975 | W25: =IFERROR(N25*B25,0) -> 359 | X25: =IF(OR(ISNUMBER(SEARCH("live nation",L25)),ISNUMBER(SEARCH("ocesa",L25))),1,0) -> 0 | Y25: Americas + Europe + ANZ
A26: 46124 | B26: 1 | C26: "The Performance" | D26: aoen, ALPHA DRIVE ONE, ATEEZ, NCT WISH, Xikers, The Jet Boy Bangerz, Hearts2Hearts, MYERA | E26: K-Arena Yokohama | F26: Yokohama | H26: Japan | J26: Arena | K26: Yen | L26: PIA Corporation | M26: Asian Pop | N26: 18951 | O26: 1666073.7 | P26: 18951 | Q26: 1 | R26: 87.91 | S26: 87.91 | T26: 87.91 | U26: =IFERROR(YEAR(A26),"") -> 2026 | V26: =IFERROR(O26*B26,0) -> 1666073.7 | W26: =IFERROR(N26*B26,0) -> 18951 | X26: =IF(OR(ISNUMBER(SEARCH("live nation",L26)),ISNUMBER(SEARCH("ocesa",L26))),1,0) -> 0 | Y26: Asia / home markets
A27: 46123 | B27: 1 | C27: "The Performance" | D27: EVNNE, ATEEZ, Verivery, Mazzel, RIIZE, ROIROM | E27: K-Arena Yokohama | F27: Yokohama | H27: Japan | J27: Arena | K27: Yen | L27: PIA Corporation | M27: Asian Pop | N27: 18951 | O27: 1665760.6 | P27: 18951 | Q27: 1 | R27: 87.9 | S27: 87.9 | T27: 87.9 | U27: =IFERROR(YEAR(A27),"") -> 2026 | V27: =IFERROR(O27*B27,0) -> 1665760.6 | W27: =IFERROR(N27*B27,0) -> 18951 | X27: =IF(OR(ISNUMBER(SEARCH("live nation",L27)),ISNUMBER(SEARCH("ocesa",L27))),1,0) -> 0 | Y27: Asia / home markets
A28: 46122 | B28: 1 | C28: Jackson Wang | E28: Barclays Center | F28: Brooklyn | G28: New York | H28: United States | I28: New York | J28: Arena | K28: US DOLLAR | L28: Live Nation | M28: Asian Pop | N28: 10344 | O28: 1481898 | P28: 10344 | Q28: 1 | R28: 22.45 | S28: 193.5 | T28: 143.26 | U28: =IFERROR(YEAR(A28),"") -> 2026 | V28: =IFERROR(O28*B28,0) -> 1481898 | W28: =IFERROR(N28*B28,0) -> 10344 | X28: =IF(OR(ISNUMBER(SEARCH("live nation",L28)),ISNUMBER(SEARCH("ocesa",L28))),1,0) -> 1 | Y28: Americas + Europe + ANZ
A29: 46122 | B29: 1 | C29: "The Performance" | D29: RIIZE, The Rampage | E29: K-Arena Yokohama | F29: Yokohama | H29: Japan | J29: Arena | K29: Yen | L29: PIA Corporation | M29: Asian Pop | N29: 12380 | O29: 1011311.9 | P29: 12380 | Q29: 1 | R29: 81.69 | S29: 81.69 | T29: 81.69 | U29: =IFERROR(YEAR(A29),"") -> 2026 | V29: =IFERROR(O29*B29,0) -> 1011311.9 | W29: =IFERROR(N29*B29,0) -> 12380 | X29: =IF(OR(ISNUMBER(SEARCH("live nation",L29)),ISNUMBER(SEARCH("ocesa",L29))),1,0) -> 0 | Y29: Asia / home markets
A30: 46121 | B30: 1 | C30: Nmixx | E30: YouTube Theater | F30: Inglewood | G30: California | H30: United States | I30: Los Angeles | J30: Auditorium / Theatre | K30: US DOLLAR | L30: Live Nation | M30: Asian Pop | N30: 5731 | O30: 580042.5 | P30: 5737 | Q30: 0.99 | R30: 69.5 | S30: 159.5 | T30: 101.21 | U30: =IFERROR(YEAR(A30),"") -> 2026 | V30: =IFERROR(O30*B30,0) -> 580042.5 | W30: =IFERROR(N30*B30,0) -> 5731 | X30: =IF(OR(ISNUMBER(SEARCH("live nation",L30)),ISNUMBER(SEARCH("ocesa",L30))),1,0) -> 1 | Y30: Americas + Europe + ANZ
A31: 46121 | B31: 3 | C31: BTS | E31: Goyang Stadium | F31: Goyang | H31: South Korea | J31: Stadium | K31: Won | L31: HYBE Co. Ltd. | M31: Asian Pop | N31: 42406 | O31: 5628730.8 | P31: 42528 | Q31: 0.99 | R31: 133.59 | S31: 178.13 | T31: 132.73 | U31: =IFERROR(YEAR(A31),"") -> 2026 | V31: =IFERROR(O31*B31,0) -> 16886193 | W31: =IFERROR(N31*B31,0) -> 127218 | X31: =IF(OR(ISNUMBER(SEARCH("live nation",L31)),ISNUMBER(SEARCH("ocesa",L31))),1,0) -> 0 | Y31: Asia / home markets
A32: 46120 | B32: 1 | C32: Jackson Wang | E32: Allstate Arena | F32: Rosemont | G32: Illinois | H32: United States | I32: Chicago | J32: Arena | K32: US DOLLAR | L32: Live Nation | M32: Asian Pop | N32: 5059 | O32: 633336 | P32: 5059 | Q32: 1 | R32: 59.5 | S32: 199.5 | T32: 125.19 | U32: =IFERROR(YEAR(A32),"") -> 2026 | V32: =IFERROR(O32*B32,0) -> 633336 | W32: =IFERROR(N32*B32,0) -> 5059 | X32: =IF(OR(ISNUMBER(SEARCH("live nation",L32)),ISNUMBER(SEARCH("ocesa",L32))),1,0) -> 1 | Y32: Americas + Europe + ANZ
A33: 46120 | B33: 1 | C33: Naniwa Danshi | E33: K-Arena Yokohama | F33: Yokohama | H33: Japan | J33: Arena | K33: Yen | L33: PIA Corporation | M33: Asian Pop | N33: 18951 | O33: 1315683.6 | P33: 18951 | Q33: 1 | R33: 69.43 | S33: 69.43 | T33: 69.43 | U33: =IFERROR(YEAR(A33),"") -> 2026 | V33: =IFERROR(O33*B33,0) -> 1315683.6 | W33: =IFERROR(N33*B33,0) -> 18951 | X33: =IF(OR(ISNUMBER(SEARCH("live nation",L33)),ISNUMBER(SEARCH("ocesa",L33))),1,0) -> 0 | Y33: Asia / home markets
A34: 46119 | B34: 1 | C34: Naniwa Danshi | E34: K-Arena Yokohama | F34: Yokohama | H34: Japan | J34: Arena | K34: Yen | L34: PIA Corporation | M34: Asian Pop | N34: 18951 | O34: 1304250.7 | P34: 18951 | Q34: 1 | R34: 68.82 | S34: 68.82 | T34: 68.82 | U34: =IFERROR(YEAR(A34),"") -> 2026 | V34: =IFERROR(O34*B34,0) -> 1304250.7 | W34: =IFERROR(N34*B34,0) -> 18951 | X34: =IF(OR(ISNUMBER(SEARCH("live nation",L34)),ISNUMBER(SEARCH("ocesa",L34))),1,0) -> 0 | Y34: Asia / home markets
A35: 46117 | B35: 1 | C35: "Central Music & Entertainment Festival" | D35: Chanmina, HANA, Yuuri, Murasaki Ima | E35: K-Arena Yokohama | F35: Yokohama | H35: Japan | J35: Arena | K35: Yen | L35: Sony Music Solutions | M35: Asian Pop | N35: 18123 | O35: 1362170.7 | P35: 18123 | Q35: 1 | R35: 75.16 | S35: 75.16 | T35: 75.16 | U35: =IFERROR(YEAR(A35),"") -> 2026 | V35: =IFERROR(O35*B35,0) -> 1362170.7 | W35: =IFERROR(N35*B35,0) -> 18123 | X35: =IF(OR(ISNUMBER(SEARCH("live nation",L35)),ISNUMBER(SEARCH("ocesa",L35))),1,0) -> 0 | Y35: Asia / home markets
A36: 46116 | B36: 1 | C36: "Central Music & Entertainment Festival" | D36: Amazarashi, Orange Range, Kessoku Band, Ling tosite sigure, Ling tosite sigure | E36: K-Arena Yokohama | F36: Yokohama | H36: Japan | J36: Arena | K36: Yen | L36: Sony Music Solutions | M36: Asian Pop | N36: 11544 | O36: 867676.33 | P36: 11544 | Q36: 1 | R36: 75.16 | S36: 75.16 | T36: 75.16 | U36: =IFERROR(YEAR(A36),"") -> 2026 | V36: =IFERROR(O36*B36,0) -> 867676.33 | W36: =IFERROR(N36*B36,0) -> 11544 | X36: =IF(OR(ISNUMBER(SEARCH("live nation",L36)),ISNUMBER(SEARCH("ocesa",L36))),1,0) -> 0 | Y36: Asia / home markets
A37: 46116 | B37: 2 | C37: SEVENTEEN | E37: Incheon Asiad Main Stadium | F37: Incheon | H37: South Korea | J37: Stadium | K37: Won | L37: HYBE Co. Ltd. | M37: Asian Pop | N37: 22650 | O37: 2155433.3 | P37: 25905 | Q37: 0.87 | R37: 131.11 | S37: 87.4 | T37: 95.16 | U37: =IFERROR(YEAR(A37),"") -> 2026 | V37: =IFERROR(O37*B37,0) -> 4310866.5 | W37: =IFERROR(N37*B37,0) -> 45300 | X37: =IF(OR(ISNUMBER(SEARCH("live nation",L37)),ISNUMBER(SEARCH("ocesa",L37))),1,0) -> 0 | Y37: Asia / home markets
A38: 46116 | B38: 1 | C38: "K-Pop Forever" | E38: Unipol Arena | F38: Bologna | H38: Italy | J38: Arena | K38: Euro | L38: Vivo Concerti | M38: Asian Pop, Tribute Acts | N38: 5493 | O38: 363359.13 | P38: 9193 | Q38: 0.59 | R38: 39.75 | S38: 108.64 | T38: 66.15 | U38: =IFERROR(YEAR(A38),"") -> 2026 | V38: =IFERROR(O38*B38,0) -> 363359.13 | W38: =IFERROR(N38*B38,0) -> 5493 | X38: =IF(OR(ISNUMBER(SEARCH("live nation",L38)),ISNUMBER(SEARCH("ocesa",L38))),1,0) -> 0 | Y38: Americas + Europe + ANZ
A39: 46115 | B39: 1 | C39: "Forever K-Pop" | E39: Mayo Performing Arts Center | F39: Morristown | G39: New Jersey | H39: United States | I39: New York | J39: Auditorium / Theatre | K39: US DOLLAR | L39: (In-House Promotion) | M39: Asian Pop, Tribute Acts | N39: 749 | O39: 43975.3 | P39: 1222 | Q39: 0.61 | R39: 35 | S39: 75 | T39: 58.71 | U39: =IFERROR(YEAR(A39),"") -> 2026 | V39: =IFERROR(O39*B39,0) -> 43975.3 | W39: =IFERROR(N39*B39,0) -> 749 | X39: =IF(OR(ISNUMBER(SEARCH("live nation",L39)),ISNUMBER(SEARCH("ocesa",L39))),1,0) -> 0 | Y39: Americas + Europe + ANZ
A40: 46115 | B40: 2 | C40: TWICE | E40: TD Garden | F40: Boston | G40: Massachusetts | H40: United States | I40: Boston (Manchester) | J40: Arena | K40: US DOLLAR | L40: Live Nation | M40: Asian Pop | N40: 14655 | O40: 2002366.5 | P40: 15248 | Q40: 0.96 | R40: 52.5 | S40: 222.5 | T40: 136.63 | U40: =IFERROR(YEAR(A40),"") -> 2026 | V40: =IFERROR(O40*B40,0) -> 4004733 | W40: =IFERROR(N40*B40,0) -> 29310 | X40: =IF(OR(ISNUMBER(SEARCH("live nation",L40)),ISNUMBER(SEARCH("ocesa",L40))),1,0) -> 1 | Y40: Americas + Europe + ANZ
...
