Workbook

Sheet Impact
A1: LYV — State AG Verdict: Damages & AOI Impact
A2: Updated per LYV statement, 4/15/26 — Case 1:24-cv-03973 (S.D.N.Y.)
A4: ASSUMPTIONS (blue = input)
A5: VOLUME — per LYV statement
A6: Verdict-covered venues (count) | B6: 257 | C6: LYV statement: 257 venues, ~20% of total tickets
A7: Verdict-covered tickets per year (M) | B7: 17.4 | C7: Back-solved from LYV's <$150M / $1.72 / 5yr; excludes brokers
A8: DAMAGES PARAMETERS
A9: Per-ticket overcharge ($) | B9: 1.72 | C9: Jury verdict 4/15/26
A10: Lookback period (years) | B10: 5 | C10: Per LYV statement: 'past five years'
A11: Treble multiplier | B11: 3 | C11: Clayton Act § 4 / § 4C parens patriae
A12: Prejudgment interest + plaintiff fees | B12: 0.08 | C12: Estimate; varies by judge & state law
A13: Existing accrual (offset) | B13: 280 | C13: LYV statement: $280M accrued in connection with DOJ settlement
A14: AOI
A15: FY26E consolidated AOI ($M) | B15: 2570 | C15: Consensus ~$2.5–2.6B
A16: DOJ behavioral remedy AOI drag ($M) | B16: 55 | C16: Bernstein est., midpoint of $50–60M
A17: Incremental state remedy AOI drag ($M) | B17: 0 | C17: LYV: 'outcome not materially different than DOJ settlement'
A18: Venue Nation incremental AOI at maturity ($M) | B18: 600 | C18: Per Investor Day; Bernstein VN model
A20: DAMAGES BUILD (per LYV statement)
A21: Verdict-covered tickets/year (M) | B21: =B7 -> 17.4
A22: × Per-ticket overcharge | B22: =B9 -> 1.72
A23: Annual overcharge ($M) | B23: =B21*B22 -> 29.928
A24: × Lookback years | B24: =B10 -> 5
A25: Single damages ($M) | B25: =B23*B24 -> 149.64
A26: × Treble multiplier | B26: =B11 -> 3
A27: Trebled damages ($M) | B27: =B25*B26 -> 448.92
A28: × (1 + interest & fees) | B28: =1+B12 -> 1.08
A29: Gross all-in damages ($M) | B29: =B27*B28 -> 484.8336
A30: Less: existing accrual ($M) | B30: =-B13 -> -280
A31: NET INCREMENTAL CHARGE ($M) | B31: =B29+B30 -> 204.8336 | C31: ← incremental cash exposure beyond existing accrual
A32: NET INCREMENTAL CHARGE ($B) | B32: =B31/1000 -> 0.2048336
A34: AOI IMPACT
A35: DOJ behavioral remedy AOI drag ($M) | B35: =B16 -> 55
A36: Incremental state remedy AOI drag ($M) | B36: =B17 -> 0
A37: Combined annual AOI drag ($M) | B37: =B35+B36 -> 55
A38: As % of FY26E AOI | B38: =B37/B15 -> 0.021400778
A39: Venue Nation incremental AOI at maturity ($M) | B39: =B18 -> 600
A40: VN coverage of combined AOI drag | B40: =B39/B37 -> 10.909091
A42: OPTIONALITY — pending motions could reduce/vacate liability
A43: • Rule 50 motion (judgment as a matter of law): Court previously called LYV's arguments 'serious issues'
A44: • Motion to strike damages testimony: Court flagged 'significant concerns' with damages expert's analysis
...

Sheet Sensitivity
A1: Damages Sensitivity Tables ($M)
A2: All tables hold non-flexed inputs at base case (Impact tab). LYV base = ~17M tickets/year.
A4: Table 1: GROSS all-in damages — Tickets/yr × Lookback Years
A5: $/ticket = Impact!B9; treble = Impact!B11; +interest/fees = Impact!B12
A7: Tickets (M) ↓ / Years → | B7: 3 | C7: 4 | D7: 5 | E7: 6 | F7: 7
A8: 10 | B8: =$A8*Impact!$B$9*3*Impact!$B$11*(1+Impact!$B$12) -> 167.184 | C8: =$A8*Impact!$B$9*4*Impact!$B$11*(1+Impact!$B$12) -> 222.912 | D8: =$A8*Impact!$B$9*5*Impact!$B$11*(1+Impact!$B$12) -> 278.64 | E8: =$A8*Impact!$B$9*6*Impact!$B$11*(1+Impact!$B$12) -> 334.368 | F8: =$A8*Impact!$B$9*7*Impact!$B$11*(1+Impact!$B$12) -> 390.096
A9: 15 | B9: =$A9*Impact!$B$9*3*Impact!$B$11*(1+Impact!$B$12) -> 250.776 | C9: =$A9*Impact!$B$9*4*Impact!$B$11*(1+Impact!$B$12) -> 334.368 | D9: =$A9*Impact!$B$9*5*Impact!$B$11*(1+Impact!$B$12) -> 417.96 | E9: =$A9*Impact!$B$9*6*Impact!$B$11*(1+Impact!$B$12) -> 501.552 | F9: =$A9*Impact!$B$9*7*Impact!$B$11*(1+Impact!$B$12) -> 585.144
A10: 17.4 | B10: =$A10*Impact!$B$9*3*Impact!$B$11*(1+Impact!$B$12) -> 290.90016 | C10: =$A10*Impact!$B$9*4*Impact!$B$11*(1+Impact!$B$12) -> 387.86688 | D10: =$A10*Impact!$B$9*5*Impact!$B$11*(1+Impact!$B$12) -> 484.8336 | E10: =$A10*Impact!$B$9*6*Impact!$B$11*(1+Impact!$B$12) -> 581.80032 | F10: =$A10*Impact!$B$9*7*Impact!$B$11*(1+Impact!$B$12) -> 678.76704
A11: 20 | B11: =$A11*Impact!$B$9*3*Impact!$B$11*(1+Impact!$B$12) -> 334.368 | C11: =$A11*Impact!$B$9*4*Impact!$B$11*(1+Impact!$B$12) -> 445.824 | D11: =$A11*Impact!$B$9*5*Impact!$B$11*(1+Impact!$B$12) -> 557.28 | E11: =$A11*Impact!$B$9*6*Impact!$B$11*(1+Impact!$B$12) -> 668.736 | F11: =$A11*Impact!$B$9*7*Impact!$B$11*(1+Impact!$B$12) -> 780.192
A12: 25 | B12: =$A12*Impact!$B$9*3*Impact!$B$11*(1+Impact!$B$12) -> 417.96 | C12: =$A12*Impact!$B$9*4*Impact!$B$11*(1+Impact!$B$12) -> 557.28 | D12: =$A12*Impact!$B$9*5*Impact!$B$11*(1+Impact!$B$12) -> 696.6 | E12: =$A12*Impact!$B$9*6*Impact!$B$11*(1+Impact!$B$12) -> 835.92 | F12: =$A12*Impact!$B$9*7*Impact!$B$11*(1+Impact!$B$12) -> 975.24
A13: 35 | B13: =$A13*Impact!$B$9*3*Impact!$B$11*(1+Impact!$B$12) -> 585.144 | C13: =$A13*Impact!$B$9*4*Impact!$B$11*(1+Impact!$B$12) -> 780.192 | D13: =$A13*Impact!$B$9*5*Impact!$B$11*(1+Impact!$B$12) -> 975.24 | E13: =$A13*Impact!$B$9*6*Impact!$B$11*(1+Impact!$B$12) -> 1170.288 | F13: =$A13*Impact!$B$9*7*Impact!$B$11*(1+Impact!$B$12) -> 1365.336
A16: Table 2: GROSS all-in damages — Tickets/yr × Treble Multiplier
A17: $/ticket = Impact!B9; lookback = Impact!B10; +interest/fees = Impact!B12
A19: Tickets (M) ↓ / Multiplier → | B19: 1 | C19: 1.5 | D19: 2 | E19: 2.5 | F19: 3
A20: 10 | B20: =$A20*Impact!$B$9*Impact!$B$10*1*(1+Impact!$B$12) -> 92.88 | C20: =$A20*Impact!$B$9*Impact!$B$10*1.5*(1+Impact!$B$12) -> 139.32 | D20: =$A20*Impact!$B$9*Impact!$B$10*2*(1+Impact!$B$12) -> 185.76 | E20: =$A20*Impact!$B$9*Impact!$B$10*2.5*(1+Impact!$B$12) -> 232.2 | F20: =$A20*Impact!$B$9*Impact!$B$10*3*(1+Impact!$B$12) -> 278.64
A21: 15 | B21: =$A21*Impact!$B$9*Impact!$B$10*1*(1+Impact!$B$12) -> 139.32 | C21: =$A21*Impact!$B$9*Impact!$B$10*1.5*(1+Impact!$B$12) -> 208.98 | D21: =$A21*Impact!$B$9*Impact!$B$10*2*(1+Impact!$B$12) -> 278.64 | E21: =$A21*Impact!$B$9*Impact!$B$10*2.5*(1+Impact!$B$12) -> 348.3 | F21: =$A21*Impact!$B$9*Impact!$B$10*3*(1+Impact!$B$12) -> 417.96
A22: 17.4 | B22: =$A22*Impact!$B$9*Impact!$B$10*1*(1+Impact!$B$12) -> 161.6112 | C22: =$A22*Impact!$B$9*Impact!$B$10*1.5*(1+Impact!$B$12) -> 242.4168 | D22: =$A22*Impact!$B$9*Impact!$B$10*2*(1+Impact!$B$12) -> 323.2224 | E22: =$A22*Impact!$B$9*Impact!$B$10*2.5*(1+Impact!$B$12) -> 404.028 | F22: =$A22*Impact!$B$9*Impact!$B$10*3*(1+Impact!$B$12) -> 484.8336
A23: 20 | B23: =$A23*Impact!$B$9*Impact!$B$10*1*(1+Impact!$B$12) -> 185.76 | C23: =$A23*Impact!$B$9*Impact!$B$10*1.5*(1+Impact!$B$12) -> 278.64 | D23: =$A23*Impact!$B$9*Impact!$B$10*2*(1+Impact!$B$12) -> 371.52 | E23: =$A23*Impact!$B$9*Impact!$B$10*2.5*(1+Impact!$B$12) -> 464.4 | F23: =$A23*Impact!$B$9*Impact!$B$10*3*(1+Impact!$B$12) -> 557.28
A24: 25 | B24: =$A24*Impact!$B$9*Impact!$B$10*1*(1+Impact!$B$12) -> 232.2 | C24: =$A24*Impact!$B$9*Impact!$B$10*1.5*(1+Impact!$B$12) -> 348.3 | D24: =$A24*Impact!$B$9*Impact!$B$10*2*(1+Impact!$B$12) -> 464.4 | E24: =$A24*Impact!$B$9*Impact!$B$10*2.5*(1+Impact!$B$12) -> 580.5 | F24: =$A24*Impact!$B$9*Impact!$B$10*3*(1+Impact!$B$12) -> 696.6
A25: 35 | B25: =$A25*Impact!$B$9*Impact!$B$10*1*(1+Impact!$B$12) -> 325.08 | C25: =$A25*Impact!$B$9*Impact!$B$10*1.5*(1+Impact!$B$12) -> 487.62 | D25: =$A25*Impact!$B$9*Impact!$B$10*2*(1+Impact!$B$12) -> 650.16 | E25: =$A25*Impact!$B$9*Impact!$B$10*2.5*(1+Impact!$B$12) -> 812.7 | F25: =$A25*Impact!$B$9*Impact!$B$10*3*(1+Impact!$B$12) -> 975.24
A28: Table 3: NET INCREMENTAL CHARGE — Gross damages less $280M existing accrual
A29: Gross = Tickets × $/ticket × Years × Treble × (1+fees); Net = Gross − Impact!B13
A31: Tickets (M) ↓ / Years → | B31: 3 | C31: 4 | D31: 5 | E31: 6 | F31: 7
A32: 10 | B32: =MAX(0,$A32*Impact!$B$9*3*Impact!$B$11*(1+Impact!$B$12)-Impact!$B$13) -> 0 | C32: =MAX(0,$A32*Impact!$B$9*4*Impact!$B$11*(1+Impact!$B$12)-Impact!$B$13) -> 0 | D32: =MAX(0,$A32*Impact!$B$9*5*Impact!$B$11*(1+Impact!$B$12)-Impact!$B$13) -> 0 | E32: =MAX(0,$A32*Impact!$B$9*6*Impact!$B$11*(1+Impact!$B$12)-Impact!$B$13) -> 54.368 | F32: =MAX(0,$A32*Impact!$B$9*7*Impact!$B$11*(1+Impact!$B$12)-Impact!$B$13) -> 110.096
A33: 15 | B33: =MAX(0,$A33*Impact!$B$9*3*Impact!$B$11*(1+Impact!$B$12)-Impact!$B$13) -> 0 | C33: =MAX(0,$A33*Impact!$B$9*4*Impact!$B$11*(1+Impact!$B$12)-Impact!$B$13) -> 54.368 | D33: =MAX(0,$A33*Impact!$B$9*5*Impact!$B$11*(1+Impact!$B$12)-Impact!$B$13) -> 137.96 | E33: =MAX(0,$A33*Impact!$B$9*6*Impact!$B$11*(1+Impact!$B$12)-Impact!$B$13) -> 221.552 | F33: =MAX(0,$A33*Impact!$B$9*7*Impact!$B$11*(1+Impact!$B$12)-Impact!$B$13) -> 305.144
A34: 17.4 | B34: =MAX(0,$A34*Impact!$B$9*3*Impact!$B$11*(1+Impact!$B$12)-Impact!$B$13) -> 10.90016 | C34: =MAX(0,$A34*Impact!$B$9*4*Impact!$B$11*(1+Impact!$B$12)-Impact!$B$13) -> 107.86688 | D34: =MAX(0,$A34*Impact!$B$9*5*Impact!$B$11*(1+Impact!$B$12)-Impact!$B$13) -> 204.8336 | E34: =MAX(0,$A34*Impact!$B$9*6*Impact!$B$11*(1+Impact!$B$12)-Impact!$B$13) -> 301.80032 | F34: =MAX(0,$A34*Impact!$B$9*7*Impact!$B$11*(1+Impact!$B$12)-Impact!$B$13) -> 398.76704
A35: 20 | B35: =MAX(0,$A35*Impact!$B$9*3*Impact!$B$11*(1+Impact!$B$12)-Impact!$B$13) -> 54.368 | C35: =MAX(0,$A35*Impact!$B$9*4*Impact!$B$11*(1+Impact!$B$12)-Impact!$B$13) -> 165.824 | D35: =MAX(0,$A35*Impact!$B$9*5*Impact!$B$11*(1+Impact!$B$12)-Impact!$B$13) -> 277.28 | E35: =MAX(0,$A35*Impact!$B$9*6*Impact!$B$11*(1+Impact!$B$12)-Impact!$B$13) -> 388.736 | F35: =MAX(0,$A35*Impact!$B$9*7*Impact!$B$11*(1+Impact!$B$12)-Impact!$B$13) -> 500.192
A36: 25 | B36: =MAX(0,$A36*Impact!$B$9*3*Impact!$B$11*(1+Impact!$B$12)-Impact!$B$13) -> 137.96 | C36: =MAX(0,$A36*Impact!$B$9*4*Impact!$B$11*(1+Impact!$B$12)-Impact!$B$13) -> 277.28 | D36: =MAX(0,$A36*Impact!$B$9*5*Impact!$B$11*(1+Impact!$B$12)-Impact!$B$13) -> 416.6 | E36: =MAX(0,$A36*Impact!$B$9*6*Impact!$B$11*(1+Impact!$B$12)-Impact!$B$13) -> 555.92 | F36: =MAX(0,$A36*Impact!$B$9*7*Impact!$B$11*(1+Impact!$B$12)-Impact!$B$13) -> 695.24
A37: 35 | B37: =MAX(0,$A37*Impact!$B$9*3*Impact!$B$11*(1+Impact!$B$12)-Impact!$B$13) -> 305.144 | C37: =MAX(0,$A37*Impact!$B$9*4*Impact!$B$11*(1+Impact!$B$12)-Impact!$B$13) -> 500.192 | D37: =MAX(0,$A37*Impact!$B$9*5*Impact!$B$11*(1+Impact!$B$12)-Impact!$B$13) -> 695.24 | E37: =MAX(0,$A37*Impact!$B$9*6*Impact!$B$11*(1+Impact!$B$12)-Impact!$B$13) -> 890.288 | F37: =MAX(0,$A37*Impact!$B$9*7*Impact!$B$11*(1+Impact!$B$12)-Impact!$B$13) -> 1085.336
A40: Bear case stress test: even at 35M tickets and 7-year lookback (vs LYV's 17M / 5yr), trebled all-in is ~$1.4B.
A41: Net of $280M accrual: ~$1.1B. Implies stock has overshot if today's $2.5B selloff is purely about damages.
