Workbook

Sheet TAM Summary
B2: SPOTIFY PREMIUM — GLOBAL SUBSCRIBER TAM
B3: Bottoms-up across 130 priced markets. Proxy = online adults. Ceiling = continuous GDP-per-capita curve. Spotify-addressable = industry × Spotify share.
B5: Headline — Spotify-addressable (subscribers, M) | E5: By Spotify region — base case
B6: Current Premium subscribers (FY2025) | C6: ='Country Build'!M135 -> 290 | E6: Region | F6: Proxy (M) | G6: Current | H6: Cur pen | I6: Max base | J6: Incr. | K6: Max pen | L6: Rev $M
B7: Realistic max — Low (bearish ceiling) | C7: ='Country Build'!R135 -> 333.32627 | E7: Europe | F7: =SUMIF('Country Build'!$C$5:$C$134,E7,'Country Build'!$I$5:$I$134) -> 443.03964 | G7: =SUMIF('Country Build'!$C$5:$C$134,E7,'Country Build'!$M$5:$M$134) -> 108 | H7: =G7/F7 -> 0.24377051 | I7: =SUMIF('Country Build'!$C$5:$C$134,E7,'Country Build'!$O$5:$O$134) -> 118.07695 | J7: =I7-G7 -> 10.076946 | K7: =I7/F7 -> 0.26651553 | L7: =SUMIF('Country Build'!$C$5:$C$134,E7,'Country Build'!$W$5:$W$134) -> 9490.3861
B8: Realistic max — Base | C8: ='Country Build'!O135 -> 395.62449 | E8: North America | F8: =SUMIF('Country Build'!$C$5:$C$134,E8,'Country Build'!$I$5:$I$134) -> 292.9152 | G8: =SUMIF('Country Build'!$C$5:$C$134,E8,'Country Build'!$M$5:$M$134) -> 74 | H8: =G8/F8 -> 0.25263284 | I8: =SUMIF('Country Build'!$C$5:$C$134,E8,'Country Build'!$O$5:$O$134) -> 75.437175 | J8: =I8-G8 -> 1.4371748 | K8: =I8/F8 -> 0.2575393 | L8: =SUMIF('Country Build'!$C$5:$C$134,E8,'Country Build'!$W$5:$W$134) -> 5711.8207
B9: Realistic max — High (bullish ceiling) | C9: ='Country Build'!T135 -> 457.02559 | E9: Latin America | F9: =SUMIF('Country Build'!$C$5:$C$134,E9,'Country Build'!$I$5:$I$134) -> 383.48452 | G9: =SUMIF('Country Build'!$C$5:$C$134,E9,'Country Build'!$M$5:$M$134) -> 67 | H9: =G9/F9 -> 0.1747137 | I9: =SUMIF('Country Build'!$C$5:$C$134,E9,'Country Build'!$O$5:$O$134) -> 72.709615 | J9: =I9-G9 -> 5.7096151 | K9: =I9/F9 -> 0.18960248 | L9: =SUMIF('Country Build'!$C$5:$C$134,E9,'Country Build'!$W$5:$W$134) -> 2451.5851
B10: Incremental TAM — Base (max − current) | C10: =C8-C6 -> 105.62449 | E10: Rest of World | F10: =SUMIF('Country Build'!$C$5:$C$134,E10,'Country Build'!$I$5:$I$134) -> 1473.4695 | G10: =SUMIF('Country Build'!$C$5:$C$134,E10,'Country Build'!$M$5:$M$134) -> 41 | H10: =G10/F10 -> 0.027825483 | I10: =SUMIF('Country Build'!$C$5:$C$134,E10,'Country Build'!$O$5:$O$134) -> 129.40075 | J10: =I10-G10 -> 88.40075 | K10: =I10/F10 -> 0.087820448 | L10: =SUMIF('Country Build'!$C$5:$C$134,E10,'Country Build'!$W$5:$W$134) -> 3245.5943
B11: Upside vs current — Base | C11: =C8/C6-1 -> 0.36422237 | E11: Total | F11: =SUM(F7:F10) -> 2592.9089 | G11: =SUM(G7:G10) -> 290 | H11: =G11/F11 -> 0.1118435 | I11: =SUM(I7:I10) -> 395.62449 | J11: =SUM(J7:J10) -> 105.62449 | K11: =I11/F11 -> 0.1525794 | L11: =SUM(L7:L10) -> 20899.386
B13: Penetration of online adults | E13: By income tier — base case
B14: Current | C14: =C6/'Country Build'!I135 -> 0.1118435 | E14: Tier | F14: Current | G14: Max base | H14: Incr. | I14: Rev $M
B15: At base ceiling | C15: =C8/'Country Build'!I135 -> 0.1525794 | E15: 1 >$35k | F15: =SUMIF('Country Build'!$X$5:$X$134,1,'Country Build'!$M$5:$M$134) -> 152.31642 | G15: =SUMIF('Country Build'!$X$5:$X$134,1,'Country Build'!$O$5:$O$134) -> 167.46281 | H15: =G15-F15 -> 15.146383 | I15: =SUMIF('Country Build'!$X$5:$X$134,1,'Country Build'!$W$5:$W$134) -> 13795.144
B16: Online adults in scope (M, ex-China/Russia) | C16: ='Country Build'!I135 -> 2592.9089 | E16: 2 $12–35k | F16: =SUMIF('Country Build'!$X$5:$X$134,2,'Country Build'!$M$5:$M$134) -> 74.531295 | G16: =SUMIF('Country Build'!$X$5:$X$134,2,'Country Build'!$O$5:$O$134) -> 98.055121 | H16: =G16-F16 -> 23.523827 | I16: =SUMIF('Country Build'!$X$5:$X$134,2,'Country Build'!$W$5:$W$134) -> 4356.2655
E17: 3 $4–12k | F17: =SUMIF('Country Build'!$X$5:$X$134,3,'Country Build'!$M$5:$M$134) -> 46.313448 | G17: =SUMIF('Country Build'!$X$5:$X$134,3,'Country Build'!$O$5:$O$134) -> 80.769513 | H17: =G17-F17 -> 34.456065 | I17: =SUMIF('Country Build'!$X$5:$X$134,3,'Country Build'!$W$5:$W$134) -> 2096.7799
B18: Revenue TAM (base max, current pricing) | E18: 4 <$4k | F18: =SUMIF('Country Build'!$X$5:$X$134,4,'Country Build'!$M$5:$M$134) -> 16.838833 | G18: =SUMIF('Country Build'!$X$5:$X$134,4,'Country Build'!$O$5:$O$134) -> 49.337045 | H18: =G18-F18 -> 32.498212 | I18: =SUMIF('Country Build'!$X$5:$X$134,4,'Country Build'!$W$5:$W$134) -> 651.19689
B19: Spotify-addressable revenue TAM ($M/yr) | C19: ='Country Build'!W135 -> 20899.386
B20: Implied current ARPU ($/mo, check) | C20: =SUMPRODUCT('Country Build'!M5:M134,'Country Build'!V5:V134)/C6 -> 5.0606766
B23: Sensitivity — Base-max subscribers (M): x0 shift (rows) × Spotify-share multiplier (cols)
B24: Lower x0 / higher multiplier = more bullish.
B25: x0 shift ↓ / mult → | C25: 0.8 | D25: 0.9 | E25: 1 | F25: 1.1 | G25: 1.2
B26: 0.5 | C26: =SUMPRODUCT('Country Build'!$I$5:$I$134,(Assumptions!$C$5/(1+EXP(-Assumptions!$C$6*(LN('Country Build'!$D$5:$D$134)-(Assumptions!$C$7+$B26))))),'Country Build'!$K$5:$K$134*C$25) -> 266.66102 | D26: =SUMPRODUCT('Country Build'!$I$5:$I$134,(Assumptions!$C$5/(1+EXP(-Assumptions!$C$6*(LN('Country Build'!$D$5:$D$134)-(Assumptions!$C$7+$B26))))),'Country Build'!$K$5:$K$134*D$25) -> 299.99365 | E26: =SUMPRODUCT('Country Build'!$I$5:$I$134,(Assumptions!$C$5/(1+EXP(-Assumptions!$C$6*(LN('Country Build'!$D$5:$D$134)-(Assumptions!$C$7+$B26))))),'Country Build'!$K$5:$K$134*E$25) -> 333.32627 | F26: =SUMPRODUCT('Country Build'!$I$5:$I$134,(Assumptions!$C$5/(1+EXP(-Assumptions!$C$6*(LN('Country Build'!$D$5:$D$134)-(Assumptions!$C$7+$B26))))),'Country Build'!$K$5:$K$134*F$25) -> 366.6589 | G26: =SUMPRODUCT('Country Build'!$I$5:$I$134,(Assumptions!$C$5/(1+EXP(-Assumptions!$C$6*(LN('Country Build'!$D$5:$D$134)-(Assumptions!$C$7+$B26))))),'Country Build'!$K$5:$K$134*G$25) -> 399.99153
B27: 0.25 | C27: =SUMPRODUCT('Country Build'!$I$5:$I$134,(Assumptions!$C$5/(1+EXP(-Assumptions!$C$6*(LN('Country Build'!$D$5:$D$134)-(Assumptions!$C$7+$B27))))),'Country Build'!$K$5:$K$134*C$25) -> 291.54071 | D27: =SUMPRODUCT('Country Build'!$I$5:$I$134,(Assumptions!$C$5/(1+EXP(-Assumptions!$C$6*(LN('Country Build'!$D$5:$D$134)-(Assumptions!$C$7+$B27))))),'Country Build'!$K$5:$K$134*D$25) -> 327.9833 | E27: =SUMPRODUCT('Country Build'!$I$5:$I$134,(Assumptions!$C$5/(1+EXP(-Assumptions!$C$6*(LN('Country Build'!$D$5:$D$134)-(Assumptions!$C$7+$B27))))),'Country Build'!$K$5:$K$134*E$25) -> 364.42589 | F27: =SUMPRODUCT('Country Build'!$I$5:$I$134,(Assumptions!$C$5/(1+EXP(-Assumptions!$C$6*(LN('Country Build'!$D$5:$D$134)-(Assumptions!$C$7+$B27))))),'Country Build'!$K$5:$K$134*F$25) -> 400.86848 | G27: =SUMPRODUCT('Country Build'!$I$5:$I$134,(Assumptions!$C$5/(1+EXP(-Assumptions!$C$6*(LN('Country Build'!$D$5:$D$134)-(Assumptions!$C$7+$B27))))),'Country Build'!$K$5:$K$134*G$25) -> 437.31106
B28: 0 | C28: =SUMPRODUCT('Country Build'!$I$5:$I$134,(Assumptions!$C$5/(1+EXP(-Assumptions!$C$6*(LN('Country Build'!$D$5:$D$134)-(Assumptions!$C$7+$B28))))),'Country Build'!$K$5:$K$134*C$25) -> 316.49959 | D28: =SUMPRODUCT('Country Build'!$I$5:$I$134,(Assumptions!$C$5/(1+EXP(-Assumptions!$C$6*(LN('Country Build'!$D$5:$D$134)-(Assumptions!$C$7+$B28))))),'Country Build'!$K$5:$K$134*D$25) -> 356.06204 | E28: =SUMPRODUCT('Country Build'!$I$5:$I$134,(Assumptions!$C$5/(1+EXP(-Assumptions!$C$6*(LN('Country Build'!$D$5:$D$134)-(Assumptions!$C$7+$B28))))),'Country Build'!$K$5:$K$134*E$25) -> 395.62449 | F28: =SUMPRODUCT('Country Build'!$I$5:$I$134,(Assumptions!$C$5/(1+EXP(-Assumptions!$C$6*(LN('Country Build'!$D$5:$D$134)-(Assumptions!$C$7+$B28))))),'Country Build'!$K$5:$K$134*F$25) -> 435.18693 | G28: =SUMPRODUCT('Country Build'!$I$5:$I$134,(Assumptions!$C$5/(1+EXP(-Assumptions!$C$6*(LN('Country Build'!$D$5:$D$134)-(Assumptions!$C$7+$B28))))),'Country Build'!$K$5:$K$134*G$25) -> 474.74938
B29: -0.25 | C29: =SUMPRODUCT('Country Build'!$I$5:$I$134,(Assumptions!$C$5/(1+EXP(-Assumptions!$C$6*(LN('Country Build'!$D$5:$D$134)-(Assumptions!$C$7+$B29))))),'Country Build'!$K$5:$K$134*C$25) -> 341.28348 | D29: =SUMPRODUCT('Country Build'!$I$5:$I$134,(Assumptions!$C$5/(1+EXP(-Assumptions!$C$6*(LN('Country Build'!$D$5:$D$134)-(Assumptions!$C$7+$B29))))),'Country Build'!$K$5:$K$134*D$25) -> 383.94392 | E29: =SUMPRODUCT('Country Build'!$I$5:$I$134,(Assumptions!$C$5/(1+EXP(-Assumptions!$C$6*(LN('Country Build'!$D$5:$D$134)-(Assumptions!$C$7+$B29))))),'Country Build'!$K$5:$K$134*E$25) -> 426.60435 | F29: =SUMPRODUCT('Country Build'!$I$5:$I$134,(Assumptions!$C$5/(1+EXP(-Assumptions!$C$6*(LN('Country Build'!$D$5:$D$134)-(Assumptions!$C$7+$B29))))),'Country Build'!$K$5:$K$134*F$25) -> 469.26479 | G29: =SUMPRODUCT('Country Build'!$I$5:$I$134,(Assumptions!$C$5/(1+EXP(-Assumptions!$C$6*(LN('Country Build'!$D$5:$D$134)-(Assumptions!$C$7+$B29))))),'Country Build'!$K$5:$K$134*G$25) -> 511.92522
B30: -0.5 | C30: =SUMPRODUCT('Country Build'!$I$5:$I$134,(Assumptions!$C$5/(1+EXP(-Assumptions!$C$6*(LN('Country Build'!$D$5:$D$134)-(Assumptions!$C$7+$B30))))),'Country Build'!$K$5:$K$134*C$25) -> 365.62047 | D30: =SUMPRODUCT('Country Build'!$I$5:$I$134,(Assumptions!$C$5/(1+EXP(-Assumptions!$C$6*(LN('Country Build'!$D$5:$D$134)-(Assumptions!$C$7+$B30))))),'Country Build'!$K$5:$K$134*D$25) -> 411.32303 | E30: =SUMPRODUCT('Country Build'!$I$5:$I$134,(Assumptions!$C$5/(1+EXP(-Assumptions!$C$6*(LN('Country Build'!$D$5:$D$134)-(Assumptions!$C$7+$B30))))),'Country Build'!$K$5:$K$134*E$25) -> 457.02559 | F30: =SUMPRODUCT('Country Build'!$I$5:$I$134,(Assumptions!$C$5/(1+EXP(-Assumptions!$C$6*(LN('Country Build'!$D$5:$D$134)-(Assumptions!$C$7+$B30))))),'Country Build'!$K$5:$K$134*F$25) -> 502.72815 | G30: =SUMPRODUCT('Country Build'!$I$5:$I$134,(Assumptions!$C$5/(1+EXP(-Assumptions!$C$6*(LN('Country Build'!$D$5:$D$134)-(Assumptions!$C$7+$B30))))),'Country Build'!$K$5:$K$134*G$25) -> 548.43071
B33: Read me
B34: • Proxy = population × 15+ share × internet% (all editable on Country Build).
B35: • Ceiling = continuous logistic curve in ln(GDP/cap): max share of online adults paying for music.
B36: • Spotify share = Spotify's cut of that ceiling, net of Apple/YouTube/local players (col K, per country).
B37: • Current subs allocated from Bernstein regional control totals; ties out exactly.
B38: • China & Russia excluded. Subs = paid ACCOUNTS (×~1.3–1.5 for individuals via Family/Duo).
B39: • Prices from your Feb-2026 file; FX ECB 16-Jun-2026. All on the Pricing tab, fully editable.

Sheet Country Build
A1: Bottoms-up Premium subscriber TAM — every priced Spotify market (subscribers in millions)
A2: Proxy = online adults (pop × 15+ share × internet%). Ceiling = continuous GDP curve. Blue=input, Green=link, Black=formula.
A4: Country | B4: ISO | C4: Segment | D4: GDP/cap $ | E4: Pop (M) | F4: 15+ % | G4: Int % | H4: Adults 15+ (M) | I4: Online-adult proxy (M) | J4: Ceiling % base | K4: Spotify share % | L4: Wt | M4: Current subs (M) | N4: Current pen. | O4: Max subs base (M) | P4: Incremental (M) | Q4: Ceiling % low | R4: Max low (M) | S4: Ceiling % high | T4: Max high (M) | U4: Blended ARPU $ | V4: Realized ARPU $ | W4: Rev TAM base $M | X4: Tier
A5: Germany | B5: DEU | C5: Europe | D5: 53356 | E5: 83.52 | F5: 0.83 | G5: 0.96 | H5: =E5*F5 -> 69.3216 | I5: =H5*G5 -> 66.548736 | J5: =Assumptions!$C$5/(1+EXP(-Assumptions!$C$6*(LN(D5)-Assumptions!$C$7))) -> 0.53133326 | K5: 0.55 | L5: =I5*J5 -> 35.359557 | M5: =VLOOKUP(C5,Assumptions!$B$20:$C$23,2,FALSE())*L5/SUMIF($C$5:$C$134,C5,$L$5:$L$134) -> 17.577897 | N5: =IF(I5=0,0,M5/I5) -> 0.2641357 | O5: =I5*J5*K5 -> 19.447756 | P5: =O5-M5 -> 1.8698595 | Q5: =Assumptions!$C$5/(1+EXP(-Assumptions!$C$6*(LN(D5)-(Assumptions!$C$7+Assumptions!$C$8)))) -> 0.48882835 | R5: =I5*Q5*K5 -> 17.892 | S5: =Assumptions!$C$5/(1+EXP(-Assumptions!$C$6*(LN(D5)-(Assumptions!$C$7-Assumptions!$C$8)))) -> 0.56170733 | T5: =I5*S5*K5 -> 20.559502 | U5: =VLOOKUP(A5,Pricing!$A$5:$L$134,12,FALSE()) -> 16.301449 | V5: =U5*Assumptions!$C$17 -> 7.4986667 | W5: =O5*V5*12 -> 1749.9869 | X5: =IF(D5>=35000,1,IF(D5>=12000,2,IF(D5>=4000,3,4))) -> 1
A6: United Kingdom | B6: GBR | C6: Europe | D6: 48248 | E6: 69.23 | F6: 0.83 | G6: 0.96 | H6: =E6*F6 -> 57.4609 | I6: =H6*G6 -> 55.162464 | J6: =Assumptions!$C$5/(1+EXP(-Assumptions!$C$6*(LN(D6)-Assumptions!$C$7))) -> 0.52381817 | K6: 0.55 | L6: =I6*J6 -> 28.895101 | M6: =VLOOKUP(C6,Assumptions!$B$20:$C$23,2,FALSE())*L6/SUMIF($C$5:$C$134,C6,$L$5:$L$134) -> 14.364295 | N6: =IF(I6=0,0,M6/I6) -> 0.26039981 | O6: =I6*J6*K6 -> 15.892306 | P6: =O6-M6 -> 1.5280106 | Q6: =Assumptions!$C$5/(1+EXP(-Assumptions!$C$6*(LN(D6)-(Assumptions!$C$7+Assumptions!$C$8)))) -> 0.47866894 | R6: =I6*Q6*K6 -> 14.522507 | S6: =Assumptions!$C$5/(1+EXP(-Assumptions!$C$6*(LN(D6)-(Assumptions!$C$7-Assumptions!$C$8)))) -> 0.55645877 | T6: =I6*S6*K6 -> 16.8826 | U6: =VLOOKUP(A6,Pricing!$A$5:$L$134,12,FALSE()) -> 18.651113 | V6: =U6*Assumptions!$C$17 -> 8.5795119 | W6: =O6*V6*12 -> 1636.1787 | X6: =IF(D6>=35000,1,IF(D6>=12000,2,IF(D6>=4000,3,4))) -> 1
A7: France | B7: FRA | C7: Europe | D7: 44213 | E7: 68.55 | F7: 0.83 | G7: 0.96 | H7: =E7*F7 -> 56.8965 | I7: =H7*G7 -> 54.62064 | J7: =Assumptions!$C$5/(1+EXP(-Assumptions!$C$6*(LN(D7)-Assumptions!$C$7))) -> 0.51688155 | K7: 0.5 | L7: =I7*J7 -> 28.232401 | M7: =VLOOKUP(C7,Assumptions!$B$20:$C$23,2,FALSE())*L7/SUMIF($C$5:$C$134,C7,$L$5:$L$134) -> 14.034854 | N7: =IF(I7=0,0,M7/I7) -> 0.25695148 | O7: =I7*J7*K7 -> 14.116201 | P7: =O7-M7 -> 0.081346145 | Q7: =Assumptions!$C$5/(1+EXP(-Assumptions!$C$6*(LN(D7)-(Assumptions!$C$7+Assumptions!$C$8)))) -> 0.46941225 | R7: =I7*Q7*K7 -> 12.819799 | S7: =Assumptions!$C$5/(1+EXP(-Assumptions!$C$6*(LN(D7)-(Assumptions!$C$7-Assumptions!$C$8)))) -> 0.55156866 | T7: =I7*S7*K7 -> 15.063517 | U7: =VLOOKUP(A7,Pricing!$A$5:$L$134,12,FALSE()) -> 15.50342 | V7: =U7*Assumptions!$C$17 -> 7.1315733 | W7: =O7*V7*12 -> 1208.0486 | X7: =IF(D7>=35000,1,IF(D7>=12000,2,IF(D7>=4000,3,4))) -> 1
A8: Italy | B8: ITA | C8: Europe | D8: 38248 | E8: 58.95 | F8: 0.84 | G8: 0.93 | H8: =E8*F8 -> 49.518 | I8: =H8*G8 -> 46.05174 | J8: =Assumptions!$C$5/(1+EXP(-Assumptions!$C$6*(LN(D8)-Assumptions!$C$7))) -> 0.50449595 | K8: 0.55 | L8: =I8*J8 -> 23.232916 | M8: =VLOOKUP(C8,Assumptions!$B$20:$C$23,2,FALSE())*L8/SUMIF($C$5:$C$134,C8,$L$5:$L$134) -> 11.549517 | N8: =IF(I8=0,0,M8/I8) -> 0.25079437 | O8: =I8*J8*K8 -> 12.778104 | P8: =O8-M8 -> 1.2285869 | Q8: =Assumptions!$C$5/(1+EXP(-Assumptions!$C$6*(LN(D8)-(Assumptions!$C$7+Assumptions!$C$8)))) -> 0.45316539 | R8: =I8*Q8*K8 -> 11.47798 | S8: =Assumptions!$C$5/(1+EXP(-Assumptions!$C$6*(LN(D8)-(Assumptions!$C$7-Assumptions!$C$8)))) -> 0.54272649 | T8: =I8*S8*K8 -> 13.746424 | U8: =VLOOKUP(A8,Pricing!$A$5:$L$134,12,FALSE()) -> 15.228986 | V8: =U8*Assumptions!$C$17 -> 7.0053333 | W8: =O8*V8*12 -> 1074.1785 | X8: =IF(D8>=35000,1,IF(D8>=12000,2,IF(D8>=4000,3,4))) -> 1
A9: Spain | B9: ESP | C9: Europe | D9: 32359 | E9: 48.85 | F9: 0.84 | G9: 0.93 | H9: =E9*F9 -> 41.034 | I9: =H9*G9 -> 38.16162 | J9: =Assumptions!$C$5/(1+EXP(-Assumptions!$C$6*(LN(D9)-Assumptions!$C$7))) -> 0.48881909 | K9: 0.55 | L9: =I9*J9 -> 18.654128 | M9: =VLOOKUP(C9,Assumptions!$B$20:$C$23,2,FALSE())*L9/SUMIF($C$5:$C$134,C9,$L$5:$L$134) -> 9.2733159 | N9: =IF(I9=0,0,M9/I9) -> 0.24300111 | O9: =I9*J9*K9 -> 10.259771 | P9: =O9-M9 -> 0.98645464 | Q9: =Assumptions!$C$5/(1+EXP(-Assumptions!$C$6*(LN(D9)-(Assumptions!$C$7+Assumptions!$C$8)))) -> 0.43310263 | R9: =I9*Q9*K9 -> 9.0903439 | S9: =Assumptions!$C$5/(1+EXP(-Assumptions!$C$6*(LN(D9)-(Assumptions!$C$7-Assumptions!$C$8)))) -> 0.53132646 | T9: =I9*S9*K9 -> 11.151953 | U9: =VLOOKUP(A9,Pricing!$A$5:$L$134,12,FALSE()) -> 15.228986 | V9: =U9*Assumptions!$C$17 -> 7.0053333 | W9: =O9*V9*12 -> 862.47735 | X9: =IF(D9>=35000,1,IF(D9>=12000,2,IF(D9>=4000,3,4))) -> 2
A10: Ukraine | B10: UKR | C10: Europe | D10: 4721 | E10: 37.86 | F10: 0.84 | G10: 0.63 | H10: =E10*F10 -> 31.8024 | I10: =H10*G10 -> 20.035512 | J10: =Assumptions!$C$5/(1+EXP(-Assumptions!$C$6*(LN(D10)-Assumptions!$C$7))) -> 0.23215321 | K10: 0.55 | L10: =I10*J10 -> 4.6513083 | M10: =VLOOKUP(C10,Assumptions!$B$20:$C$23,2,FALSE())*L10/SUMIF($C$5:$C$134,C10,$L$5:$L$134) -> 2.3122523 | N10: =IF(I10=0,0,M10/I10) -> 0.1154077 | O10: =I10*J10*K10 -> 2.5582196 | P10: =O10-M10 -> 0.24596725 | Q10: =Assumptions!$C$5/(1+EXP(-Assumptions!$C$6*(LN(D10)-(Assumptions!$C$7+Assumptions!$C$8)))) -> 0.16818443 | R10: =I10*Q10*K10 -> 1.8533137 | S10: =Assumptions!$C$5/(1+EXP(-Assumptions!$C$6*(LN(D10)-(Assumptions!$C$7-Assumptions!$C$8)))) -> 0.30407772 | T10: =I10*S10*K10 -> 3.3507941 | U10: =VLOOKUP(A10,Pricing!$A$5:$L$134,12,FALSE()) -> 5.26 | V10: =U10*Assumptions!$C$17 -> 2.4196 | W10: =O10*V10*12 -> 74.278417 | X10: =IF(D10>=35000,1,IF(D10>=12000,2,IF(D10>=4000,3,4))) -> 3
A11: Poland | B11: POL | C11: Europe | D11: 22189 | E11: 36.56 | F11: 0.84 | G11: 0.86 | H11: =E11*F11 -> 30.7104 | I11: =H11*G11 -> 26.410944 | J11: =Assumptions!$C$5/(1+EXP(-Assumptions!$C$6*(LN(D11)-Assumptions!$C$7))) -> 0.44796092 | K11: 0.55 | L11: =I11*J11 -> 11.831071 | M11: =VLOOKUP(C11,Assumptions!$B$20:$C$23,2,FALSE())*L11/SUMIF($C$5:$C$134,C11,$L$5:$L$134) -> 5.8814465 | N11: =IF(I11=0,0,M11/I11) -> 0.22268975 | O11: =I11*J11*K11 -> 6.507089 | P11: =O11-M11 -> 0.62564246 | Q11: =Assumptions!$C$5/(1+EXP(-Assumptions!$C$6*(LN(D11)-(Assumptions!$C$7+Assumptions!$C$8)))) -> 0.38329413 | R11: =I11*Q11*K11 -> 5.5677379 | S11: =Assumptions!$C$5/(1+EXP(-Assumptions!$C$6*(LN(D11)-(Assumptions!$C$7-Assumptions!$C$8)))) -> 0.50047039 | T11: =I11*S11*K11 -> 7.2698425 | U11: =VLOOKUP(A11,Pricing!$A$5:$L$134,12,FALSE()) -> 7.988578 | V11: =U11*Assumptions!$C$17 -> 3.6747459 | W11: =O11*V11*12 -> 286.94278 | X11: =IF(D11>=35000,1,IF(D11>=12000,2,IF(D11>=4000,3,4))) -> 2
A12: Romania | B12: ROU | C12: Europe | D12: 18424 | E12: 19.05 | F12: 0.84 | G12: 0.86 | H12: =E12*F12 -> 16.002 | I12: =H12*G12 -> 13.76172 | J12: =Assumptions!$C$5/(1+EXP(-Assumptions!$C$6*(LN(D12)-Assumptions!$C$7))) -> 0.42516696 | K12: 0.55 | L12: =I12*J12 -> 5.8510287 | M12: =VLOOKUP(C12,Assumptions!$B$20:$C$23,2,FALSE())*L12/SUMIF($C$5:$C$134,C12,$L$5:$L$134) -> 2.9086557 | N12: =IF(I12=0,0,M12/I12) -> 0.21135845 | O12: =I12*J12*K12 -> 3.2180658 | P12: =O12-M12 -> 0.30941003 | Q12: =Assumptions!$C$5/(1+EXP(-Assumptions!$C$6*(LN(D12)-(Assumptions!$C$7+Assumptions!$C$8)))) -> 0.35696323 | R12: =I12*Q12*K12 -> 2.7018354 | S12: =Assumptions!$C$5/(1+EXP(-Assumptions!$C$6*(LN(D12)-(Assumptions!$C$7-Assumptions!$C$8)))) -> 0.48249807 | T12: =I12*S12*K12 -> 3.6520018 | U12: =VLOOKUP(A12,Pricing!$A$5:$L$134,12,FALSE()) -> 6.1399038 | V12: =U12*Assumptions!$C$17 -> 2.8243558 | W12: =O12*V12*12 -> 109.06755 | X12: =IF(D12>=35000,1,IF(D12>=12000,2,IF(D12>=4000,3,4))) -> 2
A13: Netherlands | B13: NLD | C13: Europe | D13: 62141 | E13: 17.99 | F13: 0.83 | G13: 0.96 | H13: =E13*F13 -> 14.9317 | I13: =H13*G13 -> 14.334432 | J13: =Assumptions!$C$5/(1+EXP(-Assumptions!$C$6*(LN(D13)-Assumptions!$C$7))) -> 0.54177785 | K13: 0.55 | L13: =I13*J13 -> 7.7660778 | M13: =VLOOKUP(C13,Assumptions!$B$20:$C$23,2,FALSE())*L13/SUMIF($C$5:$C$134,C13,$L$5:$L$134) -> 3.8606625 | N13: =IF(I13=0,0,M13/I13) -> 0.2693279 | O13: =I13*J13*K13 -> 4.2713428 | P13: =O13-M13 -> 0.41068032 | Q13: =Assumptions!$C$5/(1+EXP(-Assumptions!$C$6*(LN(D13)-(Assumptions!$C$7+Assumptions!$C$8)))) -> 0.50317901 | R13: =I13*Q13*K13 -> 3.9670319 | S13: =Assumptions!$C$5/(1+EXP(-Assumptions!$C$6*(LN(D13)-(Assumptions!$C$7-Assumptions!$C$8)))) -> 0.56891796 | T13: =I13*S13*K13 -> 4.4853137 | U13: =VLOOKUP(A13,Pricing!$A$5:$L$134,12,FALSE()) -> 16.301449 | V13: =U13*Assumptions!$C$17 -> 7.4986667 | W13: =O13*V13*12 -> 384.35251 | X13: =IF(D13>=35000,1,IF(D13>=12000,2,IF(D13>=4000,3,4))) -> 1
A14: Belgium | B14: BEL | C14: Europe | D14: 53313 | E14: 11.86 | F14: 0.83 | G14: 0.96 | H14: =E14*F14 -> 9.8438 | I14: =H14*G14 -> 9.450048 | J14: =Assumptions!$C$5/(1+EXP(-Assumptions!$C$6*(LN(D14)-Assumptions!$C$7))) -> 0.53127505 | K14: 0.55 | L14: =I14*J14 -> 5.0205747 | M14: =VLOOKUP(C14,Assumptions!$B$20:$C$23,2,FALSE())*L14/SUMIF($C$5:$C$134,C14,$L$5:$L$134) -> 2.4958215 | N14: =IF(I14=0,0,M14/I14) -> 0.26410676 | O14: =I14*J14*K14 -> 2.7613161 | P14: =O14-M14 -> 0.26549454 | Q14: =Assumptions!$C$5/(1+EXP(-Assumptions!$C$6*(LN(D14)-(Assumptions!$C$7+Assumptions!$C$8)))) -> 0.48874912 | R14: =I14*Q14*K14 -> 2.5402865 | S14: =Assumptions!$C$5/(1+EXP(-Assumptions!$C$6*(LN(D14)-(Assumptions!$C$7-Assumptions!$C$8)))) -> 0.56166687 | T14: =I14*S14*K14 -> 2.9192784 | U14: =VLOOKUP(A14,Pricing!$A$5:$L$134,12,FALSE()) -> 15.315942 | V14: =U14*Assumptions!$C$17 -> 7.0453333 | W14: =O14*V14*12 -> 233.45271 | X14: =IF(D14>=35000,1,IF(D14>=12000,2,IF(D14>=4000,3,4))) -> 1
A15: Czech Republic | B15: CZE | C15: Europe | D15: 30340 | E15: 10.9 | F15: 0.84 | G15: 0.93 | H15: =E15*F15 -> 9.156 | I15: =H15*G15 -> 8.51508 | J15: =Assumptions!$C$5/(1+EXP(-Assumptions!$C$6*(LN(D15)-Assumptions!$C$7))) -> 0.48237735 | K15: 0.55 | L15: =I15*J15 -> 4.1074817 | M15: =VLOOKUP(C15,Assumptions!$B$20:$C$23,2,FALSE())*L15/SUMIF($C$5:$C$134,C15,$L$5:$L$134) -> 2.0419059 | N15: =IF(I15=0,0,M15/I15) -> 0.2397988 | O15: =I15*J15*K15 -> 2.2591149 | P15: =O15-M15 -> 0.21720899 | Q15: =Assumptions!$C$5/(1+EXP(-Assumptions!$C$6*(LN(D15)-(Assumptions!$C$7+Assumptions!$C$8)))) -> 0.42501624 | R15: =I15*Q15*K15 -> 1.990476 | S15: =Assumptions!$C$5/(1+EXP(-Assumptions!$C$6*(LN(D15)-(Assumptions!$C$7-Assumptions!$C$8)))) -> 0.52657312 | T15: =I15*S15*K15 -> 2.4660967 | U15: =VLOOKUP(A15,Pricing!$A$5:$L$134,12,FALSE()) -> 9.4488189 | V15: =U15*Assumptions!$C$17 -> 4.3464567 | W15: =O15*V15*12 -> 117.82974 | X15: =IF(D15>=35000,1,IF(D15>=12000,2,IF(D15>=4000,3,4))) -> 2
A16: Portugal | B16: PRT | C16: Europe | D16: 26843 | E16: 10.7 | F16: 0.84 | G16: 0.93 | H16: =E16*F16 -> 8.988 | I16: =H16*G16 -> 8.35884 | J16: =Assumptions!$C$5/(1+EXP(-Assumptions!$C$6*(LN(D16)-Assumptions!$C$7))) -> 0.46951905 | K16: 0.55 | L16: =I16*J16 -> 3.9246346 | M16: =VLOOKUP(C16,Assumptions!$B$20:$C$23,2,FALSE())*L16/SUMIF($C$5:$C$134,C16,$L$5:$L$134) -> 1.9510092 | N16: =IF(I16=0,0,M16/I16) -> 0.2334067 | O16: =I16*J16*K16 -> 2.158549 | P16: =O16-M16 -> 0.2075398 | Q16: =Assumptions!$C$5/(1+EXP(-Assumptions!$C$6*(LN(D16)-(Assumptions!$C$7+Assumptions!$C$8)))) -> 0.4091413 | R16: =I16*Q16*K16 -> 1.8809707 | S16: =Assumptions!$C$5/(1+EXP(-Assumptions!$C$6*(LN(D16)-(Assumptions!$C$7-Assumptions!$C$8)))) -> 0.51696207 | T16: =I16*S16*K16 -> 2.3766618 | U16: =VLOOKUP(A16,Pricing!$A$5:$L$134,12,FALSE()) -> 11.327536 | V16: =U16*Assumptions!$C$17 -> 5.2106667 | W16: =O16*V16*12 -> 134.96975 | X16: =IF(D16>=35000,1,IF(D16>=12000,2,IF(D16>=4000,3,4))) -> 2
... A134: Tuvalu | B134: TUV | C134: Rest of World | D134: 6457 | E134: 0.01 | F134: 0.64 | G134: 0.76 | H134: =E134*F134 -> 0.0064 | I134: =H134*G134 -> 0.004864 | J134: =Assumptions!$C$5/(1+EXP(-Assumptions!$C$6*(LN(D134)-Assumptions!$C$7))) -> 0.27669156 | K134: 0.45 | L134: =I134*J134 -> 0.0013458277 | M134: =VLOOKUP(C134,Assumptions!$B$20:$C$23,2,FALSE())*L134/SUMIF($C$5:$C$134,C134,$L$5:$L$134) -> 0.00015975521 | N134: =IF(I134=0,0,M134/I134) -> 0.03284441 | O134: =I134*J134*K134 -> 0.00060562248 | P134: =O134-M134 -> 0.00044586727 | Q134: =Assumptions!$C$5/(1+EXP(-Assumptions!$C$6*(LN(D134)-(Assumptions!$C$7+Assumptions!$C$8)))) -> 0.2070004 | R134: =I134*Q134*K134 -> 0.00045308247 | S134: =Assumptions!$C$5/(1+EXP(-Assumptions!$C$6*(LN(D134)-(Assumptions!$C$7-Assumptions!$C$8)))) -> 0.34996386 | T134: =I134*S134*K134 -> 0.0007660009 | U134: =VLOOKUP(A134,Pricing!$A$5:$L$134,12,FALSE()) -> 9.9964677 | V134: =U134*Assumptions!$C$17 -> 4.5983751 | W134: =O134*V134*12 -> 0.033418552 | X134: =IF(D134>=35000,1,IF(D134>=12000,2,IF(D134>=4000,3,4))) -> 3
A135: TOTAL | E135: =SUM(E5:E134) -> 5544.39 | H135: =SUM(H5:H134) -> 3979.7736 | I135: =SUM(I5:I134) -> 2592.9089 | L135: =SUM(L5:L134) -> 857.13798 | M135: =SUM(M5:M134) -> 290 | N135: =M135/I135 -> 0.1118435 | O135: =SUM(O5:O134) -> 395.62449 | P135: =SUM(P5:P134) -> 105.62449 | R135: =SUM(R5:R134) -> 333.32627 | T135: =SUM(T5:T134) -> 457.02559 | W135: =SUM(W5:W134) -> 20899.386

Sheet Pricing
A1: Spotify pricing by country — local → USD (blue = input; paste local prices / FX to refresh)
A2: Source: user-supplied Spotify pricing file (Feb-2026). FX: ECB ref 16-Jun-2026 + embedded for minors. USD-billed markets shown as USD, FX=1.
A4: Country | B4: Currency | C4: FX (per $) | D4: Individual | E4: Student | F4: Duo | G4: Family | H4: Indiv $ | I4: Student $ | J4: Duo $ | K4: Family $ | L4: Blended $/mo
A5: Germany | B5: EUR | C5: 0.8625 | D5: 12.99 | E5: 6.99 | F5: 17.99 | G5: 21.99 | H5: =IF(D5="","",D5/$C5) -> 15.06087 | I5: =IF(E5="","",E5/$C5) -> 8.1043478 | J5: =IF(F5="","",F5/$C5) -> 20.857971 | K5: =IF(G5="","",G5/$C5) -> 25.495652 | L5: =(H5*Assumptions!$C$11+IF(K5="",H5,K5)*Assumptions!$C$12+IF(J5="",H5,J5)*Assumptions!$C$13+IF(I5="",H5,I5)*Assumptions!$C$14)/Assumptions!$C$15 -> 16.301449
A6: United Kingdom | B6: GBP | C6: 0.7458 | D6: 12.99 | E6: 5.99 | F6: 17.99 | G6: 21.99 | H6: =IF(D6="","",D6/$C6) -> 17.417538 | I6: =IF(E6="","",E6/$C6) -> 8.0316439 | J6: =IF(F6="","",F6/$C6) -> 24.121748 | K6: =IF(G6="","",G6/$C6) -> 29.485117 | L6: =(H6*Assumptions!$C$11+IF(K6="",H6,K6)*Assumptions!$C$12+IF(J6="",H6,J6)*Assumptions!$C$13+IF(I6="",H6,I6)*Assumptions!$C$14)/Assumptions!$C$15 -> 18.651113
A7: France | B7: EUR | C7: 0.8625 | D7: 12.14 | E7: 7.07 | F7: 17.2 | G7: 21.24 | H7: =IF(D7="","",D7/$C7) -> 14.075362 | I7: =IF(E7="","",E7/$C7) -> 8.1971014 | J7: =IF(F7="","",F7/$C7) -> 19.942029 | K7: =IF(G7="","",G7/$C7) -> 24.626087 | L7: =(H7*Assumptions!$C$11+IF(K7="",H7,K7)*Assumptions!$C$12+IF(J7="",H7,J7)*Assumptions!$C$13+IF(I7="",H7,I7)*Assumptions!$C$14)/Assumptions!$C$15 -> 15.50342
A8: Italy | B8: EUR | C8: 0.8625 | D8: 11.99 | E8: 6.49 | F8: 16.99 | G8: 20.99 | H8: =IF(D8="","",D8/$C8) -> 13.901449 | I8: =IF(E8="","",E8/$C8) -> 7.5246377 | J8: =IF(F8="","",F8/$C8) -> 19.698551 | K8: =IF(G8="","",G8/$C8) -> 24.336232 | L8: =(H8*Assumptions!$C$11+IF(K8="",H8,K8)*Assumptions!$C$12+IF(J8="",H8,J8)*Assumptions!$C$13+IF(I8="",H8,I8)*Assumptions!$C$14)/Assumptions!$C$15 -> 15.228986
A9: Spain | B9: EUR | C9: 0.8625 | D9: 11.99 | E9: 6.49 | F9: 16.99 | G9: 20.99 | H9: =IF(D9="","",D9/$C9) -> 13.901449 | I9: =IF(E9="","",E9/$C9) -> 7.5246377 | J9: =IF(F9="","",F9/$C9) -> 19.698551 | K9: =IF(G9="","",G9/$C9) -> 24.336232 | L9: =(H9*Assumptions!$C$11+IF(K9="",H9,K9)*Assumptions!$C$12+IF(J9="",H9,J9)*Assumptions!$C$13+IF(I9="",H9,I9)*Assumptions!$C$14)/Assumptions!$C$15 -> 15.228986
A10: Ukraine | B10: USD | C10: 1 | D10: 4.99 | E10: 2.49 | F10: 6.49 | G10: 7.99 | H10: =IF(D10="","",D10/$C10) -> 4.99 | I10: =IF(E10="","",E10/$C10) -> 2.49 | J10: =IF(F10="","",F10/$C10) -> 6.49 | K10: =IF(G10="","",G10/$C10) -> 7.99 | L10: =(H10*Assumptions!$C$11+IF(K10="",H10,K10)*Assumptions!$C$12+IF(J10="",H10,J10)*Assumptions!$C$13+IF(I10="",H10,I10)*Assumptions!$C$14)/Assumptions!$C$15 -> 5.26
A11: Poland | B11: PLN | C11: 3.6596 | D11: 26.99 | E11: 14.49 | F11: 36.99 | G11: 45.99 | H11: =IF(D11="","",D11/$C11) -> 7.375123 | I11: =IF(E11="","",E11/$C11) -> 3.9594491 | J11: =IF(F11="","",F11/$C11) -> 10.107662 | K11: =IF(G11="","",G11/$C11) -> 12.566947 | L11: =(H11*Assumptions!$C$11+IF(K11="",H11,K11)*Assumptions!$C$12+IF(J11="",H11,J11)*Assumptions!$C$13+IF(I11="",H11,I11)*Assumptions!$C$14)/Assumptions!$C$15 -> 7.988578
A12: Romania | B12: RON | C12: 4.5131 | D12: 26 | E12: 14 | F12: 35 | G12: 42 | H12: =IF(D12="","",D12/$C12) -> 5.7610068 | I12: =IF(E12="","",E12/$C12) -> 3.1020806 | J12: =IF(F12="","",F12/$C12) -> 7.7552015 | K12: =IF(G12="","",G12/$C12) -> 9.3062418 | L12: =(H12*Assumptions!$C$11+IF(K12="",H12,K12)*Assumptions!$C$12+IF(J12="",H12,J12)*Assumptions!$C$13+IF(I12="",H12,I12)*Assumptions!$C$14)/Assumptions!$C$15 -> 6.1399038
A13: Netherlands | B13: EUR | C13: 0.8625 | D13: 12.99 | E13: 6.99 | F13: 17.99 | G13: 21.99 | H13: =IF(D13="","",D13/$C13) -> 15.06087 | I13: =IF(E13="","",E13/$C13) -> 8.1043478 | J13: =IF(F13="","",F13/$C13) -> 20.857971 | K13: =IF(G13="","",G13/$C13) -> 25.495652 | L13: =(H13*Assumptions!$C$11+IF(K13="",H13,K13)*Assumptions!$C$12+IF(J13="",H13,J13)*Assumptions!$C$13+IF(I13="",H13,I13)*Assumptions!$C$14)/Assumptions!$C$15 -> 16.301449
A14: Belgium | B14: EUR | C14: 0.8625 | D14: 11.99 | E14: 6.99 | F14: 16.99 | G14: 20.99 | H14: =IF(D14="","",D14/$C14) -> 13.901449 | I14: =IF(E14="","",E14/$C14) -> 8.1043478 | J14: =IF(F14="","",F14/$C14) -> 19.698551 | K14: =IF(G14="","",G14/$C14) -> 24.336232 | L14: =(H14*Assumptions!$C$11+IF(K14="",H14,K14)*Assumptions!$C$12+IF(J14="",H14,J14)*Assumptions!$C$13+IF(I14="",H14,I14)*Assumptions!$C$14)/Assumptions!$C$15 -> 15.315942
A15: Czech Republic | B15: CZK | C15: 20.828 | D15: 185 | E15: 97 | F15: 249 | G15: 299 | H15: =IF(D15="","",D15/$C15) -> 8.8822739 | I15: =IF(E15="","",E15/$C15) -> 4.6571922 | J15: =IF(F15="","",F15/$C15) -> 11.95506 | K15: =IF(G15="","",G15/$C15) -> 14.355675 | L15: =(H15*Assumptions!$C$11+IF(K15="",H15,K15)*Assumptions!$C$12+IF(J15="",H15,J15)*Assumptions!$C$13+IF(I15="",H15,I15)*Assumptions!$C$14)/Assumptions!$C$15 -> 9.4488189
A16: Portugal | B16: EUR | C16: 0.8625 | D16: 8.99 | E16: 4.99 | F16: 11.99 | G16: 15.49 | H16: =IF(D16="","",D16/$C16) -> 10.423188 | I16: =IF(E16="","",E16/$C16) -> 5.7855072 | J16: =IF(F16="","",F16/$C16) -> 13.901449 | K16: =IF(G16="","",G16/$C16) -> 17.95942 | L16: =(H16*Assumptions!$C$11+IF(K16="",H16,K16)*Assumptions!$C$12+IF(J16="",H16,J16)*Assumptions!$C$13+IF(I16="",H16,I16)*Assumptions!$C$14)/Assumptions!$C$15 -> 11.327536
... A72: Canada | B72: CAD | C72: 1.4014 | D72: 12.69 | E72: 6.39 | F72: 17.89 | G72: 20.99 | H72: =IF(D72="","",D72/$C72) -> 9.0552305 | I72: =IF(E72="","",E72/$C72) -> 4.559726 | J72: =IF(F72="","",F72/$C72) -> 12.765806 | K72: =IF(G72="","",G72/$C72) -> 14.977879 | L72: =(H72*Assumptions!$C$11+IF(K72="",H72,K72)*Assumptions!$C$12+IF(J72="",H72,J72)*Assumptions!$C$13+IF(I72="",H72,I72)*Assumptions!$C$14)/Assumptions!$C$15 -> 9.7067218
A73: India | B73: INR | C73: 94.5605 | D73: 199 | E73: 99 | H73: =IF(D73="","",D73/$C73) -> 2.1044728 | I73: =IF(E73="","",E73/$C73) -> 1.0469488 | J73: =IF(F73="","",F73/$C73) | K73: =IF(G73="","",G73/$C73) | L73: =(H73*Assumptions!$C$11+IF(K73="",H73,K73)*Assumptions!$C$12+IF(J73="",H73,J73)*Assumptions!$C$13+IF(I73="",H73,I73)*Assumptions!$C$14)/Assumptions!$C$15 -> 1.9458442
A74: Indonesia | B74: IDR | C74: 17721.649 | D74: 79900 | E74: 39900 | H74: =IF(D74="","",D74/$C74) -> 4.5086098 | I74: =IF(E74="","",E74/$C74) -> 2.2514835 | J74: =IF(F74="","",F74/$C74) | K74: =IF(G74="","",G74/$C74) | L74: =(H74*Assumptions!$C$11+IF(K74="",H74,K74)*Assumptions!$C$12+IF(J74="",H74,J74)*Assumptions!$C$13+IF(I74="",H74,I74)*Assumptions!$C$14)/Assumptions!$C$15 -> 4.1700408
A75: Pakistan | B75: PKR | C75: 278 | D75: 379 | E75: 199 | F75: 519 | G75: 679 | H75: =IF(D75="","",D75/$C75) -> 1.3633094 | I75: =IF(E75="","",E75/$C75) -> 0.71582734 | J75: =IF(F75="","",F75/$C75) -> 1.8669065 | K75: =IF(G75="","",G75/$C75) -> 2.442446 | L75: =(H75*Assumptions!$C$11+IF(K75="",H75,K75)*Assumptions!$C$12+IF(J75="",H75,J75)*Assumptions!$C$13+IF(I75="",H75,I75)*Assumptions!$C$14)/Assumptions!$C$15 -> 1.4956835
A76: Nigeria | B76: NGN | C76: 1530 | D76: 1600 | E76: 800 | F76: 2100 | G76: 2500 | H76: =IF(D76="","",D76/$C76) -> 1.0457516 | I76: =IF(E76="","",E76/$C76) -> 0.52287582 | J76: =IF(F76="","",F76/$C76) -> 1.372549 | K76: =IF(G76="","",G76/$C76) -> 1.6339869 | L76: =(H76*Assumptions!$C$11+IF(K76="",H76,K76)*Assumptions!$C$12+IF(J76="",H76,J76)*Assumptions!$C$13+IF(I76="",H76,I76)*Assumptions!$C$14)/Assumptions!$C$15 -> 1.0960784
A77: Bangladesh | B77: BDT | C77: 120 | D77: 219 | E77: 109 | F77: 299 | G77: 379 | H77: =IF(D77="","",D77/$C77) -> 1.825 | I77: =IF(E77="","",E77/$C77) -> 0.90833333 | J77: =IF(F77="","",F77/$C77) -> 2.4916667 | K77: =IF(G77="","",G77/$C77) -> 3.1583333 | L77: =(H77*Assumptions!$C$11+IF(K77="",H77,K77)*Assumptions!$C$12+IF(J77="",H77,J77)*Assumptions!$C$13+IF(I77="",H77,I77)*Assumptions!$C$14)/Assumptions!$C$15 -> 1.9741667
A78: Ethiopia | B78: USD | C78: 1 | D78: 3.29 | E78: 1.69 | F78: 4.49 | G78: 5.79 | H78: =IF(D78="","",D78/$C78) -> 3.29 | I78: =IF(E78="","",E78/$C78) -> 1.69 | J78: =IF(F78="","",F78/$C78) -> 4.49 | K78: =IF(G78="","",G78/$C78) -> 5.79 | L78: =(H78*Assumptions!$C$11+IF(K78="",H78,K78)*Assumptions!$C$12+IF(J78="",H78,J78)*Assumptions!$C$13+IF(I78="",H78,I78)*Assumptions!$C$14)/Assumptions!$C$15 -> 3.584
A79: Japan | B79: JPY | C79: 160.3761 | D79: 1080 | E79: 580 | F79: 1480 | G79: 1880 | H79: =IF(D79="","",D79/$C79) -> 6.7341705 | I79: =IF(E79="","",E79/$C79) -> 3.616499 | J79: =IF(F79="","",F79/$C79) -> 9.2283077 | K79: =IF(G79="","",G79/$C79) -> 11.722445 | L79: =(H79*Assumptions!$C$11+IF(K79="",H79,K79)*Assumptions!$C$12+IF(J79="",H79,J79)*Assumptions!$C$13+IF(I79="",H79,I79)*Assumptions!$C$14)/Assumptions!$C$15 -> 7.3389988
A80: Egypt | B80: EGP | C80: 49.5 | D80: 79 | E80: 39 | F80: 109 | G80: 139 | H80: =IF(D80="","",D80/$C80) -> 1.5959596 | I80: =IF(E80="","",E80/$C80) -> 0.78787879 | J80: =IF(F80="","",F80/$C80) -> 2.2020202 | K80: =IF(G80="","",G80/$C80) -> 2.8080808 | L80: =(H80*Assumptions!$C$11+IF(K80="",H80,K80)*Assumptions!$C$12+IF(J80="",H80,J80)*Assumptions!$C$13+IF(I80="",H80,I80)*Assumptions!$C$14)/Assumptions!$C$15 -> 1.7353535
A81: Philippines | B81: PHP | C81: 60.3114 | D81: 169 | E81: 85 | F81: 229 | G81: 279 | H81: =IF(D81="","",D81/$C81) -> 2.8021236 | I81: =IF(E81="","",E81/$C81) -> 1.4093521 | J81: =IF(F81="","",F81/$C81) -> 3.7969604 | K81: =IF(G81="","",G81/$C81) -> 4.6259911 | L81: =(H81*Assumptions!$C$11+IF(K81="",H81,K81)*Assumptions!$C$12+IF(J81="",H81,J81)*Assumptions!$C$13+IF(I81="",H81,I81)*Assumptions!$C$14)/Assumptions!$C$15 -> 2.9911426
A82: Vietnam | B82: VND | C82: 25400 | D82: 65000 | E82: 33000 | H82: =IF(D82="","",D82/$C82) -> 2.5590551 | I82: =IF(E82="","",E82/$C82) -> 1.2992126 | J82: =IF(F82="","",F82/$C82) | K82: =IF(G82="","",G82/$C82) | L82: =(H82*Assumptions!$C$11+IF(K82="",H82,K82)*Assumptions!$C$12+IF(J82="",H82,J82)*Assumptions!$C$13+IF(I82="",H82,I82)*Assumptions!$C$14)/Assumptions!$C$15 -> 2.3700787
A83: Turkey | B83: USD | C83: 1 | D83: 2.6 | E83: 1.3 | F83: 3.4 | G83: 4.2 | H83: =IF(D83="","",D83/$C83) -> 2.6 | I83: =IF(E83="","",E83/$C83) -> 1.3 | J83: =IF(F83="","",F83/$C83) -> 3.4 | K83: =IF(G83="","",G83/$C83) -> 4.2 | L83: =(H83*Assumptions!$C$11+IF(K83="",H83,K83)*Assumptions!$C$12+IF(J83="",H83,J83)*Assumptions!$C$13+IF(I83="",H83,I83)*Assumptions!$C$14)/Assumptions!$C$15 -> 2.749
A84: Thailand | B84: THB | C84: 32.5151 | D84: 149 | E84: 79 | F84: 209 | G84: 249 | H84: =IF(D84="","",D84/$C84) -> 4.5824863 | I84: =IF(E84="","",E84/$C84) -> 2.4296404 | J84: =IF(F84="","",F84/$C84) -> 6.4277828 | K84: =IF(G84="","",G84/$C84) -> 7.6579804 | L84: =(H84*Assumptions!$C$11+IF(K84="",H84,K84)*Assumptions!$C$12+IF(J84="",H84,J84)*Assumptions!$C$13+IF(I84="",H84,I84)*Assumptions!$C$14)/Assumptions!$C$15 -> 4.9423191
A85: Tanzania | B85: TZS | C85: 2550 | D85: 7500 | E85: 4000 | F85: 10000 | G85: 13000 | H85: =IF(D85="","",D85/$C85) -> 2.9411765 | I85: =IF(E85="","",E85/$C85) -> 1.5686275 | J85: =IF(F85="","",F85/$C85) -> 3.9215686 | K85: =IF(G85="","",G85/$C85) -> 5.0980392 | L85: =(H85*Assumptions!$C$11+IF(K85="",H85,K85)*Assumptions!$C$12+IF(J85="",H85,J85)*Assumptions!$C$13+IF(I85="",H85,I85)*Assumptions!$C$14)/Assumptions!$C$15 -> 3.1921569
A86: South Africa | B86: ZAR | C86: 16.1896 | D86: 94.99 | E86: 47.99 | H86: =IF(D86="","",D86/$C86) -> 5.8673469 | I86: =IF(E86="","",E86/$C86) -> 2.9642487 | J86: =IF(F86="","",F86/$C86) | K86: =IF(G86="","",G86/$C86) | L86: =(H86*Assumptions!$C$11+IF(K86="",H86,K86)*Assumptions!$C$12+IF(J86="",H86,J86)*Assumptions!$C$13+IF(I86="",H86,I86)*Assumptions!$C$14)/Assumptions!$C$15 -> 5.4318822
A87: Kenya | B87: KES | C87: 129 | D87: 419 | E87: 209 | F87: 549 | G87: 669 | H87: =IF(D87="","",D87/$C87) -> 3.248062 | I87: =IF(E87="","",E87/$C87) -> 1.620155 | J87: =IF(F87="","",F87/$C87) -> 4.255814 | K87: =IF(G87="","",G87/$C87) -> 5.1860465 | L87: =(H87*Assumptions!$C$11+IF(K87="",H87,K87)*Assumptions!$C$12+IF(J87="",H87,J87)*Assumptions!$C$13+IF(I87="",H87,I87)*Assumptions!$C$14)/Assumptions!$C$15 -> 3.4232558
A88: South Korea | B88: KRW | C88: 1508.8494 | D88: 10900 | E88: 6000 | F88: 16350 | H88: =IF(D88="","",D88/$C88) -> 7.2240477 | I88: =IF(E88="","",E88/$C88) -> 3.97654 | J88: =IF(F88="","",F88/$C88) -> 10.836072 | K88: =IF(G88="","",G88/$C88) | L88: =(H88*Assumptions!$C$11+IF(K88="",H88,K88)*Assumptions!$C$12+IF(J88="",H88,J88)*Assumptions!$C$13+IF(I88="",H88,I88)*Assumptions!$C$14)/Assumptions!$C$15 -> 6.9897632
A89: Uganda | B89: UGX | C89: 3700 | D89: 11000 | E89: 5500 | F89: 15000 | G89: 19000 | H89: =IF(D89="","",D89/$C89) -> 2.972973 | I89: =IF(E89="","",E89/$C89) -> 1.4864865 | J89: =IF(F89="","",F89/$C89) -> 4.0540541 | K89: =IF(G89="","",G89/$C89) -> 5.1351351 | L89: =(H89*Assumptions!$C$11+IF(K89="",H89,K89)*Assumptions!$C$12+IF(J89="",H89,J89)*Assumptions!$C$13+IF(I89="",H89,I89)*Assumptions!$C$14)/Assumptions!$C$15 -> 3.2148649
A90: Algeria | B90: USD | C90: 1 | D90: 4.99 | E90: 2.49 | F90: 6.49 | G90: 7.99 | H90: =IF(D90="","",D90/$C90) -> 4.99 | I90: =IF(E90="","",E90/$C90) -> 2.49 | J90: =IF(F90="","",F90/$C90) -> 6.49 | K90: =IF(G90="","",G90/$C90) -> 7.99 | L90: =(H90*Assumptions!$C$11+IF(K90="",H90,K90)*Assumptions!$C$12+IF(J90="",H90,J90)*Assumptions!$C$13+IF(I90="",H90,I90)*Assumptions!$C$14)/Assumptions!$C$15 -> 5.26
A91: Morocco | B91: MAD | C91: 9.9 | D91: 45 | E91: 23 | F91: 60 | G91: 75 | H91: =IF(D91="","",D91/$C91) -> 4.5454545 | I91: =IF(E91="","",E91/$C91) -> 2.3232323 | J91: =IF(F91="","",F91/$C91) -> 6.0606061 | K91: =IF(G91="","",G91/$C91) -> 7.5757576 | L91: =(H91*Assumptions!$C$11+IF(K91="",H91,K91)*Assumptions!$C$12+IF(J91="",H91,J91)*Assumptions!$C$13+IF(I91="",H91,I91)*Assumptions!$C$14)/Assumptions!$C$15 -> 4.8636364
A92: Uzbekistan | B92: USD | C92: 1 | D92: 5.49 | E92: 2.99 | F92: 7.49 | G92: 9.49 | H92: =IF(D92="","",D92/$C92) -> 5.49 | I92: =IF(E92="","",E92/$C92) -> 2.99 | J92: =IF(F92="","",F92/$C92) -> 7.49 | K92: =IF(G92="","",G92/$C92) -> 9.49 | L92: =(H92*Assumptions!$C$11+IF(K92="",H92,K92)*Assumptions!$C$12+IF(J92="",H92,J92)*Assumptions!$C$13+IF(I92="",H92,I92)*Assumptions!$C$14)/Assumptions!$C$15 -> 5.975
A93: Malaysia | B93: MYR | C93: 4.068 | D93: 17.5 | E93: 9.5 | F93: 24.5 | G93: 27.9 | H93: =IF(D93="","",D93/$C93) -> 4.3018682 | I93: =IF(E93="","",E93/$C93) -> 2.3352999 | J93: =IF(F93="","",F93/$C93) -> 6.0226155 | K93: =IF(G93="","",G93/$C93) -> 6.8584071 | L93: =(H93*Assumptions!$C$11+IF(K93="",H93,K93)*Assumptions!$C$12+IF(J93="",H93,J93)*Assumptions!$C$13+IF(I93="",H93,I93)*Assumptions!$C$14)/Assumptions!$C$15 -> 4.5875123
A94: Saudi Arabia | B94: SAR | C94: 3.75 | D94: 31 | E94: 15 | H94: =IF(D94="","",D94/$C94) -> 8.2666667 | I94: =IF(E94="","",E94/$C94) -> 4 | J94: =IF(F94="","",F94/$C94) | K94: =IF(G94="","",G94/$C94) | L94: =(H94*Assumptions!$C$11+IF(K94="",H94,K94)*Assumptions!$C$12+IF(J94="",H94,J94)*Assumptions!$C$13+IF(I94="",H94,I94)*Assumptions!$C$14)/Assumptions!$C$15 -> 7.6266667
A95: Ghana | B95: GHS | C95: 15.2 | D95: 24 | E95: 12 | F95: 33 | G95: 43 | H95: =IF(D95="","",D95/$C95) -> 1.5789474 | I95: =IF(E95="","",E95/$C95) -> 0.78947368 | J95: =IF(F95="","",F95/$C95) -> 2.1710526 | K95: =IF(G95="","",G95/$C95) -> 2.8289474 | L95: =(H95*Assumptions!$C$11+IF(K95="",H95,K95)*Assumptions!$C$12+IF(J95="",H95,J95)*Assumptions!$C$13+IF(I95="",H95,I95)*Assumptions!$C$14)/Assumptions!$C$15 -> 1.7269737
A96: Nepal | B96: USD | C96: 1 | D96: 3.29 | E96: 1.69 | F96: 4.49 | G96: 5.79 | H96: =IF(D96="","",D96/$C96) -> 3.29 | I96: =IF(E96="","",E96/$C96) -> 1.69 | J96: =IF(F96="","",F96/$C96) -> 4.49 | K96: =IF(G96="","",G96/$C96) -> 5.79 | L96: =(H96*Assumptions!$C$11+IF(K96="",H96,K96)*Assumptions!$C$12+IF(J96="",H96,J96)*Assumptions!$C$13+IF(I96="",H96,I96)*Assumptions!$C$14)/Assumptions!$C$15 -> 3.584
...

Sheet Top 20
A1: Top 20 markets by base-case Spotify-addressable max subscribers (values live; order = base case)
A3: # | B3: Country | C3: Segment | D3: Current subs (M) | E3: Max base (M) | F3: Incremental (M) | G3: Rev TAM $M
A4: 1 | B4: United States | C4: =VLOOKUP(B4,'Country Build'!$A$5:$X$134,3,FALSE()) -> North America | D4: =VLOOKUP(B4,'Country Build'!$A$5:$X$134,13,FALSE()) -> 66.347857 | E4: =VLOOKUP(B4,'Country Build'!$A$5:$X$134,15,FALSE()) -> 68.388747 | F4: =VLOOKUP(B4,'Country Build'!$A$5:$X$134,16,FALSE()) -> 2.04089 | G4: =VLOOKUP(B4,'Country Build'!$A$5:$X$134,23,FALSE()) -> 5334.1581
A5: 2 | B5: Brazil | C5: =VLOOKUP(B5,'Country Build'!$A$5:$X$134,3,FALSE()) -> Latin America | D5: =VLOOKUP(B5,'Country Build'!$A$5:$X$134,13,FALSE()) -> 21.380021 | E5: =VLOOKUP(B5,'Country Build'!$A$5:$X$134,15,FALSE()) -> 23.201986 | F5: =VLOOKUP(B5,'Country Build'!$A$5:$X$134,16,FALSE()) -> 1.8219655 | G5: =VLOOKUP(B5,'Country Build'!$A$5:$X$134,23,FALSE()) -> 654.76342
A6: 3 | B6: India | C6: =VLOOKUP(B6,'Country Build'!$A$5:$X$134,3,FALSE()) -> Rest of World | D6: =VLOOKUP(B6,'Country Build'!$A$5:$X$134,13,FALSE()) -> 8.4074002 | E6: =VLOOKUP(B6,'Country Build'!$A$5:$X$134,15,FALSE()) -> 19.831438 | F6: =VLOOKUP(B6,'Country Build'!$A$5:$X$134,16,FALSE()) -> 11.424037 | G6: =VLOOKUP(B6,'Country Build'!$A$5:$X$134,23,FALSE()) -> 213.01066
A7: 4 | B7: Germany | C7: =VLOOKUP(B7,'Country Build'!$A$5:$X$134,3,FALSE()) -> Europe | D7: =VLOOKUP(B7,'Country Build'!$A$5:$X$134,13,FALSE()) -> 17.577897 | E7: =VLOOKUP(B7,'Country Build'!$A$5:$X$134,15,FALSE()) -> 19.447756 | F7: =VLOOKUP(B7,'Country Build'!$A$5:$X$134,16,FALSE()) -> 1.8698595 | G7: =VLOOKUP(B7,'Country Build'!$A$5:$X$134,23,FALSE()) -> 1749.9869
A8: 5 | B8: Mexico | C8: =VLOOKUP(B8,'Country Build'!$A$5:$X$134,3,FALSE()) -> Latin America | D8: =VLOOKUP(B8,'Country Build'!$A$5:$X$134,13,FALSE()) -> 16.708747 | E8: =VLOOKUP(B8,'Country Build'!$A$5:$X$134,15,FALSE()) -> 18.132635 | F8: =VLOOKUP(B8,'Country Build'!$A$5:$X$134,16,FALSE()) -> 1.4238882 | G8: =VLOOKUP(B8,'Country Build'!$A$5:$X$134,23,FALSE()) -> 877.12341
A9: 6 | B9: Indonesia | C9: =VLOOKUP(B9,'Country Build'!$A$5:$X$134,3,FALSE()) -> Rest of World | D9: =VLOOKUP(B9,'Country Build'!$A$5:$X$134,13,FALSE()) -> 3.694776 | E9: =VLOOKUP(B9,'Country Build'!$A$5:$X$134,15,FALSE()) -> 18.053049 | F9: =VLOOKUP(B9,'Country Build'!$A$5:$X$134,16,FALSE()) -> 14.358273 | G9: =VLOOKUP(B9,'Country Build'!$A$5:$X$134,23,FALSE()) -> 415.55637
A10: 7 | B10: United Kingdom | C10: =VLOOKUP(B10,'Country Build'!$A$5:$X$134,3,FALSE()) -> Europe | D10: =VLOOKUP(B10,'Country Build'!$A$5:$X$134,13,FALSE()) -> 14.364295 | E10: =VLOOKUP(B10,'Country Build'!$A$5:$X$134,15,FALSE()) -> 15.892306 | F10: =VLOOKUP(B10,'Country Build'!$A$5:$X$134,16,FALSE()) -> 1.5280106 | G10: =VLOOKUP(B10,'Country Build'!$A$5:$X$134,23,FALSE()) -> 1636.1787
A11: 8 | B11: France | C11: =VLOOKUP(B11,'Country Build'!$A$5:$X$134,3,FALSE()) -> Europe | D11: =VLOOKUP(B11,'Country Build'!$A$5:$X$134,13,FALSE()) -> 14.034854 | E11: =VLOOKUP(B11,'Country Build'!$A$5:$X$134,15,FALSE()) -> 14.116201 | F11: =VLOOKUP(B11,'Country Build'!$A$5:$X$134,16,FALSE()) -> 0.081346145 | G11: =VLOOKUP(B11,'Country Build'!$A$5:$X$134,23,FALSE()) -> 1208.0486
A12: 9 | B12: Italy | C12: =VLOOKUP(B12,'Country Build'!$A$5:$X$134,3,FALSE()) -> Europe | D12: =VLOOKUP(B12,'Country Build'!$A$5:$X$134,13,FALSE()) -> 11.549517 | E12: =VLOOKUP(B12,'Country Build'!$A$5:$X$134,15,FALSE()) -> 12.778104 | F12: =VLOOKUP(B12,'Country Build'!$A$5:$X$134,16,FALSE()) -> 1.2285869 | G12: =VLOOKUP(B12,'Country Build'!$A$5:$X$134,23,FALSE()) -> 1074.1785
A13: 10 | B13: Spain | C13: =VLOOKUP(B13,'Country Build'!$A$5:$X$134,3,FALSE()) -> Europe | D13: =VLOOKUP(B13,'Country Build'!$A$5:$X$134,13,FALSE()) -> 9.2733159 | E13: =VLOOKUP(B13,'Country Build'!$A$5:$X$134,15,FALSE()) -> 10.259771 | F13: =VLOOKUP(B13,'Country Build'!$A$5:$X$134,16,FALSE()) -> 0.98645464 | G13: =VLOOKUP(B13,'Country Build'!$A$5:$X$134,23,FALSE()) -> 862.47735
A14: 11 | B14: Turkey | C14: =VLOOKUP(B14,'Country Build'!$A$5:$X$134,3,FALSE()) -> Rest of World | D14: =VLOOKUP(B14,'Country Build'!$A$5:$X$134,13,FALSE()) -> 2.3759522 | E14: =VLOOKUP(B14,'Country Build'!$A$5:$X$134,15,FALSE()) -> 9.0070933 | F14: =VLOOKUP(B14,'Country Build'!$A$5:$X$134,16,FALSE()) -> 6.6311411 | G14: =VLOOKUP(B14,'Country Build'!$A$5:$X$134,23,FALSE()) -> 136.67796
A15: 12 | B15: Japan | C15: =VLOOKUP(B15,'Country Build'!$A$5:$X$134,3,FALSE()) -> Rest of World | D15: =VLOOKUP(B15,'Country Build'!$A$5:$X$134,13,FALSE()) -> 5.7415173 | E15: =VLOOKUP(B15,'Country Build'!$A$5:$X$134,15,FALSE()) -> 8.7063 | F15: =VLOOKUP(B15,'Country Build'!$A$5:$X$134,16,FALSE()) -> 2.9647827 | G15: =VLOOKUP(B15,'Country Build'!$A$5:$X$134,23,FALSE()) -> 352.7033
... A23: 20 | B23: Colombia | C23: =VLOOKUP(B23,'Country Build'!$A$5:$X$134,3,FALSE()) -> Latin America | D23: =VLOOKUP(B23,'Country Build'!$A$5:$X$134,13,FALSE()) -> 4.425367 | E23: =VLOOKUP(B23,'Country Build'!$A$5:$X$134,15,FALSE()) -> 4.8024885 | F23: =VLOOKUP(B23,'Country Build'!$A$5:$X$134,16,FALSE()) -> 0.37712153 | G23: =VLOOKUP(B23,'Country Build'!$A$5:$X$134,23,FALSE()) -> 128.15195

Sheet Assumptions
B2: Spotify Premium — Global Subscriber TAM | Assumptions
B4: 1. Ceiling curve ceiling% = L / (1 + e^(−k·(ln(GDPpc) − x0))) — share of ONLINE ADULTS who pay for any music service
B5: L (max penetration ceiling) | C5: 0.62
B6: k (curve steepness) | C6: 0.95
B7: x0 (ln GDP/cap midpoint; e^x0 = $) | C7: 9
B8: scenario shift (± on x0 for low/high) | C8: 0.5 | D8: =EXP(C8) -> 1.6487213 | E8: midpoint income
B10: 2. Plan mix (share of paying ACCOUNTS — used to blend ARPU)
B11: Individual | C11: 0.6
B12: Family | C12: 0.18
B13: Duo | C13: 0.07
B14: Student | C14: 0.15
B15: Sum | C15: =SUM(C11:C14) -> 1
B17: 3. ARPU realization (realized ARPU ÷ blended list; captures promos, trials, VAT) | C17: 0.46 | D17: Tunes blended list price to reported ARPU (~$5.1/mo).
B19: 4. Current Premium subs by region — control totals, FY2025 EOP (M)
B20: Europe | C20: 108 | E20: Source: Bernstein SPOT model regional mix × 290M.
B21: North America | C21: 74
B22: Latin America | C22: 67
B23: Rest of World | C23: 41
B24: Total | C24: =SUM(C20:C23) -> 290
B26: Excluded (memo): China — Spotify absent (~1.1bn online); Russia — exited 2022.

Sheet Sources & Notes
B2: Sources, Methodology & Caveats
B4: Methodology
B5: Proxy (online adults) = Population × 15+ share × Internet penetration.
B6: Ceiling% = L/(1+e^(−k(ln GDPpc − x0))) — continuous curve, share of online adults paying for ANY music service.
B7: Industry max = proxy × ceiling%. Spotify-addressable = industry × Spotify share (per country).
B8: Current subs allocated from Bernstein regional totals by (proxy × ceiling), reconciled within each region.
B9: Revenue TAM = max subs × realized ARPU × 12. Realized ARPU = blended plan list × realization factor.
B11: Data sources
B12: Pricing: user-supplied Spotify global pricing file, dated Feb-2026 (Individual/Standard/Duo/Family/Student, local currency).
B13: FX: ECB reference rates 16-Jun-2026 (42 currencies) + embedded estimates for minor currencies (override on Pricing tab).
B14: Population (2024) & GDP (→ per-capita): World Bank via datahub mirrors. Region/segment: ISO-3166. Taiwan added manually.
B15: 15+ share and internet% are estimates by sub-region / income band — editable per country (override columns).
... B24: 6. Realization factor (0.57) ties blended list price to reported ARPU; revisit if plan mix or coverage changes.
