Workbook

Sheet Exhibit
D3: Year
C4: EV/EBITDA | D4: 2026E | E4: 2027E | F4: 2028E
B5: 2026 Scenarios | C5: 2 WWE Saudi PLEs cancelled; rest runs | D5: ='2026 Scenarios'!C9 -> 19.03876 | E5: =Assumptions!B11/Assumptions!C19 -> 16.680783 | F5: =Assumptions!B11/Assumptions!D19 -> 15.35
C6: Full ME out; US/EU repl. for WWE/UFC | D6: ='2026 Scenarios'!C19 -> 19.152294 | E6: =Assumptions!B11/Assumptions!C19 -> 16.680783 | F6: =Assumptions!B11/Assumptions!D19 -> 15.35
C7: Full ME out; NO replacements | D7: ='2026 Scenarios'!C25 -> 19.519402 | E7: =Assumptions!B11/Assumptions!C19 -> 16.680783 | F7: =Assumptions!B11/Assumptions!D19 -> 15.35
D10: Year
C11: EV/EBITDA | D11: 2026E | E11: 2027E | F11: 2028E
B12: 2026 + 2027 Combined Scenarios | C12: '26: WWE PLEs | '27: No repl (incl. WM43) | D12: ='EV-EBITDA Walk'!B20 -> 19.03876 | E12: ='EV-EBITDA Walk'!C20 -> 18.208461 | F12: ='EV-EBITDA Walk'!D20 -> 15.35
C13: '26: WWE PLEs | '27: WM43→US + repl | D13: ='EV-EBITDA Walk'!B22 -> 19.03876 | E13: ='EV-EBITDA Walk'!C22 -> 17.550231 | F13: ='EV-EBITDA Walk'!D22 -> 15.35
C14: '26: Full ME repl | '27: No repl | D14: ='EV-EBITDA Walk'!B24 -> 19.152294 | E14: ='EV-EBITDA Walk'!C24 -> 18.208461 | F14: ='EV-EBITDA Walk'!D24 -> 15.35
C15: '26: Full ME repl | '27: WM43→US + repl | D15: ='EV-EBITDA Walk'!B26 -> 19.152294 | E15: ='EV-EBITDA Walk'!C26 -> 17.550231 | F15: ='EV-EBITDA Walk'!D26 -> 15.35
C16: '26: No repl | '27: No repl | D16: ='EV-EBITDA Walk'!B28 -> 19.519402 | E16: ='EV-EBITDA Walk'!C28 -> 18.208461 | F16: ='EV-EBITDA Walk'!D28 -> 15.35
C17: '26: No repl | '27: WM43→US + repl | D17: ='EV-EBITDA Walk'!B30 -> 19.519402 | E17: ='EV-EBITDA Walk'!C30 -> 17.550231 | F17: ='EV-EBITDA Walk'!D30 -> 15.35

Sheet EV-EBITDA Walk
A1: TKO — LOOK THROUGH THE NOISE: 2028E ANCHORS AT ~15x REGARDLESS
A2: EV ~$41.7B | >$15B locked media rights | ME = ~6% of EBITDA | FCF assumptions are placeholders
B4: 2026E | C4: 2027E | D4: 2028E | E4: 26 uFCF/EV | F4: 27 uFCF/EV | G4: 28 uFCF/EV | H4: 26 lFCF/Eq | I4: 27 lFCF/Eq | J4: 28 lFCF/Eq
A5: TKO Adj. EBITDA — Base Case | B5: =Assumptions!B19 -> 2281 | C5: =Assumptions!C19 -> 2503 | D5: =Assumptions!D19 -> 2720
A6: Base Case EV / EBITDA | B6: =Assumptions!B11/B5 -> 18.304253 | C6: =Assumptions!B11/C5 -> 16.680783 | D6: =Assumptions!B11/D5 -> 15.35 | E6: =(B5-Assumptions!B69)/Assumptions!B11 -> 0.05151849 | F6: =(C5-Assumptions!C69)/Assumptions!B11 -> 0.056596091 | G6: =(D5-Assumptions!D69)/Assumptions!B11 -> 0.061673692 | H6: =(B5-Assumptions!B69-Assumptions!B71-MAX(0,Assumptions!B72*(B5-Assumptions!B70-Assumptions!B71)))/Assumptions!B7 -> 0.044929897 | I6: =(C5-Assumptions!C69-Assumptions!C71-MAX(0,Assumptions!C72*(C5-Assumptions!C70-Assumptions!C71)))/Assumptions!B7 -> 0.04899433 | J6: =(D5-Assumptions!D69-Assumptions!D71-MAX(0,Assumptions!D72*(D5-Assumptions!D70-Assumptions!D71)))/Assumptions!B7 -> 0.052819588
A8: 2026 SCENARIOS
B9: 2026E | C9: 2027E | D9: 2028E | E9: 26 uFCF/EV | F9: 27 uFCF/EV | G9: 28 uFCF/EV | H9: 26 lFCF/Eq | I9: 27 lFCF/Eq | J9: 28 lFCF/Eq
A10: A) 2 WWE Saudi PLEs cancelled | B10: ='2026 Scenarios'!C8 -> 2193 | C10: =Assumptions!C19 -> 2503 | D10: =Assumptions!D19 -> 2720
A11: EV / EBITDA | B11: =Assumptions!B11/B10 -> 19.03876 | C11: =Assumptions!B11/C10 -> 16.680783 | D11: =Assumptions!B11/D10 -> 15.35 | E11: =(B10-Assumptions!B69)/Assumptions!B11 -> 0.049410807 | F11: =(C10-Assumptions!C69)/Assumptions!B11 -> 0.056596091 | G11: =(D10-Assumptions!D69)/Assumptions!B11 -> 0.061673692 | H11: =(B10-Assumptions!B69-Assumptions!B71-MAX(0,Assumptions!B72*(B10-Assumptions!B70-Assumptions!B71)))/Assumptions!B7 -> 0.042934021 | I11: =(C10-Assumptions!C69-Assumptions!C71-MAX(0,Assumptions!C72*(C10-Assumptions!C70-Assumptions!C71)))/Assumptions!B7 -> 0.04899433 | J11: =(D10-Assumptions!D69-Assumptions!D71-MAX(0,Assumptions!D72*(D10-Assumptions!D70-Assumptions!D71)))/Assumptions!B7 -> 0.052819588
A12: B) Full ME out, with replacements | B12: ='2026 Scenarios'!C18 -> 2180 | C12: =Assumptions!C19 -> 2503 | D12: =Assumptions!D19 -> 2720
A13: EV / EBITDA | B13: =Assumptions!B11/B12 -> 19.152294 | C13: =Assumptions!B11/C12 -> 16.680783 | D13: =Assumptions!B11/D12 -> 15.35 | E13: =(B12-Assumptions!B69)/Assumptions!B11 -> 0.049099444 | F13: =(C12-Assumptions!C69)/Assumptions!B11 -> 0.056596091 | G13: =(D12-Assumptions!D69)/Assumptions!B11 -> 0.061673692 | H13: =(B12-Assumptions!B69-Assumptions!B71-MAX(0,Assumptions!B72*(B12-Assumptions!B70-Assumptions!B71)))/Assumptions!B7 -> 0.042639175 | I13: =(C12-Assumptions!C69-Assumptions!C71-MAX(0,Assumptions!C72*(C12-Assumptions!C70-Assumptions!C71)))/Assumptions!B7 -> 0.04899433 | J13: =(D12-Assumptions!D69-Assumptions!D71-MAX(0,Assumptions!D72*(D12-Assumptions!D70-Assumptions!D71)))/Assumptions!B7 -> 0.052819588
A14: C) Full ME out, NO replacements | B14: ='2026 Scenarios'!C24 -> 2139 | C14: =Assumptions!C19 -> 2503 | D14: =Assumptions!D19 -> 2720
A15: EV / EBITDA | B15: =Assumptions!B11/B14 -> 19.519402 | C15: =Assumptions!B11/C14 -> 16.680783 | D15: =Assumptions!B11/D14 -> 15.35 | E15: =(B14-Assumptions!B69)/Assumptions!B11 -> 0.048117455 | F15: =(C14-Assumptions!C69)/Assumptions!B11 -> 0.056596091 | G15: =(D14-Assumptions!D69)/Assumptions!B11 -> 0.061673692 | H15: =(B14-Assumptions!B69-Assumptions!B71-MAX(0,Assumptions!B72*(B14-Assumptions!B70-Assumptions!B71)))/Assumptions!B7 -> 0.041709278 | I15: =(C14-Assumptions!C69-Assumptions!C71-MAX(0,Assumptions!C72*(C14-Assumptions!C70-Assumptions!C71)))/Assumptions!B7 -> 0.04899433 | J15: =(D14-Assumptions!D69-Assumptions!D71-MAX(0,Assumptions!D72*(D14-Assumptions!D70-Assumptions!D71)))/Assumptions!B7 -> 0.052819588
A17: 2026 + 2027 COMBINED SCENARIOS (Conflict Persists)
B18: 2026E | C18: 2027E | D18: 2028E | E18: 26 uFCF/EV | F18: 27 uFCF/EV | G18: 28 uFCF/EV | H18: 26 lFCF/Eq | I18: 27 lFCF/Eq | J18: 28 lFCF/Eq
A19: A+D) '26: WWE PLEs | '27: No repl (incl WM43) | B19: ='2026 Scenarios'!C8 -> 2193 | C19: ='2027 Scenarios'!C8 -> 2293 | D19: =Assumptions!D19 -> 2720
A20: EV / EBITDA | B20: =Assumptions!B11/B19 -> 19.03876 | C20: =Assumptions!B11/C19 -> 18.208461 | D20: =Assumptions!B11/D19 -> 15.35 | E20: =(B19-Assumptions!B69)/Assumptions!B11 -> 0.049410807 | F20: =(C19-Assumptions!C69)/Assumptions!B11 -> 0.051566392 | G20: =(D19-Assumptions!D69)/Assumptions!B11 -> 0.061673692 | H20: =(B19-Assumptions!B69-Assumptions!B71-MAX(0,Assumptions!B72*(B19-Assumptions!B70-Assumptions!B71)))/Assumptions!B7 -> 0.042934021 | I20: =(C19-Assumptions!C69-Assumptions!C71-MAX(0,Assumptions!C72*(C19-Assumptions!C70-Assumptions!C71)))/Assumptions!B7 -> 0.044339691 | J20: =(D19-Assumptions!D69-Assumptions!D71-MAX(0,Assumptions!D72*(D19-Assumptions!D70-Assumptions!D71)))/Assumptions!B7 -> 0.052819588
A21: A+E) '26: WWE PLEs | '27: WM43→US + repl | B21: ='2026 Scenarios'!C8 -> 2193 | C21: ='2027 Scenarios'!C16 -> 2379 | D21: =Assumptions!D19 -> 2720
A22: EV / EBITDA | B22: =Assumptions!B11/B21 -> 19.03876 | C22: =Assumptions!B11/C21 -> 17.550231 | D22: =Assumptions!B11/D21 -> 15.35 | E22: =(B21-Assumptions!B69)/Assumptions!B11 -> 0.049410807 | F22: =(C21-Assumptions!C69)/Assumptions!B11 -> 0.053626174 | G22: =(D21-Assumptions!D69)/Assumptions!B11 -> 0.061673692 | H22: =(B21-Assumptions!B69-Assumptions!B71-MAX(0,Assumptions!B72*(B21-Assumptions!B70-Assumptions!B71)))/Assumptions!B7 -> 0.042934021 | I22: =(C21-Assumptions!C69-Assumptions!C71-MAX(0,Assumptions!C72*(C21-Assumptions!C70-Assumptions!C71)))/Assumptions!B7 -> 0.046245876 | J22: =(D21-Assumptions!D69-Assumptions!D71-MAX(0,Assumptions!D72*(D21-Assumptions!D70-Assumptions!D71)))/Assumptions!B7 -> 0.052819588
A23: B+D) '26: Full ME repl | '27: No repl | B23: ='2026 Scenarios'!C18 -> 2180 | C23: ='2027 Scenarios'!C8 -> 2293 | D23: =Assumptions!D19 -> 2720
A24: EV / EBITDA | B24: =Assumptions!B11/B23 -> 19.152294 | C24: =Assumptions!B11/C23 -> 18.208461 | D24: =Assumptions!B11/D23 -> 15.35 | E24: =(B23-Assumptions!B69)/Assumptions!B11 -> 0.049099444 | F24: =(C23-Assumptions!C69)/Assumptions!B11 -> 0.051566392 | G24: =(D23-Assumptions!D69)/Assumptions!B11 -> 0.061673692 | H24: =(B23-Assumptions!B69-Assumptions!B71-MAX(0,Assumptions!B72*(B23-Assumptions!B70-Assumptions!B71)))/Assumptions!B7 -> 0.042639175 | I24: =(C23-Assumptions!C69-Assumptions!C71-MAX(0,Assumptions!C72*(C23-Assumptions!C70-Assumptions!C71)))/Assumptions!B7 -> 0.044339691 | J24: =(D23-Assumptions!D69-Assumptions!D71-MAX(0,Assumptions!D72*(D23-Assumptions!D70-Assumptions!D71)))/Assumptions!B7 -> 0.052819588
A25: B+E) '26: Full ME repl | '27: WM43→US + repl | B25: ='2026 Scenarios'!C18 -> 2180 | C25: ='2027 Scenarios'!C16 -> 2379 | D25: =Assumptions!D19 -> 2720
A26: EV / EBITDA | B26: =Assumptions!B11/B25 -> 19.152294 | C26: =Assumptions!B11/C25 -> 17.550231 | D26: =Assumptions!B11/D25 -> 15.35 | E26: =(B25-Assumptions!B69)/Assumptions!B11 -> 0.049099444 | F26: =(C25-Assumptions!C69)/Assumptions!B11 -> 0.053626174 | G26: =(D25-Assumptions!D69)/Assumptions!B11 -> 0.061673692 | H26: =(B25-Assumptions!B69-Assumptions!B71-MAX(0,Assumptions!B72*(B25-Assumptions!B70-Assumptions!B71)))/Assumptions!B7 -> 0.042639175 | I26: =(C25-Assumptions!C69-Assumptions!C71-MAX(0,Assumptions!C72*(C25-Assumptions!C70-Assumptions!C71)))/Assumptions!B7 -> 0.046245876 | J26: =(D25-Assumptions!D69-Assumptions!D71-MAX(0,Assumptions!D72*(D25-Assumptions!D70-Assumptions!D71)))/Assumptions!B7 -> 0.052819588
A27: C+D) WORST: No repl either year | B27: ='2026 Scenarios'!C24 -> 2139 | C27: ='2027 Scenarios'!C8 -> 2293 | D27: =Assumptions!D19 -> 2720
A28: EV / EBITDA | B28: =Assumptions!B11/B27 -> 19.519402 | C28: =Assumptions!B11/C27 -> 18.208461 | D28: =Assumptions!B11/D27 -> 15.35 | E28: =(B27-Assumptions!B69)/Assumptions!B11 -> 0.048117455 | F28: =(C27-Assumptions!C69)/Assumptions!B11 -> 0.051566392 | G28: =(D27-Assumptions!D69)/Assumptions!B11 -> 0.061673692 | H28: =(B27-Assumptions!B69-Assumptions!B71-MAX(0,Assumptions!B72*(B27-Assumptions!B70-Assumptions!B71)))/Assumptions!B7 -> 0.041709278 | I28: =(C27-Assumptions!C69-Assumptions!C71-MAX(0,Assumptions!C72*(C27-Assumptions!C70-Assumptions!C71)))/Assumptions!B7 -> 0.044339691 | J28: =(D27-Assumptions!D69-Assumptions!D71-MAX(0,Assumptions!D72*(D27-Assumptions!D70-Assumptions!D71)))/Assumptions!B7 -> 0.052819588
A29: C+E) '26: No repl | '27: WM43→US + repl | B29: ='2026 Scenarios'!C24 -> 2139 | C29: ='2027 Scenarios'!C16 -> 2379 | D29: =Assumptions!D19 -> 2720
A30: EV / EBITDA | B30: =Assumptions!B11/B29 -> 19.519402 | C30: =Assumptions!B11/C29 -> 17.550231 | D30: =Assumptions!B11/D29 -> 15.35 | E30: =(B29-Assumptions!B69)/Assumptions!B11 -> 0.048117455 | F30: =(C29-Assumptions!C69)/Assumptions!B11 -> 0.053626174 | G30: =(D29-Assumptions!D69)/Assumptions!B11 -> 0.061673692 | H30: =(B29-Assumptions!B69-Assumptions!B71-MAX(0,Assumptions!B72*(B29-Assumptions!B70-Assumptions!B71)))/Assumptions!B7 -> 0.041709278 | I30: =(C29-Assumptions!C69-Assumptions!C71-MAX(0,Assumptions!C72*(C29-Assumptions!C70-Assumptions!C71)))/Assumptions!B7 -> 0.046245876 | J30: =(D29-Assumptions!D69-Assumptions!D71-MAX(0,Assumptions!D72*(D29-Assumptions!D70-Assumptions!D71)))/Assumptions!B7 -> 0.052819588
A32: THE LOOK-THROUGH: 2028E MULTIPLE IS ~15x IN EVERY SCENARIO
A33: 2028E unaffected — all scenarios revert to full calendar. >$15B locked media rights provide floor.
A35: Implied Share Price at Target 2028E EV/EBITDA | B35: Multiple | C35: Implied EV ($M) | D35: Implied Equity ($M) | E35: Implied $/sh | F35: % vs Current | G35: uFCF/EV
A36: Current (spot) | B36: =Assumptions!B11/Assumptions!D19 -> 15.35 | C36: =B36*Assumptions!D19 -> 41752 | D36: =C36-Assumptions!B10 -> 38800 | E36: =D36/Assumptions!B6 -> 200 | F36: =(E36/Assumptions!B5)-1 -> 0 | G36: =(Assumptions!D19-Assumptions!D69)/C36 -> 0.061673692
A37: 13.0x | B37: 13 | C37: =B37*Assumptions!D19 -> 35360 | D37: =C37-Assumptions!B10 -> 32408 | E37: =D37/Assumptions!B6 -> 167.05155 | F37: =(E37/Assumptions!B5)-1 -> -0.16474227 | G37: =(Assumptions!D19-Assumptions!D69)/C37 -> 0.072822398
A38: 15.0x | B38: 15 | C38: =B38*Assumptions!D19 -> 40800 | D38: =C38-Assumptions!B10 -> 37848 | E38: =D38/Assumptions!B6 -> 195.09278 | F38: =(E38/Assumptions!B5)-1 -> -0.024536082 | G38: =(Assumptions!D19-Assumptions!D69)/C38 -> 0.063112745
A39: 17.0x | B39: 17 | C39: =B39*Assumptions!D19 -> 46240 | D39: =C39-Assumptions!B10 -> 43288 | E39: =D39/Assumptions!B6 -> 223.13402 | F39: =(E39/Assumptions!B5)-1 -> 0.1156701 | G39: =(Assumptions!D19-Assumptions!D69)/C39 -> 0.055687716
A40: 19.0x | B40: 19 | C40: =B40*Assumptions!D19 -> 51680 | D40: =C40-Assumptions!B10 -> 48728 | E40: =D40/Assumptions!B6 -> 251.17526 | F40: =(E40/Assumptions!B5)-1 -> 0.25587629 | G40: =(Assumptions!D19-Assumptions!D69)/C40 -> 0.049825851
A41: 21.0x (premium peers) | B41: 21 | C41: =B41*Assumptions!D19 -> 57120 | D41: =C41-Assumptions!B10 -> 54168 | E41: =D41/Assumptions!B6 -> 279.21649 | F41: =(E41/Assumptions!B5)-1 -> 0.39608247 | G41: =(Assumptions!D19-Assumptions!D69)/C41 -> 0.045080532
A43: BERNSTEIN BOTTOM LINE
A44: • ME exposure is ~6-7% of TKO EBITDA — meaningful but NOT existential (vs ~20%+ for FWONK).
A45: • Media rights ($7.7B UFC/Paramount + $1.6B WWE/ESPN + Netflix) are 100% geography-agnostic.
A46: • Even worst case (C+D: no repl, 2 years), 2028E still lands at ~15.3x with 6.2% uFCF/EV yield.
...

Sheet Assumptions
A1: TKO GROUP HOLDINGS (TKO) — ME Disruption Model: Assumptions
A2: Anchored to TKO FY2026 guidance ($2.24-2.29B Adj. EBITDA) and Bernstein estimates
A4: TKO Market Data | B4: Value | G4: Source / Note
A5: Stock Price ($/sh) | B5: 200 | G5: CNBC 3/16/2026
A6: Total Economic Shares (M) | B6: 194 | G6: TKO 10-K 2/25/2026; incl. all OpCo units
A7: Market Cap ($M) | B7: =B5*B6 -> 38800
A8: Gross Debt ($M) | B8: 3783 | G8: TKO 10-K 2025 YE
A9: Cash & Equivalents ($M) | B9: 831 | G9: TKO 10-K 2025 YE
A10: Net Debt ($M) | B10: =B8-B9 -> 2952
A11: Enterprise Value ($M) | B11: =B7+B10 -> 41752
A13: TKO Consolidated Adj. EBITDA ($M) | B13: 2026E | C13: 2027E | D13: 2028E | G13: Note
A14: UFC | B14: 1108 | C14: 1120 | D14: 1250 | G14: Paramount $1.1B AAV kicks in 2026; ~55% margin
A15: WWE | B15: 908 | C15: 1035 | D15: 1050 | G15: Full yr Netflix + ESPN PLEs; margin →45%
A16: IMG / On Location / PBR | B16: 350 | C16: 410 | D16: 470 | G16: 2026 = WC (On Loc); 2027 = trough; 2028 = Olympics
A17: Zuffa Boxing | B17: 25 | C17: 50 | D17: 55 | G17: Early-stage; Saudi partnership
A18: Corporate & Other | B18: -110 | C18: -112 | D18: -105 | G18: SGA, public co costs; thin overlay
A19: Total TKO Adj. EBITDA (Base Case) | B19: =SUM(B14:B18) -> 2281 | C19: =SUM(C14:C18) -> 2503 | D19: =SUM(D14:D18) -> 2720
A20: Check vs. Guidance Midpoint ($2,265M) | B20: =B19-2265 -> 16
A22: 2026 ME Event Inventory | B22: Revenue ($M) | C22: Prod. Cost ($M) | D22: Net EBITDA ($M) | E22: Status | G22: Note
A23: WWE: Royal Rumble (Jan 31, Riyadh) | B23: 60 | C23: 12 | D23: =B23-C23 -> 48 | E23: ✅ Completed | G23: Pre-conflict; already in Q1 actuals
A24: WWE: Night of Champions (~Jun, Saudi) | B24: 55 | C24: 11 | D24: =B24-C24 -> 44 | E24: ⚠️ At Risk | G24: Standard Saudi PLE; $55M site fee
A25: WWE: Nov Saudi PLE (TBD) | B25: 55 | C25: 11 | D25: =B25-C25 -> 44 | E25: ⚠️ At Risk | G25: Standard Saudi PLE
A26: UFC: Saudi Arabia event | B26: 30 | C26: 10 | D26: =B26-C26 -> 20 | E26: ⚠️ At Risk | G26: Site fee + live events
A27: UFC: Abu Dhabi (~Dec) | B27: 22 | C27: 8 | D27: =B27-C27 -> 14 | E27: ⚠️ At Risk | G27: Traditional Fight Island venue
A28: UFC: Qatar (if scheduled) | B28: 12 | C28: 5 | D28: =B28-C28 -> 7 | E28: ⚠️ At Risk | G28: Smaller; may not be on 2026 calendar
A29: Zuffa Boxing: Saudi-funded cards | B29: 22 | C29: 9 | D29: =B29-C29 -> 13 | E29: ⚠️ At Risk | G29: Sela/Turki partnership; excl. US super fights
A30: Total ME Revenue (all, incl. completed) | B30: =SUM(B23:B29) -> 256 | D30: =SUM(D23:D29) -> 190
A31: Total AT-RISK ME EBITDA (excl. Royal Rumble) | B31: =SUM(B24:B29) -> 196 | D31: =SUM(D24:D29) -> 142
A32: % of 2026E Consolidated EBITDA | D32: =D31/B19 -> 0.062253398
A33: WWE Saudi PLEs only (2 events) | D33: =D24+D25 -> 88
A34: UFC ME Events (Saudi + Abu Dhabi + Qatar) | D34: =D26+D27+D28 -> 41
A35: Zuffa Boxing ME | D35: =D29 -> 13
A37: Revenue Retention on Cancellation (No Repl) | B37: % Lost | C37: % Retained | G37: Rationale
A38: Site Fees / FIPs | B38: 1 | C38: =1-B38 -> 0 | G38: Government pays for event in their country. No event = no fee.
A39: Media Rights | B39: 0 | C39: =1-B39 -> 1 | G39: Netflix/Paramount/ESPN annual contracts. ZERO geography dependence.
A40: Sponsorship | B40: 0.05 | C40: =1-B40 -> 0.95 | G40: TKO partnerships annual (Monster, Meta). Tiny per-event activation.
A41: Live Events (tickets, merch at venue) | B41: 1 | C41: =1-B41 -> 0 | G41: No event = no tickets/venue merch.
A42: Consumer Products | B42: 0 | C42: =1-B42 -> 1 | G42: Completely geography-independent.
A43: Key: TKO site fees ARE the revenue. Media rights (biggest P&L line) are unaffected.
A45: Replacement Economics (Relocate to US/EU) | B45: Value | G45: Note
...

Sheet 2026 Scenarios
A1: TKO — 2026 ME Disruption Scenarios
A2: Royal Rumble already completed. Remaining 2 WWE Saudi PLEs + UFC + Zuffa Boxing at risk.
A4: SCENARIO A: 2 WWE Saudi PLEs Cancelled Only | C4: EBITDA Hit ($M)
A5: 2 WWE Saudi PLEs cancelled (no replacement) | C5: =Assumptions!D33 -> 88
A6: UFC / Zuffa Boxing → assumed to run | C6: 0
A7: Total 2026 EBITDA Haircut — Scenario A | C7: =C5+C6 -> 88
A8: Adjusted TKO 2026E EBITDA | C8: =Assumptions!B19-C7 -> 2193
A9: EV / Adjusted EBITDA | C9: =Assumptions!B11/C8 -> 19.03876
A11: SCENARIO B: Full ME Out — With US/EU Replacements | C11: EBITDA Hit ($M)
A12: 2 WWE Saudi PLEs: gross EBITDA loss | C12: =Assumptions!D33 -> 88
A13: Less: WWE PLE replacement recovery (2 events) | C13: =-Assumptions!B48*2 -> -26
A14: UFC ME events: gross EBITDA loss | C14: =Assumptions!D34 -> 41
A15: Less: UFC replacement recovery (~3 events) | C15: =-Assumptions!B49*3 -> -15
A16: Zuffa Boxing ME: gross EBITDA loss | C16: =Assumptions!D35 -> 13
A17: Total 2026 EBITDA Haircut — Scenario B | C17: =SUM(C12:C16) -> 101
A18: Adjusted TKO 2026E EBITDA | C18: =Assumptions!B19-C17 -> 2180
A19: EV / Adjusted EBITDA | C19: =Assumptions!B11/C18 -> 19.152294
A21: SCENARIO C: Full ME Out — NO Replacements | C21: EBITDA Hit ($M)
A22: All at-risk ME events cancelled, no replacement | C22: =Assumptions!D31 -> 142
A23: Total 2026 EBITDA Haircut — Scenario C | C23: =C22 -> 142
A24: Adjusted TKO 2026E EBITDA | C24: =Assumptions!B19-C23 -> 2139
A25: EV / Adjusted EBITDA | C25: =Assumptions!B11/C24 -> 19.519402

Sheet 2027 Scenarios
A1: TKO — 2027 ME Disruption Scenarios (incl. WrestleMania 43)
A2: WM43 in Riyadh is the marquee incremental risk. Modeled separately from standard ME events.
A4: SCENARIO D: Full 2027 ME Out — NO Replacements (incl. WM43) | C4: EBITDA Hit ($M)
A5: WrestleMania 43 (Riyadh) — cancelled | C5: =Assumptions!B58 -> 68
A6: Other ME events (2 WWE PLEs + UFC + Zuffa) | C6: =Assumptions!B65 -> 142
A7: Total 2027 EBITDA Haircut — Scenario D | C7: =C5+C6 -> 210
A8: Adjusted TKO 2027E EBITDA | C8: =Assumptions!C19-C7 -> 2293
A9: EV / Adjusted EBITDA | C9: =Assumptions!B11/C8 -> 18.208461
A11: SCENARIO E: Full 2027 ME Out — WM43 to US + Replacements | C11: EBITDA Hit ($M)
A12: WM43 relocated to US (net of recovery) | C12: =Assumptions!B59 -> 28
A13: Other ME: gross loss | C13: =Assumptions!B65 -> 142
A14: Less: Other ME replacement recovery | C14: =-Assumptions!B66 -> -46
A15: Total 2027 EBITDA Haircut — Scenario E | C15: =C12+C13+C14 -> 124
A16: Adjusted TKO 2027E EBITDA | C16: =Assumptions!C19-C15 -> 2379
A17: EV / Adjusted EBITDA | C17: =Assumptions!B11/C16 -> 17.550231

Sheet Implied Price
A1: TKO — IMPLIED SHARE PRICE: PRE-CONFLICT MULTIPLE × DISRUPTED EBITDA
A2: What would TKO be worth if the market re-rates to pre-conflict multiples on each scenario EBITDA?
A4: Inputs (linkable to model) | B4: 2026E | C4: 2027E | F4: Note
A5: Pre-Conflict EV/EBITDA (Feb 26) | B5: 20.5 | F5: TKO spot EV/EBITDA on 2/26/2026, pre-conflict
A6: Net Debt ($M) | B6: 3160 | C6: 3406 | F6: Link from financial model
A7: Diluted Share Count (M) | B7: 193 | C7: 191
A8: Current Stock Price ($/sh) | B8: =Assumptions!B5 -> 200
A10: 2026E Scenarios | B10: Adj. EBITDA | C10: Implied EV | D10: Impl. Equity | E10: Impl. $/sh | F10: % vs Current
A11: Base Case (no disruption) | B11: =Assumptions!B19 -> 2281 | C11: =$B$5*B11 -> 46760.5 | D11: =C11-$B$6 -> 43600.5 | E11: =D11/$B$7 -> 225.90933 | F11: =(E11/$B$8)-1 -> 0.12954663
A12: A) 2 WWE Saudi PLEs cancelled; rest runs | B12: ='2026 Scenarios'!C8 -> 2193 | C12: =$B$5*B12 -> 44956.5 | D12: =C12-$B$6 -> 41796.5 | E12: =D12/$B$7 -> 216.56218 | F12: =(E12/$B$8)-1 -> 0.082810881
A13: B) Full ME out; US/EU repl for WWE/UFC | B13: ='2026 Scenarios'!C18 -> 2180 | C13: =$B$5*B13 -> 44690 | D13: =C13-$B$6 -> 41530 | E13: =D13/$B$7 -> 215.18135 | F13: =(E13/$B$8)-1 -> 0.075906736
A14: C) Full ME out; NO replacements | B14: ='2026 Scenarios'!C24 -> 2139 | C14: =$B$5*B14 -> 43849.5 | D14: =C14-$B$6 -> 40689.5 | E14: =D14/$B$7 -> 210.82642 | F14: =(E14/$B$8)-1 -> 0.054132124
A16: 2027E Scenarios | B16: Adj. EBITDA | C16: Implied EV | D16: Impl. Equity | E16: Impl. $/sh | F16: % vs Current
A17: Base Case (no disruption) | B17: =Assumptions!C19 -> 2503 | C17: =$B$5*B17 -> 51311.5 | D17: =C17-$C$6 -> 47905.5 | E17: =D17/$C$7 -> 250.81414 | F17: =(E17/$B$8)-1 -> 0.25407068
A18: D) Full ME out incl. WM43; NO replacements | B18: ='2027 Scenarios'!C8 -> 2293 | C18: =$B$5*B18 -> 47006.5 | D18: =C18-$C$6 -> 43600.5 | E18: =D18/$C$7 -> 228.27487 | F18: =(E18/$B$8)-1 -> 0.14137435
A19: E) Full ME out; WM43→US + replacements | B19: ='2027 Scenarios'!C16 -> 2379 | C19: =$B$5*B19 -> 48769.5 | D19: =C19-$C$6 -> 45363.5 | E19: =D19/$C$7 -> 237.50524 | F19: =(E19/$B$8)-1 -> 0.18752618
A21: KEY TAKEAWAY
A22: At the pre-conflict 20.5x multiple, even the worst-case EBITDA implies a price well above current levels.
A23: ME exposure is only ~6% of TKO EBITDA — the stock is over-discounting a risk that barely moves the needle.
A25: Notes:
A26: 1. Pre-conflict multiple of 20.5x is TKO EV/EBITDA on Feb 26, 2026 (day of Q4 earnings release).
A27: 2. Net Debt and Share Count are linkable (yellow cells) — connect to financial model for dynamic updates.
A28: 3. Formula: Pre-Conflict EV/EBITDA x Scenario EBITDA = Implied EV. Implied EV - Net Debt = Implied Equity. Equity / Shares = $/sh.

Sheet Bridge
A1: TKO — REVENUE & EBITDA BRIDGE UNDER ME DISRUPTION SCENARIOS
A2: Event-level waterfall from base estimates to scenario-adjusted numbers
A4: Inputs (linkable) | B4: 2026E | C4: 2027E
A5: TKO Revenue ($M) | B5: 5773 | C5: 5890
A6: TKO Adj. EBITDA ($M) | B6: 2281 | C6: 2503
A8: 2026 At-Risk Event Economics | B8: Revenue | C8: Prod. Cost | D8: EBITDA | E8: Repl. Recovery
A9: WWE: Night of Champions (Saudi) | B9: 55 | C9: 11 | D9: =B9-C9 -> 44 | E9: 13
A10: WWE: Nov Saudi PLE | B10: 55 | C10: 11 | D10: =B10-C10 -> 44 | E10: 13
A11: UFC: Saudi Arabia | B11: 30 | C11: 10 | D11: =B11-C11 -> 20 | E11: 5
A12: UFC: Abu Dhabi | B12: 22 | C12: 8 | D12: =B12-C12 -> 14 | E12: 5
A13: UFC: Qatar | B13: 12 | C13: 5 | D13: =B13-C13 -> 7 | E13: 5
A14: Zuffa Boxing: Saudi cards | B14: 22 | C14: 9 | D14: =B14-C14 -> 13 | E14: 0
A15: Total 2026 At-Risk | B15: =SUM(B9:B14) -> 196 | C15: =SUM(C9:C14) -> 54 | D15: =SUM(D9:D14) -> 142 | E15: =SUM(E9:E14) -> 41
A16: WWE PLEs only (2 events) | B16: =B9+B10 -> 110 | D16: =D9+D10 -> 88 | E16: =E9+E10 -> 26
A17: UFC + Zuffa (4 events) | B17: =B11+B12+B13+B14 -> 86 | D17: =D11+D12+D13+D14 -> 54 | E17: =E11+E12+E13+E14 -> 15
A19: 2027 Incremental: WrestleMania 43 (Riyadh) | B19: Revenue | C19: Prod. Cost | D19: EBITDA | E19: US Reloc. Recovery
A20: WrestleMania 43 | B20: 90 | C20: 22 | D20: =B20-C20 -> 68 | E20: 40 | F20: $10M US site fee + $30M domestic gate
A22: 2026E REVENUE & EBITDA BRIDGE
B23: Base | C23: Uber-Bull | D23: Bull | E23: Bear | F23: Worst Case
C24: 2 WWE PLEs only | D24: Full ME, US repl | E24: Full ME, no repl | F24: Bear (2026)
A25: REVENUE
A26: Base TKO Revenue | B26: =B5 -> 5773 | C26: =B5 -> 5773 | D26: =B5 -> 5773 | E26: =B5 -> 5773 | F26: =B5 -> 5773
A27: Less: ME Event Revenue Lost | B27: 0 | C27: =-B16 -> -110 | D27: =-B15 -> -196 | E27: =-B15 -> -196 | F27: =E27 -> -196
A28: Plus: Replacement Revenue Recovery | B28: 0 | C28: 0 | D28: =E16+E17 -> 41 | E28: 0 | F28: =E28 -> 0
A29: Net Revenue Adjustment | B29: =B27+B28 -> 0 | C29: =C27+C28 -> -110 | D29: =D27+D28 -> -155 | E29: =E27+E28 -> -196 | F29: =F27+F28 -> -196
A30: Adjusted TKO Revenue | B30: =B26+B29 -> 5773 | C30: =C26+C29 -> 5663 | D30: =D26+D29 -> 5618 | E30: =E26+E29 -> 5577 | F30: =F26+F29 -> 5577
A32: EBITDA
A33: Base TKO Adj. EBITDA | B33: =B6 -> 2281 | C33: =B6 -> 2281 | D33: =B6 -> 2281 | E33: =B6 -> 2281 | F33: =B6 -> 2281
A34: Less: ME Event EBITDA Lost | B34: 0 | C34: =-D16 -> -88 | D34: =-D15 -> -142 | E34: =-D15 -> -142 | F34: =E34 -> -142
A35: Plus: Replacement EBITDA Recovery | B35: 0 | C35: 0 | D35: =E15 -> 41 | E35: 0 | F35: =E35 -> 0
A36: Net EBITDA Adjustment | B36: =B34+B35 -> 0 | C36: =C34+C35 -> -88 | D36: =D34+D35 -> -101 | E36: =E34+E35 -> -142 | F36: =F34+F35 -> -142
A37: Adjusted TKO EBITDA | B37: =B33+B36 -> 2281 | C37: =C33+C36 -> 2193 | D37: =D33+D36 -> 2180 | E37: =E33+E36 -> 2139 | F37: =F33+F36 -> 2139
A38: EV / EBITDA | B38: =Assumptions!B11/B37 -> 18.304253 | C38: =Assumptions!B11/C37 -> 19.03876 | D38: =Assumptions!B11/D37 -> 19.152294 | E38: =Assumptions!B11/E37 -> 19.519402 | F38: =Assumptions!B11/F37 -> 19.519402
A40: 2027E REVENUE & EBITDA BRIDGE
B41: Base | C41: Uber-Bull | D41: Bull | E41: Bear | F41: Worst Case
C42: 2027 normal | D42: 2027 normal | E42: 2027 normal | F42: Full ME + WM43, no repl
A43: REVENUE
A44: Base TKO Revenue | B44: =C5 -> 5890 | C44: =C5 -> 5890 | D44: =C5 -> 5890 | E44: =C5 -> 5890 | F44: =C5 -> 5890
A45: Less: ME Event Revenue Lost | B45: 0 | C45: 0 | D45: 0 | E45: 0 | F45: =-(B15+B20) -> -286
A46: Plus: Replacement Revenue Recovery | B46: 0 | C46: 0 | D46: 0 | E46: 0 | F46: 0
...

Sheet Exhibit - Bridge
C3: Scenario
B4: 2026E ($M) | C4: Base | D4: Uber-Bull | E4: Bull | F4: Bear | G4: Worst Case
C5: No disruption | D5: 2 WWE PLEs only | E5: Full ME, US repl | F5: Full ME, no repl | G5: Bear (2026)
B6: TKO Revenue | C6: =Bridge!B26 -> 5773 | D6: =Bridge!C26 -> 5773 | E6: =Bridge!D26 -> 5773 | F6: =Bridge!E26 -> 5773 | G6: =Bridge!F26 -> 5773
B7: Revenue Adjustment | C7: =Bridge!B29 -> 0 | D7: =Bridge!C29 -> -110 | E7: =Bridge!D29 -> -155 | F7: =Bridge!E29 -> -196 | G7: =Bridge!F29 -> -196
B8: Adjusted TKO Revenue | C8: =Bridge!B30 -> 5773 | D8: =Bridge!C30 -> 5663 | E8: =Bridge!D30 -> 5618 | F8: =Bridge!E30 -> 5577 | G8: =Bridge!F30 -> 5577
B10: TKO Adj. EBITDA | C10: =Bridge!B33 -> 2281 | D10: =Bridge!C33 -> 2281 | E10: =Bridge!D33 -> 2281 | F10: =Bridge!E33 -> 2281 | G10: =Bridge!F33 -> 2281
B11: EBITDA Adjustment | C11: =Bridge!B36 -> 0 | D11: =Bridge!C36 -> -88 | E11: =Bridge!D36 -> -101 | F11: =Bridge!E36 -> -142 | G11: =Bridge!F36 -> -142
B12: Adjusted TKO EBITDA | C12: =Bridge!B37 -> 2281 | D12: =Bridge!C37 -> 2193 | E12: =Bridge!D37 -> 2180 | F12: =Bridge!E37 -> 2139 | G12: =Bridge!F37 -> 2139
B13: EV / EBITDA | C13: =Bridge!B38 -> 18.304253 | D13: =Bridge!C38 -> 19.03876 | E13: =Bridge!D38 -> 19.152294 | F13: =Bridge!E38 -> 19.519402 | G13: =Bridge!F38 -> 19.519402
C16: Scenario
B17: 2027E ($M) | C17: Base | D17: Uber-Bull | E17: Bull | F17: Bear | G17: Worst Case
C18: No disruption | D18: 2027 normal | E18: 2027 normal | F18: 2027 normal | G18: Full ME + WM43
B19: TKO Revenue | C19: =Bridge!B44 -> 5890 | D19: =Bridge!C44 -> 5890 | E19: =Bridge!D44 -> 5890 | F19: =Bridge!E44 -> 5890 | G19: =Bridge!F44 -> 5890
B20: Revenue Adjustment | C20: =Bridge!B47 -> 0 | D20: =Bridge!C47 -> 0 | E20: =Bridge!D47 -> 0 | F20: =Bridge!E47 -> 0 | G20: =Bridge!F47 -> -286
B21: Adjusted TKO Revenue | C21: =Bridge!B48 -> 5890 | D21: =Bridge!C48 -> 5890 | E21: =Bridge!D48 -> 5890 | F21: =Bridge!E48 -> 5890 | G21: =Bridge!F48 -> 5604
B23: TKO Adj. EBITDA | C23: =Bridge!B51 -> 2503 | D23: =Bridge!C51 -> 2503 | E23: =Bridge!D51 -> 2503 | F23: =Bridge!E51 -> 2503 | G23: =Bridge!F51 -> 2503
B24: EBITDA Adjustment | C24: =Bridge!B54 -> 0 | D24: =Bridge!C54 -> 0 | E24: =Bridge!D54 -> 0 | F24: =Bridge!E54 -> 0 | G24: =Bridge!F54 -> -210
B25: Adjusted TKO EBITDA | C25: =Bridge!B55 -> 2503 | D25: =Bridge!C55 -> 2503 | E25: =Bridge!D55 -> 2503 | F25: =Bridge!E55 -> 2503 | G25: =Bridge!F55 -> 2293
B26: EV / EBITDA | C26: =Bridge!B56 -> 16.680783 | D26: =Bridge!C56 -> 16.680783 | E26: =Bridge!D56 -> 16.680783 | F26: =Bridge!E56 -> 16.680783 | G26: =Bridge!F56 -> 18.208461
B28: Source: Bernstein analysis and estimates
