Workbook

Sheet Model
A1: WMG Bottoms-Up OIBDA Margin Build
A2: Your revenue/SGA/OIBDA. Blue = adjustable CM assumptions. Green = Sub CM (formula plug, guarantees $0 diff). All other cells are formulas.
A4: ($M) | B4: FY2023 | C4: FY2024 | D4: FY2025 | E4: FY2026E | F4: FY2027E | G4: FY2028E | H4: Notes
A5: REVENUE (your model)
A6: Subscription Streaming | B6: 2340 | C6: 2544 | D6: 2627 | E6: 2980 | F6: 3266 | G6: 3560
A7: Ad-Supported Streaming | B7: 883 | C7: 900 | D7: 878 | E7: 927 | F7: 983 | G7: 1042
A8: Downloads & Other Digital | B8: 99 | C8: 75 | D8: 89 | E8: 61 | F8: 61 | G8: 61
A9: Physical | B9: 507 | C9: 519 | D9: 527 | E9: 513 | F9: 513 | G9: 513
A10: Artist Svcs & Expanded Rights | B10: 744 | C10: 684 | D10: 835 | E10: 800 | F10: 802 | G10: 802
A11: Licensing | B11: 382 | C11: 501 | D11: 452 | E11: 463 | F11: 463 | G11: 463
A12: Publishing - Digital | B12: 669 | C12: 763 | D12: 800 | E12: 877 | F12: 956 | G12: 1042
A13: Publishing - Other | B13: 419 | C13: 447 | D13: 506 | E13: 550 | F13: 583 | G13: 618
A14: Intersegment Eliminations | B14: -6 | C14: -7 | D14: -7 | E14: -7 | F14: -7 | G14: -7
A15: Total Revenue | B15: =B6+B7+B8+B9+B10+B11+B12+B13+B14 -> 6037 | C15: =C6+C7+C8+C9+C10+C11+C12+C13+C14 -> 6426 | D15: =D6+D7+D8+D9+D10+D11+D12+D13+D14 -> 6707 | E15: =E6+E7+E8+E9+E10+E11+E12+E13+E14 -> 7164 | F15: =F6+F7+F8+F9+F10+F11+F12+F13+F14 -> 7620 | G15: =G6+G7+G8+G9+G10+G11+G12+G13+G14 -> 8094
A16: Your Adj. OIBDA | B16: 1227 | C16: 1432 | D16: 1430 | E16: 1729 | F16: 1934 | G16: 2175
A17: Your Adj Cash SGA | B17: 1633 | C17: 1639 | D17: 1645 | E17: 1633 | F17: 1641 | G17: 1662
A18: Your OIBDA Margin | B18: =B16/B15 -> 0.20324665 | C18: =C16/C15 -> 0.22284469 | D18: =D16/D15 -> 0.21321008 | E18: =E16/E15 -> 0.24134562 | F18: =F16/F15 -> 0.25380577 | G18: =G16/G15 -> 0.26871757
A19: Your SGA as % of Revenue | B19: =B17/B15 -> 0.27049859 | C19: =C17/C15 -> 0.25505758 | D19: =D17/D15 -> 0.24526614 | E19: =E17/E15 -> 0.22794528 | F19: =F17/F15 -> 0.21535433 | G19: =G17/G15 -> 0.20533729
A21: CONTRIBUTION MARGINS BY STREAM
A22: Subscription Streaming | B22: =(B16+B17-(B7*B23+B8*B24+B9*B25+B10*B26+B11*B27+B12*B28+B13*B29))/B6 -> 0.52413248 | C22: =(C16+C17-(C7*C23+C8*C24+C9*C25+C10*C26+C11*C27+C12*C28+C13*C29))/C6 -> 0.50911164 | D22: =(D16+D17-(D7*D23+D8*D24+D9*D25+D10*D26+D11*D27+D12*D28+D13*D29))/D6 -> 0.47510468 | E22: =(E16+E17-(E7*E23+E8*E24+E9*E25+E10*E26+E11*E27+E12*E28+E13*E29))/E6 -> 0.4885453 | F22: =(F16+F17-(F7*F23+F8*F24+F9*F25+F10*F26+F11*F27+F12*F28+F13*F29))/F6 -> 0.48305266 | G22: =(G16+G17-(G7*G23+G8*G24+G9*G25+G10*G26+G11*G27+G12*G28+G13*G29))/G6 -> 0.48939466 | H22: PLUG: formula-derived to tie OIBDA. Green = calculated.
A23: Ad-Supported Streaming | B23: 0.43 | C23: 0.43 | D23: 0.43 | E23: 0.43 | F23: 0.43 | G23: 0.43 | H23: 43%. Stable. Ad CPMs steady; no structural change.
A24: Downloads & Other Digital | B24: 0.5 | C24: 0.5 | D24: 0.5 | E24: 0.49 | F24: 0.48 | G24: 0.47 | H24: 50%→47%. Declining 1pp/yr. Secular shrinkage, fixed cost deleverage.
A25: Physical | B25: 0.3 | C25: 0.3 | D25: 0.3 | E25: 0.295 | F25: 0.29 | G25: 0.285 | H25: 30%→28.5%. Declining 0.5pp/yr. Fewer units → higher per-unit mfg/dist cost.
A26: Artist Svcs & Expanded Rights | B26: 0.2 | C26: 0.2 | D26: 0.2 | E26: 0.21 | F26: 0.215 | G26: 0.22 | H26: 20%→22%. Improving 0.67pp/yr. Oasis pass-through normalizes. Mix toward merch/DTC.
A27: Licensing | B27: 0.7 | C27: 0.7 | D27: 0.7 | E27: 0.7 | F27: 0.7 | G27: 0.7 | H27: 70%. Stable. Already highest CM. Catalog deals incrementally positive.
A28: Publishing - Digital | B28: 0.6 | C28: 0.6 | D28: 0.6 | E28: 0.6 | F28: 0.6 | G28: 0.6 | H28: 60%. Stable. Writer share (~50%) anchors variable cost. Direct licensing modest help.
A29: Publishing - Other | B29: 0.56 | C29: 0.56 | D29: 0.56 | E29: 0.56 | F29: 0.56 | G29: 0.56 | H29: 56%. Stable. Sync growing within bucket but small overall impact.
A31: CONTRIBUTION PROFIT (Revenue × CM)
A32: Subscription Streaming | B32: =B6*B22 -> 1226.47 | C32: =C6*C22 -> 1295.18 | D32: =D6*D22 -> 1248.1 | E32: =E6*E22 -> 1455.865 | F32: =F6*F22 -> 1577.65 | G32: =G6*G22 -> 1742.245
A33: Ad-Supported Streaming | B33: =B7*B23 -> 379.69 | C33: =C7*C23 -> 387 | D33: =D7*D23 -> 377.54 | E33: =E7*E23 -> 398.61 | F33: =F7*F23 -> 422.69 | G33: =G7*G23 -> 448.06
A34: Downloads & Other Digital | B34: =B8*B24 -> 49.5 | C34: =C8*C24 -> 37.5 | D34: =D8*D24 -> 44.5 | E34: =E8*E24 -> 29.89 | F34: =F8*F24 -> 29.28 | G34: =G8*G24 -> 28.67
A35: Physical | B35: =B9*B25 -> 152.1 | C35: =C9*C25 -> 155.7 | D35: =D9*D25 -> 158.1 | E35: =E9*E25 -> 151.335 | F35: =F9*F25 -> 148.77 | G35: =G9*G25 -> 146.205
A36: Artist Svcs & Expanded Rights | B36: =B10*B26 -> 148.8 | C36: =C10*C26 -> 136.8 | D36: =D10*D26 -> 167 | E36: =E10*E26 -> 168 | F36: =F10*F26 -> 172.43 | G36: =G10*G26 -> 176.44
A37: Licensing | B37: =B11*B27 -> 267.4 | C37: =C11*C27 -> 350.7 | D37: =D11*D27 -> 316.4 | E37: =E11*E27 -> 324.1 | F37: =F11*F27 -> 324.1 | G37: =G11*G27 -> 324.1
A38: Publishing - Digital | B38: =B12*B28 -> 401.4 | C38: =C12*C28 -> 457.8 | D38: =D12*D28 -> 480 | E38: =E12*E28 -> 526.2 | F38: =F12*F28 -> 573.6 | G38: =G12*G28 -> 625.2
A39: Publishing - Other | B39: =B13*B29 -> 234.64 | C39: =C13*C29 -> 250.32 | D39: =D13*D29 -> 283.36 | E39: =E13*E29 -> 308 | F39: =F13*F29 -> 326.48 | G39: =G13*G29 -> 346.08
A40: Total Contribution Profit | B40: =B32+B33+B34+B35+B36+B37+B38+B39 -> 2860 | C40: =C32+C33+C34+C35+C36+C37+C38+C39 -> 3071 | D40: =D32+D33+D34+D35+D36+D37+D38+D39 -> 3075 | E40: =E32+E33+E34+E35+E36+E37+E38+E39 -> 3362 | F40: =F32+F33+F34+F35+F36+F37+F38+F39 -> 3575 | G40: =G32+G33+G34+G35+G36+G37+G38+G39 -> 3837
A41: Blended Contribution Margin | B41: =B40/(B6+B7+B8+B9+B10+B11+B12+B13) -> 0.47327486 | C41: =C40/(C6+C7+C8+C9+C10+C11+C12+C13) -> 0.47738225 | D41: =D40/(D6+D7+D8+D9+D10+D11+D12+D13) -> 0.45799821 | E41: =E40/(E6+E7+E8+E9+E10+E11+E12+E13) -> 0.4688328 | F41: =F40/(F6+F7+F8+F9+F10+F11+F12+F13) -> 0.46872951 | G41: =G40/(G6+G7+G8+G9+G10+G11+G12+G13) -> 0.47364523
A43: CONTRIBUTION PROFIT MIX (% of Total CP)
A44: Subscription Streaming | B44: =B32/B40 -> 0.42883566 | C44: =C32/C40 -> 0.42174536 | D44: =D32/D40 -> 0.40588618 | E44: =E32/E40 -> 0.4330354 | F44: =F32/F40 -> 0.4413007 | G44: =G32/G40 -> 0.45406437
...

Sheet Lever Sensitivity
A1: Lever Sensitivity: From Your FY28E (26.9%) to 30%+
A2: Base values from Model tab (FY28E). Blue = scenario inputs. All results are formulas.
B4: Value | C4: Low | D4: Mid | E4: High | F4: Max
A5: FY28E BASE (from Model tab)
A6: Sub Rev | B6: =Model!G6 -> 3560
A7: Sub Eff CM | B7: =Model!G22 -> 0.48939466
A8: Physical Eff CM | B8: =Model!G25 -> 0.285
A9: Artist Svcs Eff CM | B9: =Model!G26 -> 0.22
A10: Total Revenue | B10: =Model!G15 -> 8094
A11: OIBDA | B11: =Model!G16 -> 2175
A12: OIBDA Margin | B12: =B11/B10 -> 0.26871757
A13: Target | B13: 0.3
A14: Gap (bps) | B14: =(B13-B12)*10000 -> 312.82431
A16: LEVER 1: INCREMENTAL SUB STREAMING
C17: Low | D17: Mid | E17: High | F17: Max
A18: Incremental Sub Rev ($M) | B18: Input → | C18: 178 | D18: 356 | E18: 534 | F18: 712
A19: New Total Rev | C19: =B10+C18 -> 8272 | D19: =B10+D18 -> 8450 | E19: =B10+E18 -> 8628 | F19: =B10+F18 -> 8806
A20: Incremental CP | C20: =C18*B7 -> 87.11225 | D20: =D18*B7 -> 174.2245 | E20: =E18*B7 -> 261.33675 | F20: =F18*B7 -> 348.449
A21: New OIBDA | C21: =B11+C20 -> 2262.1123 | D21: =B11+D20 -> 2349.2245 | E21: =B11+E20 -> 2436.3367 | F21: =B11+F20 -> 2523.449
A22: New Margin | C22: =C21/C19 -> 0.27346618 | D22: =D21/D19 -> 0.27801473 | E22: =E21/E19 -> 0.28237561 | F22: =F21/F19 -> 0.28656019
A23: Margin Δ (bps) | C23: =(C22-B12)*10000 -> 47.486125 | D23: =(D22-B12)*10000 -> 92.971652 | E23: =(E22-B12)*10000 -> 136.5804 | F23: =(F22-B12)*10000 -> 178.42618
A25: LEVER 2: SGA REDUCTION
C26: Low | D26: Mid | E26: High | F26: Max
A27: SGA Cut ($M) | B27: Input → | C27: 50 | D27: 100 | E27: 150 | F27: 250
A28: New OIBDA | C28: =B11+C27 -> 2225 | D28: =B11+D27 -> 2275 | E28: =B11+E27 -> 2325 | F28: =B11+F27 -> 2425
A29: New Margin | C29: =C28/B10 -> 0.27489498 | D29: =D28/B10 -> 0.2810724 | E29: =E28/B10 -> 0.28724981 | F29: =F28/B10 -> 0.29960465
A30: Margin Δ (bps) | C30: =(C29-B12)*10000 -> 61.774154 | D30: =(D29-B12)*10000 -> 123.54831 | E30: =(E29-B12)*10000 -> 185.32246 | F30: =(F29-B12)*10000 -> 308.87077
A32: LEVER 3: AS → STREAMING SHIFT (rev-neutral)
C33: Low | D33: Mid | E33: High | F33: Max
A34: AS Shifted to Sub ($M) | B34: Input → | C34: 50 | D34: 100 | E34: 150 | F34: 200
A35: Net CP Pickup | C35: =C34*(B7-B9) -> 13.469733 | D35: =D34*(B7-B9) -> 26.939466 | E35: =E34*(B7-B9) -> 40.409199 | F35: =F34*(B7-B9) -> 53.878933
A36: New OIBDA | C36: =B11+C35 -> 2188.4697 | D36: =B11+D35 -> 2201.9395 | E36: =B11+E35 -> 2215.4092 | F36: =B11+F35 -> 2228.8789
A37: New Margin | C37: =C36/B10 -> 0.27038173 | D37: =D36/B10 -> 0.27204589 | E37: =E36/B10 -> 0.27371006 | F37: =F36/B10 -> 0.27537422
A38: Margin Δ (bps) | C38: =(C37-B12)*10000 -> 16.641627 | D38: =(D37-B12)*10000 -> 33.283255 | E38: =(E37-B12)*10000 -> 49.924882 | F38: =(F37-B12)*10000 -> 66.566509
A40: LEVER 4: PHYSICAL → STREAMING SHIFT (rev-neutral)
C41: Low | D41: Mid | E41: High | F41: Max
A42: Physical Shifted to Sub ($M) | B42: Input → | C42: 50 | D42: 100 | E42: 150 | F42: 200
A43: Net CP Pickup | C43: =C42*(B7-B8) -> 10.219733 | D43: =D42*(B7-B8) -> 20.439466 | E43: =E42*(B7-B8) -> 30.659199 | F43: =F42*(B7-B8) -> 40.878933
A44: New OIBDA | C44: =B11+C43 -> 2185.2197 | D44: =B11+D43 -> 2195.4395 | E44: =B11+E43 -> 2205.6592 | F44: =B11+F43 -> 2215.8789
A45: New Margin | C45: =C44/B10 -> 0.2699802 | D45: =D44/B10 -> 0.27124283 | E45: =E44/B10 -> 0.27250546 | F45: =F44/B10 -> 0.27376809
...

Sheet Exhibit
A1: Exhibit: WMG FY28E OIBDA Margin — Lever Sensitivity
B3: Low | C3: Mid | D3: High | E3: Max | F3: Mechanism
A4: YOUR FY28E BASE MARGIN | B4: ='Lever Sensitivity'!B12 -> 0.26871757 | F4: Rev $8.1B, OIBDA $2.2B, SGA $1.66B (20.5%)
A5: GAP TO 30% | B5: ='Lever Sensitivity'!B14 -> 312.82431 | C5: bps
A9: 1. Sub Streaming Growth (+5%/+10%/+15%/+20% vs est) | B9: ='Lever Sensitivity'!C23 -> 47.486125 | C9: ='Lever Sensitivity'!D23 -> 92.971652 | D9: ='Lever Sensitivity'!E23 -> 136.5804 | E9: ='Lever Sensitivity'!F23 -> 178.42618 | F9: ~49% CM. Scales with slate + DSP pricing.
A10: 2. SGA Reduction ($50M/$100M/$150M/$250M) | B10: ='Lever Sensitivity'!C30 -> 61.774154 | C10: ='Lever Sensitivity'!D30 -> 123.54831 | D10: ='Lever Sensitivity'!E30 -> 185.32246 | E10: ='Lever Sensitivity'!F30 -> 308.87077 | F10: Highest impact per $. Dollar-for-dollar.
A11: 3. AS → Streaming Shift ($50-200M reallocation) | B11: ='Lever Sensitivity'!C38 -> 16.641627 | C11: ='Lever Sensitivity'!D38 -> 33.283255 | D11: ='Lever Sensitivity'!E38 -> 49.924882 | E11: ='Lever Sensitivity'!F38 -> 66.566509 | F11: ~27pp CM pickup. Oasis normalization.
A12: 4. Physical → Streaming ($50-200M reallocation) | B12: ='Lever Sensitivity'!C46 -> 12.626307 | C12: ='Lever Sensitivity'!D46 -> 25.252615 | D12: ='Lever Sensitivity'!E46 -> 37.878922 | E12: ='Lever Sensitivity'!F46 -> 50.505229 | F12: ~20pp CM pickup. Structurally inevitable.
A14: COMBINED: Bull Case | B14: ='Lever Sensitivity'!C57 -> 0.294659 | C14: ='Lever Sensitivity'!C58 -> 259.41433 | D14: bps | F14: Sub+10%, SGA-$100M, AS+Phys shift $175M
A15: COMBINED: Max Case (30%+) | B15: ='Lever Sensitivity'!D57 -> 0.30643665 | C15: ='Lever Sensitivity'!D58 -> 377.19081 | D15: bps | F15: Sub+15%, SGA-$150M, AS+Phys shift $250M
A17: Note: Sub streaming CM is formula-derived (plug) to tie your OIBDA. All other CMs have independent logic. FY28E implied Sub CM ~49% reflects DSP pricing recovery from FY25 trough (47.5%). SGA from your model.
A18: Source: WMG 10-K/10-Q, your model estimates. Scenarios incremental to FY28E base.

Sheet Sources
A1: Sources & CM Logic
A3: ARCHITECTURE
A4: Sub CM = plug | B4: Sub streaming CM is formula-derived: (OIBDA+SGA-non-sub CP)/Sub Rev. Guarantees $0 difference. This is standard sell-side practice: biggest line absorbs the residual.
A5: 7 independent CMs | B5: Each non-sub stream has its own CM with directional logic. Blue cells, adjustable per year. Change them and Sub CM recalculates to maintain $0 tie.
A7: NON-SUB CM LOGIC
A8: Ad (43%, stable) | B8: Structurally stable. No major change in ad-supported streaming economics expected.
A9: Downloads (50%→47%) | B9: Declining. Secular shrinkage reduces scale → fixed costs deleverage.
A10: Physical (30%→28.5%) | B10: Declining. Volume drops (CD esp.) → per-unit mfg/dist cost rises.
A11: Artist Svcs (20%→22%) | B11: Improving. FY25 Oasis pass-through (~85% cost) normalizes. Mix shifts toward higher-margin merch/DTC.
A12: Licensing (70%, stable) | B12: Already highest CM. Catalog-driven, minimal cost. AI licensing (Suno, Udio) accretive but small.
A13: Pub Digital (60%, stable) | B13: Writer share (~50%) anchors. Direct licensing helps modestly.
A14: Pub Other (56%, stable) | B14: Blended perf/mech/sync. Sync growing but small overall.
A16: SUB CM (PLUG) INTERPRETATION
A17: FY23-24: 52-51% | B17: Pre-A&R investment cycle. Variable costs lower before heavy signing/advance activity.
A18: FY25: 47.5% (trough) | B18: Peak A&R investment. Heavy advances + new deals at richer rates. Anchor year.
A19: FY26E-28E: ~48-49% | B19: Recovery. DSP pricing (Spotify hikes, contractual increases) lifts per-stream rate while royalty structure is %-based. A&R cycle matures.
A20: FY27E dip to 48.3% | B20: Your model implies flat blended CM in FY27E. All margin improvement that year from SGA (21.5% vs 22.8%). Sub CM absorbs this.
A22: CROSS-CHECKS
A23: $0 difference | B23: All 6 years. Guaranteed by Sub CM plug formula.
A24: Blended CM path | B24: 45.8% (FY25) → 47.4% (FY28E) = +156bps. Of which: ~85bps mix, ~71bps CM evolution.
A25: SGA path | B25: Your numbers: $1,645M/24.5% (FY25) → $1,662M/20.5% (FY28E). Drives ~400bps of improvement.
