Workbook

Sheet Revenue Build
A1: WMG Bottoms-Up Revenue Build by Stream
A2: Blue = adjustable assumption. Revenue lines from 10-K. Growth rates drive projections.
A4: ($M unless noted) | B4: FY2024A | C4: FY2025A | D4: FY2026E | E4: FY2027E | F4: FY2028E | G4: Source / Notes
A5: RECORDED MUSIC — REVENUE BY STREAM
A6: Subscription Streaming | B6: 2543 | C6: 2627 | D6: =C6*(1+D7) -> 2889.7 | E6: =D6*(1+E7) -> 3149.773 | F6: =E6*(1+F7) -> 3401.7548 | G6: 10-K. DSP pricing + vol growth
A7: YoY Growth | C7: 0.033031852 | D7: 0.1 | E7: 0.09 | F7: 0.08
A8: Ad-Supported Streaming | B8: 942 | C8: 878 | D8: =C8*(1+D9) -> 913.12 | E8: =D8*(1+E9) -> 958.776 | F8: =E8*(1+F9) -> 1016.3026 | G8: 10-K. Soft in FY25, recovering
A9: YoY Growth | C9: -0.067940552 | D9: 0.04 | E9: 0.05 | F9: 0.06
A10: Downloads & Other Digital | B10: 34 | C10: 89 | D10: =C10*(1+D11) -> 75.65 | E10: =D10*(1+E11) -> 64.3025 | F10: =E10*(1+F11) -> 54.657125 | G10: 10-K. Secular decline + FY25 one-off
A11: YoY Growth | C11: 1.6176471 | D11: -0.15 | E11: -0.15 | F11: -0.15
A12: Physical | B12: 519 | C12: 527 | D12: =C12*(1+D13) -> 511.19 | E12: =D12*(1+E13) -> 485.6305 | F12: =E12*(1+F13) -> 456.49267 | G12: 10-K. Vinyl stable but CD declining
A13: YoY Growth | C13: 0.015414258 | D13: -0.03 | E13: -0.05 | F13: -0.06
A14: Artist Svcs & Expanded Rights | B14: 684 | C14: 835 | D14: =C14*(1+D15) -> 918.5 | E14: =D14*(1+E15) -> 991.98 | F14: =E14*(1+F15) -> 1051.4988 | G14: 10-K. Oasis effect normalizing
A15: YoY Growth | C15: 0.22076023 | D15: 0.1 | E15: 0.08 | F15: 0.06
A16: Licensing | B16: 501 | C16: 452 | D16: =C16*(1+D17) -> 474.6 | E16: =D16*(1+E17) -> 498.33 | F16: =E16*(1+F17) -> 523.2465 | G16: 10-K. Adj for FY25 Licensing Ext comp
A17: YoY Growth | C17: -0.097804391 | D17: 0.05 | E17: 0.05 | F17: 0.05
A18: TOTAL RECORDED MUSIC | B18: 5223 | C18: 5408 | D18: =D6+D8+D10+D12+D14+D16 -> 5782.76 | E18: =E6+E8+E10+E12+E14+E16 -> 6148.792 | F18: =F6+F8+F10+F12+F14+F16 -> 6503.9525 | G18: Sum of lines above
A19: YoY Growth | C19: 0.035420257 | D19: =(D18/C18)-1 -> 0.069297337 | E19: =(E18/D18)-1 -> 0.063297111 | F19: =(F18/E18)-1 -> 0.05776102
A21: MUSIC PUBLISHING — REVENUE BY STREAM
A22: Performance | B22: 198 | C22: 228 | D22: =C22*(1+D23) -> 255.36 | E22: =D22*(1+E23) -> 280.896 | F22: =E22*(1+F23) -> 303.36768 | G22: 10-K. Concerts + collection timing
A23: YoY Growth | C23: 0.15151515 | D23: 0.12 | E23: 0.1 | F23: 0.08
A24: Digital (incl streaming) | B24: 763 | C24: 800 | D24: =C24*(1+D25) -> 856 | E24: =D24*(1+E25) -> 915.92 | F24: =E24*(1+F25) -> 970.8752 | G24: 10-K. Catalog growth + deal renewals
A25: YoY Growth | C25: 0.048492792 | D25: 0.07 | E25: 0.07 | F25: 0.06
A26: Mechanical | B26: 58 | C26: 63 | D26: =C26*(1+D27) -> 66.78 | E26: =D26*(1+E27) -> 70.119 | F26: =E26*(1+F27) -> 73.62495 | G26: 10-K
A27: YoY Growth | C27: 0.086206897 | D27: 0.06 | E27: 0.05 | F27: 0.05
A28: Synchronization | B28: 175 | C28: 197 | D28: =C28*(1+D29) -> 212.76 | E28: =D28*(1+E29) -> 227.6532 | F28: =E28*(1+F29) -> 241.31239 | G28: 10-K. Infringement settlements lumpy
A29: YoY Growth | C29: 0.12571429 | D29: 0.08 | E29: 0.07 | F29: 0.06
A30: Other | B30: 16 | C30: 18 | D30: =C30*(1+D31) -> 18.54 | E30: =D30*(1+E31) -> 19.0962 | F30: =E30*(1+F31) -> 19.669086 | G30: 10-K
A31: YoY Growth | C31: 0.125 | D31: 0.03 | E31: 0.03 | F31: 0.03
A32: TOTAL MUSIC PUBLISHING | B32: 1210 | C32: 1306 | D32: =D22+D24+D26+D28+D30 -> 1409.44 | E32: =E22+E24+E26+E28+E30 -> 1513.6844 | F32: =F22+F24+F26+F28+F30 -> 1608.8493 | G32: Sum of lines above
A33: YoY Growth | C33: 0.079338843 | D33: =(D32/C32)-1 -> 0.079203675 | E33: =(E32/D32)-1 -> 0.073961573 | F33: =(F32/E32)-1 -> 0.062869716
A35: TOTAL WMG REVENUE
A36: TOTAL REVENUE | B36: 6426 | C36: 6707 | D36: =D18+D32 -> 7192.2 | E36: =E18+E32 -> 7662.4764 | F36: =F18+F32 -> 8112.8018 | G36: RM + Pub (ignoring ~$7M elim)
A37: YoY Growth | C37: 0.043728603 | D37: =(D36/C36)-1 -> 0.072342329 | E37: =(E36/D36)-1 -> 0.065387003 | F37: =(F36/E36)-1 -> 0.058770217
A39: REVENUE MIX (% of Total)
A40: Sub Streaming | B40: =B6/B36 -> 0.39573607 | C40: =C6/C36 -> 0.39168033 | D40: =D6/D36 -> 0.40178249 | E40: =E6/E36 -> 0.41106463 | F40: =F6/F36 -> 0.41930703
A41: Ad Streaming | B41: =B8/B36 -> 0.14659197 | C41: =C8/C36 -> 0.13090801 | D41: =D8/D36 -> 0.12695976 | E41: =E8/E36 -> 0.12512613 | F41: =F8/F36 -> 0.12527146
A42: Total RM Streaming | B42: =(B6+B8)/B36 -> 0.54232804 | C42: =(C6+C8)/C36 -> 0.52258834 | D42: =(D6+D8)/D36 -> 0.52874225 | E42: =(E6+E8)/E36 -> 0.53619075 | F42: =(F6+F8)/F36 -> 0.5445785
A43: Physical | B43: =B12/B36 -> 0.08076564 | C43: =C12/C36 -> 0.078574624 | D43: =D12/D36 -> 0.07107561 | E43: =E12/E36 -> 0.063377748 | F43: =F12/F36 -> 0.05626819
A44: Artist Svcs | B44: =B14/B36 -> 0.10644258 | C44: =C14/C36 -> 0.12449679 | D44: =D14/D36 -> 0.12770779 | E44: =E14/E36 -> 0.12945945 | F44: =F14/F36 -> 0.12960982
...

Sheet Contribution Margin Build
A1: Bottoms-Up OIBDA Margin Build: Revenue × Contribution Margin → Less Fixed Costs → OIBDA
A2: Blue = estimated contribution margin per stream. WMG does not disclose; triangulated from UMG, sell-side, segment data. See Sources tab.
A4: ($M unless noted) | B4: FY2024A | C4: FY2025A | D4: FY2026E | E4: FY2027E | F4: FY2028E | G4: Contribution Margin Assumption & Basis
A5: REVENUE (pulled from Revenue Build tab)
A6: Subscription Streaming | B6: ='Revenue Build'!B6 -> 2543 | C6: ='Revenue Build'!C6 -> 2627 | D6: ='Revenue Build'!D6 -> 2889.7 | E6: ='Revenue Build'!E6 -> 3149.773 | F6: ='Revenue Build'!F6 -> 3401.7548 | G6: Linked to Revenue Build
A7: Ad-Supported Streaming | B7: ='Revenue Build'!B8 -> 942 | C7: ='Revenue Build'!C8 -> 878 | D7: ='Revenue Build'!D8 -> 913.12 | E7: ='Revenue Build'!E8 -> 958.776 | F7: ='Revenue Build'!F8 -> 1016.3026 | G7: Linked to Revenue Build
A8: Downloads & Other Digital | B8: ='Revenue Build'!B10 -> 34 | C8: ='Revenue Build'!C10 -> 89 | D8: ='Revenue Build'!D10 -> 75.65 | E8: ='Revenue Build'!E10 -> 64.3025 | F8: ='Revenue Build'!F10 -> 54.657125 | G8: Linked to Revenue Build
A9: Physical | B9: ='Revenue Build'!B12 -> 519 | C9: ='Revenue Build'!C12 -> 527 | D9: ='Revenue Build'!D12 -> 511.19 | E9: ='Revenue Build'!E12 -> 485.6305 | F9: ='Revenue Build'!F12 -> 456.49267 | G9: Linked to Revenue Build
A10: Artist Svcs & Expanded Rights | B10: ='Revenue Build'!B14 -> 684 | C10: ='Revenue Build'!C14 -> 835 | D10: ='Revenue Build'!D14 -> 918.5 | E10: ='Revenue Build'!E14 -> 991.98 | F10: ='Revenue Build'!F14 -> 1051.4988 | G10: Linked to Revenue Build
A11: Licensing | B11: ='Revenue Build'!B16 -> 501 | C11: ='Revenue Build'!C16 -> 452 | D11: ='Revenue Build'!D16 -> 474.6 | E11: ='Revenue Build'!E16 -> 498.33 | F11: ='Revenue Build'!F16 -> 523.2465 | G11: Linked to Revenue Build
A12: Publishing — Performance | B12: ='Revenue Build'!B22 -> 198 | C12: ='Revenue Build'!C22 -> 228 | D12: ='Revenue Build'!D22 -> 255.36 | E12: ='Revenue Build'!E22 -> 280.896 | F12: ='Revenue Build'!F22 -> 303.36768 | G12: Linked to Revenue Build
A13: Publishing — Digital | B13: ='Revenue Build'!B24 -> 763 | C13: ='Revenue Build'!C24 -> 800 | D13: ='Revenue Build'!D24 -> 856 | E13: ='Revenue Build'!E24 -> 915.92 | F13: ='Revenue Build'!F24 -> 970.8752 | G13: Linked to Revenue Build
A14: Publishing — Mechanical | B14: ='Revenue Build'!B26 -> 58 | C14: ='Revenue Build'!C26 -> 63 | D14: ='Revenue Build'!D26 -> 66.78 | E14: ='Revenue Build'!E26 -> 70.119 | F14: ='Revenue Build'!F26 -> 73.62495 | G14: Linked to Revenue Build
A15: Publishing — Sync | B15: ='Revenue Build'!B28 -> 175 | C15: ='Revenue Build'!C28 -> 197 | D15: ='Revenue Build'!D28 -> 212.76 | E15: ='Revenue Build'!E28 -> 227.6532 | F15: ='Revenue Build'!F28 -> 241.31239 | G15: Linked to Revenue Build
A16: Publishing — Other | B16: ='Revenue Build'!B30 -> 16 | C16: ='Revenue Build'!C30 -> 18 | D16: ='Revenue Build'!D30 -> 18.54 | E16: ='Revenue Build'!E30 -> 19.0962 | F16: ='Revenue Build'!F30 -> 19.669086 | G16: Linked to Revenue Build
A17: TOTAL REVENUE | B17: ='Revenue Build'!B36 -> 6426 | C17: ='Revenue Build'!C36 -> 6707 | D17: ='Revenue Build'!D36 -> 7192.2 | E17: ='Revenue Build'!E36 -> 7662.4764 | F17: ='Revenue Build'!F36 -> 8112.8018
A19: CONTRIBUTION MARGIN BY STREAM (adjustable)
A20: Subscription Streaming | B20: 0.47 | C20: 0.47 | D20: 0.47 | E20: 0.47 | F20: 0.47 | G20: 47%. AFTER royalties (~53% vc rate). Highest RM digital margin.
A21: Ad-Supported Streaming | B21: 0.43 | C21: 0.43 | D21: 0.43 | E21: 0.43 | F21: 0.43 | G21: 43%. Same structure as sub but lower per-stream rate → higher vc%.
A22: Downloads & Other Digital | B22: 0.5 | C22: 0.5 | D22: 0.5 | E22: 0.5 | F22: 0.5 | G22: 50%. Digital delivery. Small & shrinking.
A23: Physical | B23: 0.3 | C23: 0.3 | D23: 0.3 | E23: 0.3 | F23: 0.3 | G23: 30%. Mfg + dist + retail margin + royalties. LOWEST CM line.
A24: Artist Svcs & Expanded Rights | B24: 0.2 | C24: 0.2 | D24: 0.2 | E24: 0.2 | F24: 0.2 | G24: 20%. Concert promo pass-through + merch COGS. MARGIN DILUTIVE.
A25: Licensing | B25: 0.7 | C25: 0.7 | D25: 0.7 | E25: 0.7 | F25: 0.7 | G25: 70%. Catalog-driven, minimal incremental cost. HIGHEST CM.
A26: Publishing — Performance | B26: 0.55 | C26: 0.55 | D26: 0.55 | E26: 0.55 | F26: 0.55 | G26: 55%. Collection society fees + writer share.
A27: Publishing — Digital | B27: 0.6 | C27: 0.6 | D27: 0.6 | E27: 0.6 | F27: 0.6 | G27: 60%. Writer share + collection, but high digital efficiency.
A28: Publishing — Mechanical | B28: 0.55 | C28: 0.55 | D28: 0.55 | E28: 0.55 | F28: 0.55 | G28: 55%. Statutory rates, collection overhead.
A29: Publishing — Sync | B29: 0.7 | C29: 0.7 | D29: 0.7 | E29: 0.7 | F29: 0.7 | G29: 70%. One-time fees, minimal delivery cost. Highest pub CM.
A30: Publishing — Other | B30: 0.55 | C30: 0.55 | D30: 0.55 | E30: 0.55 | F30: 0.55 | G30: 55%. Mixed.
A32: CONTRIBUTION PROFIT = Revenue × Contribution Margin
A33: Subscription Streaming | B33: =B6*B20 -> 1195.21 | C33: =C6*C20 -> 1234.69 | D33: =D6*D20 -> 1358.159 | E33: =E6*E20 -> 1480.3933 | F33: =F6*F20 -> 1598.8248
A34: Ad-Supported Streaming | B34: =B7*B21 -> 405.06 | C34: =C7*C21 -> 377.54 | D34: =D7*D21 -> 392.6416 | E34: =E7*E21 -> 412.27368 | F34: =F7*F21 -> 437.0101
A35: Downloads & Other Digital | B35: =B8*B22 -> 17 | C35: =C8*C22 -> 44.5 | D35: =D8*D22 -> 37.825 | E35: =E8*E22 -> 32.15125 | F35: =F8*F22 -> 27.328563
A36: Physical | B36: =B9*B23 -> 155.7 | C36: =C9*C23 -> 158.1 | D36: =D9*D23 -> 153.357 | E36: =E9*E23 -> 145.68915 | F36: =F9*F23 -> 136.9478
A37: Artist Svcs & Expanded Rights | B37: =B10*B24 -> 136.8 | C37: =C10*C24 -> 167 | D37: =D10*D24 -> 183.7 | E37: =E10*E24 -> 198.396 | F37: =F10*F24 -> 210.29976
A38: Licensing | B38: =B11*B25 -> 350.7 | C38: =C11*C25 -> 316.4 | D38: =D11*D25 -> 332.22 | E38: =E11*E25 -> 348.831 | F38: =F11*F25 -> 366.27255
A39: Publishing — Performance | B39: =B12*B26 -> 108.9 | C39: =C12*C26 -> 125.4 | D39: =D12*D26 -> 140.448 | E39: =E12*E26 -> 154.4928 | F39: =F12*F26 -> 166.85222
A40: Publishing — Digital | B40: =B13*B27 -> 457.8 | C40: =C13*C27 -> 480 | D40: =D13*D27 -> 513.6 | E40: =E13*E27 -> 549.552 | F40: =F13*F27 -> 582.52512
A41: Publishing — Mechanical | B41: =B14*B28 -> 31.9 | C41: =C14*C28 -> 34.65 | D41: =D14*D28 -> 36.729 | E41: =E14*E28 -> 38.56545 | F41: =F14*F28 -> 40.493722
A42: Publishing — Sync | B42: =B15*B29 -> 122.5 | C42: =C15*C29 -> 137.9 | D42: =D15*D29 -> 148.932 | E42: =E15*E29 -> 159.35724 | F42: =F15*F29 -> 168.91867
A43: Publishing — Other | B43: =B16*B30 -> 8.8 | C43: =C16*C30 -> 9.9 | D43: =D16*D30 -> 10.197 | E43: =E16*E30 -> 10.50291 | F43: =F16*F30 -> 10.817997
...

Sheet Lever Sensitivity
A1: Which Levers Matter Most? Marginal Impact on FY28E OIBDA Margin
A2: Shows the isolated impact of changing ONE assumption while holding others constant at base case.
A4: Lever | B4: Downside | C4: Base | D4: Upside | E4: What This Tells You
A5: Sub Streaming Growth (FY26-28 avg) | B5: 6% avg | C5: 9% avg | D5: 12% avg | E5: BIGGEST lever. Each 1pp faster growth = ~30-40bps margin uplift via mix shift + SGA leverage.
A6: FY28E Margin Impact | B6: ~24.5% | C6: ~26.5% | D6: ~28.5% | E6: Streaming growth alone can swing margin by ~400bps.
A8: Physical Revenue Decline Rate | B8: Flat (0%) | C8: (4%) avg | D8: (8%) avg | E8: Physical declining HELPS margin (removing low-CM revenue). Faster decline = higher blended CM.
A9: FY28E Margin Impact | B9: ~25.5% | C9: ~26.5% | D9: ~27.0% | E9: Smaller lever than streaming growth. ~150bps swing.
A11: Artist Services Growth | B11: 15% avg | C11: 8% avg | D11: 3% avg | E11: COUNTERINTUITIVE: Slower AS growth HELPS margin because AS is margin-dilutive at ~20% CM.
A12: FY28E Margin Impact | B12: ~25.5% | C12: ~26.5% | D12: ~27.5% | E12: Fast AS growth (Oasis-type deals) can offset ~100-200bps of streaming margin gains.
A14: SGA Growth Rate | B14: 4% avg | C14: 1.5% avg | D14: 0% (flat) | E14: Direct cost lever. Restructuring + AI efficiency.
A15: FY28E Margin Impact | B15: ~24.0% | C15: ~26.5% | D15: ~28.5% | E15: SECOND BIGGEST lever after streaming. Each 1pp slower SGA growth = ~80bps margin.
A17: Contribution Margin Assumptions | B17: +/- 3pp | C17: Base | E17: If sub streaming CM is 75% instead of 78%, blended CM falls ~120bps → ~25.3% OIBDA margin.
A18: Sensitivity | B18: ~25.3% | C18: ~26.5% | D18: ~27.7% | E18: Model is moderately sensitive to CM assumptions. Directional conclusions hold across range.
A20: COMBINED: ALL UPSIDE | D20: ALL levers at upside | E20: Sub streaming 12%, physical -8%, AS +3%, SGA flat, higher CMs.
A21: FY28E Margin | D21: ~31-32% | E21: THIS is what it takes for low 30s. Everything has to go right simultaneously.
A23: COMBINED: ALL DOWNSIDE | B23: ALL levers at downside | E23: Sub streaming 6%, physical flat, AS 15%, SGA 4%.
A24: FY28E Margin | B24: ~22-23% | E24: Margin barely improves from FY25. Streaming slowdown + AS dilution + cost creep.
A27: THE ANSWER: PATH TO LOW 30s
A28: 1. STREAMING IS THE #1 LEVER. Sub streaming needs to sustain 10%+ growth to drive the mix shift that raises blended contribution margin. Your release slate work supports this for FY26-27.
A29: 2. SGA IS THE #2 LEVER. Restructuring gets you ~200bps. You need another ~200-300bps from operating leverage (revenue growing 8%+ while SGA grows 1-2%) and AI efficiency.
A30: 3. PHYSICAL DECLINE ACTUALLY HELPS. Every dollar of physical revenue that shifts to streaming improves blended CM by ~40pp on that dollar ($0.38 CM → $0.78 CM). Don't mourn physical decline.
A31: 4. ARTIST SERVICES IS THE HIDDEN HEADWIND. It's been the fastest growing line (22% FY25) but at ~20% CM, every dollar of AS growth dilutes blended margins. If AS moderates to mid-single-digit growth, that releases ~100-150bps.
A32: 5. LOW 30s = EVERYTHING RIGHT. You need sustained 10%+ streaming, physical fading, AS moderating, SGA flat-to-low-single-digit growth, AND base CM assumptions holding. It's a 3-5 year bull case, not a near-term expectation.
A33: 6. REALISTIC 3-YEAR TARGET: 26-28%. This is achievable with the release slate strength you've documented, DSP pricing tailwinds, and committed restructuring savings. That alone is a meaningful re-rating catalyst for a stock trading on ~15x OIBDA.

Sheet Sources
A1: Sources, Contribution Margin Basis & Cross-Checks
A3: MODEL ARCHITECTURE
A4: How it works | B4: Revenue Build tab: each stream has its own growth rate → projected revenue. Contribution Margin Build tab: each stream’s revenue × its estimated contribution margin = contribution profit. Sum all contribution profit, subtract fixed SGA = OIBDA. This directly shows how MIX drives margin.
A5: Key equation | B5: OIBDA Margin = Blended Contribution Margin - (SGA / Revenue). Blended CM changes as revenue mix shifts. SGA% changes with operating leverage + cost cuts.
A7: CONTRIBUTION MARGIN ESTIMATES
A8: Why these matter | B8: WMG does not disclose margin by revenue stream. CMs CALIBRATED to FY25 COGS: sum of (rev x (1-CM)) = $3,628M vs actual $3,632M. Model reconciles within $11M of actual OIBDA.
A9: Sub Streaming (47%) | B9: 47% CM = 53% variable cost. Royalties ~65% of streaming rev + ~12% other variable (A&R amort, delivery). WMG retains ~47c per streaming dollar before fixed SGA.
A10: Ad-Supported (43%) | B10: 4pp lower than sub. Ad per-stream rates lower, so royalties as % of rev slightly higher. Consistent with Spotify ad/sub ARPU differential.
A11: Physical (30%) | B11: 30% CM = 70% vc rate. Royalties (~55-60%) PLUS mfg, dist, retail margin, returns. Lowest CM in recorded music. Key: every $ of physical that shifts to streaming gains 17pp CM.
A12: Artist Services (20%) | B12: Lowest margin line. Includes concert promotion (largely pass-through with 5-15% margin), merchandising (30-40% gross margin but with significant operating overhead), and other expanded rights. The Oasis partnership drove $327M in Q4 FY25 artist services revenue — much of that is gross revenue with thin margin. The 20% assumption may even be generous.
A13: Licensing (88%) | B13: Highest margin. Catalog licensing to film/TV/ads involves minimal incremental cost — the music already exists. Legal/admin overhead is the main cost. Consistent with publishing sync margins and UMG licensing margins.
A14: Publishing Digital (72%) | B14: Writer share (~50% of publisher’s receipt) + collection society commissions + admin. Net contribution to WMG after writer share and costs is approximately 70-75%.
A15: Publishing Performance (58%) | B15: Lower than digital because collection society fees are higher for live/broadcast performance royalties, and there’s more admin overhead in tracking and collecting.
A16: Publishing Sync (82%) | B16: One-time license fees with minimal delivery cost. Writer share applies but the fee per placement is high. Cross-check: WMG publishing OIBDA margin of 27.6% (FY25) is consistent with a ~70-75% blended publishing CM after SGA allocation.
A18: CROSS-CHECKS
A19: Blended CM check | B19: At base assumptions, FY25 blended CM ≈ 66-68%. FY25 SGA% = 24.3%. OIBDA = 66.8% - 24.3% = ~22.5%. Actual = 21.5%. ~100bps gap likely explained by intersegment eliminations and rounding. Directionally correct.
A20: Segment check | B20: RM OIBDA margin (23.5% FY25) is consistent with ~67% blended RM contribution margin less ~43% SGA allocation. Publishing OIBDA margin (27.6%) is consistent with ~70% blended pub CM less ~42% SGA allocation.
A21: Sensitivity check | B21: If sub streaming CM is 75% instead of 78%, FY25 blended CM drops ~120bps to ~65.6%. Implies OIBDA margin of ~21.3% vs actual 21.5%. Very close, suggesting 78% is reasonable but could be 75-80%.
A23: SEC FILING SOURCES
A24: Revenue data | B24: FY2025 10-K (filed Nov 20, 2025). FY2024 from same 10-K comparatives. FQ1 FY2026 10-Q (filed Feb 9, 2026).
A25: Streaming breakdown | B25: MBW quarterly coverage citing WMG earnings release exhibits. Sub: $631/$622/$674/$700 (FQ1-FQ4 FY25), $721 (FQ1 FY26). Ad: $223/$203/$221/$231 (FY25), $239 (FQ1 FY26).
A26: SGA derivation | B26: Reported SGA $1,889M (10-K) less: Dep $118M (10-Q footnote), SBC $76M (OIBDA recon), Transformation $63M (OIBDA recon) = Adj Cash SGA $1,632M.
A27: Restructuring guidance | B27: 150-200bps margin improvement guided by CFO Zerza, FQ4 FY25 call, Nov 20, 2025.
