Workbook

Sheet Annual Summary
A1: WWE Live Event Box Office | Annual Summary
A2: Source: Pollstar Data Cloud, Boxoffice. Promoter: World Wrestling Entertainment. USD. Calendar years 2023 to 2026.
A4: Year | B4: Events | C4: Shows | D4: Total Gross (USD) | E4: Avg. Gross / Show (USD) | F4: Avg. Gross / Event (USD) | G4: Avg. Ticket (USD) | H4: Capacity Sold % | I4: Total Gross YoY % | J4: Avg. Gross/Show YoY % | K4: Avg. Ticket YoY %
A5: 2023 | B5: =COUNTIFS('Raw Data'!$B:$B,$A5) -> 84 | C5: =SUMIFS('Raw Data'!$E:$E,'Raw Data'!$B:$B,$A5) -> 85 | D5: =SUMIFS('Raw Data'!$N:$N,'Raw Data'!$B:$B,$A5) -> 64315187 | E5: =IF(C5=0,"",D5/C5) -> 756649.26 | F5: =IF(B5=0,"",D5/B5) -> 765656.99 | G5: =AVERAGEIFS('Raw Data'!$S:$S,'Raw Data'!$B:$B,$A5) -> 58.827024 | H5: =AVERAGEIFS('Raw Data'!$P:$P,'Raw Data'!$B:$B,$A5) -> 0.86595238 | I5: n/a | J5: n/a | K5: n/a
A6: 2024 | B6: =COUNTIFS('Raw Data'!$B:$B,$A6) -> 70 | C6: =SUMIFS('Raw Data'!$E:$E,'Raw Data'!$B:$B,$A6) -> 74 | D6: =SUMIFS('Raw Data'!$N:$N,'Raw Data'!$B:$B,$A6) -> 60018065 | E6: =IF(C6=0,"",D6/C6) -> 811054.93 | F6: =IF(B6=0,"",D6/B6) -> 857400.92 | G6: =AVERAGEIFS('Raw Data'!$S:$S,'Raw Data'!$B:$B,$A6) -> 74.969571 | H6: =AVERAGEIFS('Raw Data'!$P:$P,'Raw Data'!$B:$B,$A6) -> 0.88514286 | I6: =D6/D5-1 -> -0.06681349 | J6: =E6/E5-1 -> 0.071903423 | K6: =G6/G5-1 -> 0.27440701
A7: 2025 | B7: =COUNTIFS('Raw Data'!$B:$B,$A7) -> 51 | C7: =SUMIFS('Raw Data'!$E:$E,'Raw Data'!$B:$B,$A7) -> 52 | D7: =SUMIFS('Raw Data'!$N:$N,'Raw Data'!$B:$B,$A7) -> 87276181 | E7: =IF(C7=0,"",D7/C7) -> 1678388.1 | F7: =IF(B7=0,"",D7/B7) -> 1711297.7 | G7: =AVERAGEIFS('Raw Data'!$S:$S,'Raw Data'!$B:$B,$A7) -> 131.38882 | H7: =AVERAGEIFS('Raw Data'!$P:$P,'Raw Data'!$B:$B,$A7) -> 0.92117647 | I7: =D7/D6-1 -> 0.4541652 | J7: =E7/E6-1 -> 1.0693889 | K7: =G7/G6-1 -> 0.75256202
A8: 2026 | B8: =COUNTIFS('Raw Data'!$B:$B,$A8) -> 22 | C8: =SUMIFS('Raw Data'!$E:$E,'Raw Data'!$B:$B,$A8) -> 22 | D8: =SUMIFS('Raw Data'!$N:$N,'Raw Data'!$B:$B,$A8) -> 24423182 | E8: =IF(C8=0,"",D8/C8) -> 1110144.6 | F8: =IF(B8=0,"",D8/B8) -> 1110144.6 | G8: =AVERAGEIFS('Raw Data'!$S:$S,'Raw Data'!$B:$B,$A8) -> 112.54 | H8: =AVERAGEIFS('Raw Data'!$P:$P,'Raw Data'!$B:$B,$A8) -> 0.89636364 | I8: =D8/D7-1 -> -0.72016211 | J8: =E8/E7-1 -> -0.33856499 | K8: =G8/G7-1 -> -0.14345835
A10: Notes: 2023 YoY is not available because pre-2023 data is excluded per scope. 2026 covers Q1 to Q2 only, so its YoY figures compare a partial year against a full year and are not like-for-like.

Sheet Quarterly Summary
A1: WWE Live Event Box Office | Quarterly Summary
A2: Source: Pollstar Data Cloud, Boxoffice. USD. YoY compares each quarter to the same quarter one year earlier.
A4: Year-Qtr | B4: Events | C4: Shows | D4: Total Gross (USD) | E4: Avg. Gross / Show (USD) | F4: Avg. Ticket (USD) | G4: Capacity Sold % | H4: Total Gross YoY % | I4: Avg. Gross/Show YoY %
A5: 2023 Q1 | B5: =COUNTIFS('Raw Data'!$D:$D,$A5) -> 26 | C5: =SUMIFS('Raw Data'!$E:$E,'Raw Data'!$D:$D,$A5) -> 26 | D5: =SUMIFS('Raw Data'!$N:$N,'Raw Data'!$D:$D,$A5) -> 13643659 | E5: =IF(C5=0,"",D5/C5) -> 524756.1 | F5: =AVERAGEIFS('Raw Data'!$S:$S,'Raw Data'!$D:$D,$A5) -> 54.328846 | G5: =AVERAGEIFS('Raw Data'!$P:$P,'Raw Data'!$D:$D,$A5) -> 0.855 | H5: n/a | I5: n/a
A6: 2023 Q2 | B6: =COUNTIFS('Raw Data'!$D:$D,$A6) -> 16 | C6: =SUMIFS('Raw Data'!$E:$E,'Raw Data'!$D:$D,$A6) -> 17 | D6: =SUMIFS('Raw Data'!$N:$N,'Raw Data'!$D:$D,$A6) -> 26762178 | E6: =IF(C6=0,"",D6/C6) -> 1574245.8 | F6: =AVERAGEIFS('Raw Data'!$S:$S,'Raw Data'!$D:$D,$A6) -> 58.7575 | G6: =AVERAGEIFS('Raw Data'!$P:$P,'Raw Data'!$D:$D,$A6) -> 0.87625 | H6: n/a | I6: n/a
A7: 2023 Q3 | B7: =COUNTIFS('Raw Data'!$D:$D,$A7) -> 16 | C7: =SUMIFS('Raw Data'!$E:$E,'Raw Data'!$D:$D,$A7) -> 16 | D7: =SUMIFS('Raw Data'!$N:$N,'Raw Data'!$D:$D,$A7) -> 7888629.5 | E7: =IF(C7=0,"",D7/C7) -> 493039.34 | F7: =AVERAGEIFS('Raw Data'!$S:$S,'Raw Data'!$D:$D,$A7) -> 56.060625 | G7: =AVERAGEIFS('Raw Data'!$P:$P,'Raw Data'!$D:$D,$A7) -> 0.9 | H7: n/a | I7: n/a
A8: 2023 Q4 | B8: =COUNTIFS('Raw Data'!$D:$D,$A8) -> 26 | C8: =SUMIFS('Raw Data'!$E:$E,'Raw Data'!$D:$D,$A8) -> 26 | D8: =SUMIFS('Raw Data'!$N:$N,'Raw Data'!$D:$D,$A8) -> 16020720 | E8: =IF(C8=0,"",D8/C8) -> 616181.55 | F8: =AVERAGEIFS('Raw Data'!$S:$S,'Raw Data'!$D:$D,$A8) -> 65.070385 | G8: =AVERAGEIFS('Raw Data'!$P:$P,'Raw Data'!$D:$D,$A8) -> 0.84961538 | H8: n/a | I8: n/a
A9: 2024 Q1 | B9: =COUNTIFS('Raw Data'!$D:$D,$A9) -> 20 | C9: =SUMIFS('Raw Data'!$E:$E,'Raw Data'!$D:$D,$A9) -> 20 | D9: =SUMIFS('Raw Data'!$N:$N,'Raw Data'!$D:$D,$A9) -> 10721668 | E9: =IF(C9=0,"",D9/C9) -> 536083.42 | F9: =AVERAGEIFS('Raw Data'!$S:$S,'Raw Data'!$D:$D,$A9) -> 58.95 | G9: =AVERAGEIFS('Raw Data'!$P:$P,'Raw Data'!$D:$D,$A9) -> 0.889 | H9: =D9/D5-1 -> -0.21416471 | I9: =E9/E5-1 -> 0.021585876
A10: 2024 Q2 | B10: =COUNTIFS('Raw Data'!$D:$D,$A10) -> 14 | C10: =SUMIFS('Raw Data'!$E:$E,'Raw Data'!$D:$D,$A10) -> 18 | D10: =SUMIFS('Raw Data'!$N:$N,'Raw Data'!$D:$D,$A10) -> 21894394 | E10: =IF(C10=0,"",D10/C10) -> 1216355.2 | F10: =AVERAGEIFS('Raw Data'!$S:$S,'Raw Data'!$D:$D,$A10) -> 96.139286 | G10: =AVERAGEIFS('Raw Data'!$P:$P,'Raw Data'!$D:$D,$A10) -> 0.93928571 | H10: =D10/D6-1 -> -0.18189044 | I10: =E10/E6-1 -> -0.22734097
A11: 2024 Q3 | B11: =COUNTIFS('Raw Data'!$D:$D,$A11) -> 16 | C11: =SUMIFS('Raw Data'!$E:$E,'Raw Data'!$D:$D,$A11) -> 16 | D11: =SUMIFS('Raw Data'!$N:$N,'Raw Data'!$D:$D,$A11) -> 11138944 | E11: =IF(C11=0,"",D11/C11) -> 696184 | F11: =AVERAGEIFS('Raw Data'!$S:$S,'Raw Data'!$D:$D,$A11) -> 70.989375 | G11: =AVERAGEIFS('Raw Data'!$P:$P,'Raw Data'!$D:$D,$A11) -> 0.863125 | H11: =D11/D7-1 -> 0.41202525 | I11: =E11/E7-1 -> 0.41202525
A12: 2024 Q4 | B12: =COUNTIFS('Raw Data'!$D:$D,$A12) -> 20 | C12: =SUMIFS('Raw Data'!$E:$E,'Raw Data'!$D:$D,$A12) -> 20 | D12: =SUMIFS('Raw Data'!$N:$N,'Raw Data'!$D:$D,$A12) -> 16263058 | E12: =IF(C12=0,"",D12/C12) -> 813152.91 | F12: =AVERAGEIFS('Raw Data'!$S:$S,'Raw Data'!$D:$D,$A12) -> 79.3545 | G12: =AVERAGEIFS('Raw Data'!$P:$P,'Raw Data'!$D:$D,$A12) -> 0.861 | H12: =D12/D8-1 -> 0.015126528 | I12: =E12/E8-1 -> 0.31966449
A13: 2025 Q1 | B13: =COUNTIFS('Raw Data'!$D:$D,$A13) -> 14 | C13: =SUMIFS('Raw Data'!$E:$E,'Raw Data'!$D:$D,$A13) -> 14 | D13: =SUMIFS('Raw Data'!$N:$N,'Raw Data'!$D:$D,$A13) -> 20953480 | E13: =IF(C13=0,"",D13/C13) -> 1496677.2 | F13: =AVERAGEIFS('Raw Data'!$S:$S,'Raw Data'!$D:$D,$A13) -> 112.83286 | G13: =AVERAGEIFS('Raw Data'!$P:$P,'Raw Data'!$D:$D,$A13) -> 0.96071429 | H13: =D13/D9-1 -> 0.95431156 | I13: =E13/E9-1 -> 1.7918737
A14: 2025 Q2 | B14: =COUNTIFS('Raw Data'!$D:$D,$A14) -> 13 | C14: =SUMIFS('Raw Data'!$E:$E,'Raw Data'!$D:$D,$A14) -> 13 | D14: =SUMIFS('Raw Data'!$N:$N,'Raw Data'!$D:$D,$A14) -> 23617202 | E14: =IF(C14=0,"",D14/C14) -> 1816707.8 | F14: =AVERAGEIFS('Raw Data'!$S:$S,'Raw Data'!$D:$D,$A14) -> 138.63692 | G14: =AVERAGEIFS('Raw Data'!$P:$P,'Raw Data'!$D:$D,$A14) -> 0.90923077 | H14: =D14/D10-1 -> 0.078687142 | I14: =E14/E10-1 -> 0.49356681
A15: 2025 Q3 | B15: =COUNTIFS('Raw Data'!$D:$D,$A15) -> 15 | C15: =SUMIFS('Raw Data'!$E:$E,'Raw Data'!$D:$D,$A15) -> 16 | D15: =SUMIFS('Raw Data'!$N:$N,'Raw Data'!$D:$D,$A15) -> 23319938 | E15: =IF(C15=0,"",D15/C15) -> 1457496.1 | F15: =AVERAGEIFS('Raw Data'!$S:$S,'Raw Data'!$D:$D,$A15) -> 126.41533 | G15: =AVERAGEIFS('Raw Data'!$P:$P,'Raw Data'!$D:$D,$A15) -> 0.918 | H15: =D15/D11-1 -> 1.0935502 | I15: =E15/E11-1 -> 1.0935502
A16: 2025 Q4 | B16: =COUNTIFS('Raw Data'!$D:$D,$A16) -> 9 | C16: =SUMIFS('Raw Data'!$E:$E,'Raw Data'!$D:$D,$A16) -> 9 | D16: =SUMIFS('Raw Data'!$N:$N,'Raw Data'!$D:$D,$A16) -> 19385561 | E16: =IF(C16=0,"",D16/C16) -> 2153951.2 | F16: =AVERAGEIFS('Raw Data'!$S:$S,'Raw Data'!$D:$D,$A16) -> 158.07333 | G16: =AVERAGEIFS('Raw Data'!$P:$P,'Raw Data'!$D:$D,$A16) -> 0.88222222 | H16: =D16/D12-1 -> 0.19199974 | I16: =E16/E12-1 -> 1.6488883
A17: 2026 Q1 | B17: =COUNTIFS('Raw Data'!$D:$D,$A17) -> 13 | C17: =SUMIFS('Raw Data'!$E:$E,'Raw Data'!$D:$D,$A17) -> 13 | D17: =SUMIFS('Raw Data'!$N:$N,'Raw Data'!$D:$D,$A17) -> 14032828 | E17: =IF(C17=0,"",D17/C17) -> 1079448.3 | F17: =AVERAGEIFS('Raw Data'!$S:$S,'Raw Data'!$D:$D,$A17) -> 104.37077 | G17: =AVERAGEIFS('Raw Data'!$P:$P,'Raw Data'!$D:$D,$A17) -> 0.90692308 | H17: =D17/D13-1 -> -0.33028656 | I17: =E17/E13-1 -> -0.27877014
A18: 2026 Q2 | B18: =COUNTIFS('Raw Data'!$D:$D,$A18) -> 9 | C18: =SUMIFS('Raw Data'!$E:$E,'Raw Data'!$D:$D,$A18) -> 9 | D18: =SUMIFS('Raw Data'!$N:$N,'Raw Data'!$D:$D,$A18) -> 10390354 | E18: =IF(C18=0,"",D18/C18) -> 1154483.8 | F18: =AVERAGEIFS('Raw Data'!$S:$S,'Raw Data'!$D:$D,$A18) -> 124.34 | G18: =AVERAGEIFS('Raw Data'!$P:$P,'Raw Data'!$D:$D,$A18) -> 0.88111111 | H18: =D18/D14-1 -> -0.56005141 | I18: =E18/E14-1 -> -0.36451871
A20: Notes: YoY is blank for all 2023 quarters (no 2022 comparison in scope). Total Gross = Avg. Gross per Show multiplied by Number of Shows, summed across engagements.

Sheet Exhibit 4 - Like-for-Like
A1: Exhibit 4 | Like-for-Like Same-Venue Pricing, 2025 to 2026
A2: Latest year-over-year cut. Each venue is compared to itself in the same quarter (Q1 or Q2), 2025 vs 2026. Same venue, same quarter, one year apart, so the comparison is fully like-for-like.
A4: Venue | B4: City | C4: Qtr | D4: Window | E4: Gap | F4: First Avg Tkt | G4: Latest Avg Tkt | H4: Avg Tkt Δ | I4: First Top Tkt | J4: Latest Top Tkt | K4: Top Tkt Δ | L4: First Gross/Show | M4: Latest Gross/Show | N4: Gross/Show Δ
A5: KeyBank Center | B5: Buffalo | C5: Q1 | D5: 2025–2026 | E5: 1y | F5: 90.91 | G5: 120.93 | H5: =G5/F5-1 -> 0.3302167 | I5: 400 | J5: 400 | K5: =J5/I5-1 -> 0 | L5: 1170770 | M5: 902970 | N5: =M5/L5-1 -> -0.22873835
A6: CHI Health Center Omaha | B6: Omaha | C6: Q2 | D6: 2025–2026 | E6: 1y | F6: 81.04 | G6: 100.23 | H6: =G6/F6-1 -> 0.23679664 | I6: 250 | J6: 400 | K6: =J6/I6-1 -> 0.6 | L6: 881850 | M6: 846384.17 | N6: =M6/L6-1 -> -0.040217531
A7: Spectrum Center | B7: Charlotte | C7: Q1 | D7: 2025–2026 | E7: 1y | F7: 88.45 | G7: 100.77 | H7: =G7/F7-1 -> 0.13928773 | I7: 303.5 | J7: 100.77 | K7: =J7/I7-1 -> -0.66797364 | L7: 1213566 | M7: 893495.6 | N7: =M7/L7-1 -> -0.26374371
A8: Frost Bank Center | B8: San Antonio | C8: Q1 | D8: 2025–2026 | E8: 1y | F8: 105.4 | G8: 117.83 | H8: =G8/F8-1 -> 0.11793169 | I8: 35 | J8: 500 | K8: =J8/I8-1 -> 13.285714 | L8: 1615820 | M8: 1665318 | N8: =M8/L8-1 -> 0.030633363
A9: American Airlines Center | B9: Dallas | C9: Q1 | D9: 2025–2026 | E9: 1y | F9: 109.7 | G9: 117.43 | H9: =G9/F9-1 -> 0.070464904 | I9: 400 | J9: 800 | K9: =J9/I9-1 -> 1 | L9: 1440685 | M9: 1190420 | N9: =M9/L9-1 -> -0.1737125
A10: Golden 1 Center | B10: Sacramento | C10: Q2 | D10: 2025–2026 | E10: 1y | F10: 126.32 | G10: 135.07 | H10: =G10/F10-1 -> 0.069268524 | I10: 500 | J10: 800 | K10: =J10/I10-1 -> 0.6 | L10: 1697100 | M10: 1484719 | N10: =M10/L10-1 -> -0.12514347
A11: State Farm Arena | B11: Atlanta | C11: Q1 | D11: 2025–2026 | E11: 1y | F11: 101.23 | G11: 105.42 | H11: =G11/F11-1 -> 0.041390892 | I11: 250 | J11: 750 | K11: =J11/I11-1 -> 2 | L11: 1299337.5 | M11: 1280370 | N11: =M11/L11-1 -> -0.014597824
A12: BOK Center | B12: Tulsa | C12: Q2 | D12: 2025–2026 | E12: 1y | F12: 94.5 | G12: 92.15 | H12: =G12/F12-1 -> -0.024867725 | I12: 300 | J12: 400 | K12: =J12/I12-1 -> 0.33333333 | L12: 780180 | M12: 518620.98 | N12: =M12/L12-1 -> -0.33525471
A13: Dickies Arena | B13: Fort Worth | C13: Q2 | D13: 2025–2026 | E13: 1y | F13: 130.31 | G13: 107.98 | H13: =G13/F13-1 -> -0.1713606 | I13: 554 | J13: 619 | K13: =J13/I13-1 -> 0.11732852 | L13: 1493662 | M13: 1069191 | N13: =M13/L13-1 -> -0.28418143
A14: T-Mobile Arena | B14: Las Vegas | C14: Q2 | D14: 2025–2026 | E14: 1y | F14: 207.92 | G14: 140.35 | H14: =G14/F14-1 -> -0.32498076 | I14: 1368.5 | J14: 1641 | K14: =J14/I14-1 -> 0.19912313 | L14: 3480131 | M14: 1963923 | N14: =M14/L14-1 -> -0.43567555
A15: MEDIAN | H15: =MEDIAN(H5:H14) -> 0.069866714 | K15: =MEDIAN(K5:K14) -> 0.46666667 | N15: =MEDIAN(N5:N14) -> -0.20122543
A16: SHARE POSITIVE | H16: =COUNTIF(H5:H14,">0")/COUNT(H5:H14) -> 0.7 | K16: =COUNTIF(K5:K14,">0")/COUNT(K5:K14) -> 0.8 | N16: =COUNTIF(N5:N14,">0")/COUNT(N5:N14) -> 0.1
A18: Takeaway: on the latest 2025 to 2026 like-for-like, ticket pricing held up. The median venue raised its average ticket and its top ticket, with most venues positive on both. Gross per show declined at most venues over the same window, driven by about a fifth fewer tickets sold per show (smaller configurations and event-type mix at several arenas, with some genuine capacity softening). Read this as price per seat staying firm into 2026, not as box-office growth.
A21: Method notes: blue cells are sourced Pollstar per-engagement averages. Source: Pollstar Data Cloud, Boxoffice, Promoter = World Wrestling Entertainment, accessed Jun 2026. Top Tkt = Ticket Price Max. Sample is 10 venue comparisons; each point is a single engagement, so individual rows are card and configuration dependent. The Frost Bank top-ticket figure reflects a premium tier added in 2026 and is an outlier; the median and share-positive lines, not any single row, carry the read. 2026 covers Q1 to Q2.

Sheet Raw Data
A1: Event Date | B1: Year | C1: Quarter | D1: Year-Qtr | E1: Shows | F1: Headliner | G1: Support | H1: Venue | I1: City | J1: State | K1: Country | L1: Avg. Tickets Sold | M1: Avg. Gross / Show (USD) | N1: Engagement Gross (USD) | O1: Avg. Capacity | P1: Capacity Sold % | Q1: Min Ticket (USD) | R1: Max Ticket (USD) | S1: Avg. Ticket (USD)
A2: 44928 | B2: =YEAR(A2) -> 2023 | C2: ="Q"&ROUNDUP(MONTH(A2)/3,0) -> Q1 | D2: =B2&" Q"&ROUNDUP(MONTH(A2)/3,0) -> 2023 Q1 | E2: 1 | F2: World Wrestling Entertainment | G2: Matt Riddle, Bobby Lashley, Seth Rollins, Bianca Belair | H2: Bridgestone Arena | I2: Nashville | J2: Tennessee | K2: United States | L2: 9762 | M2: 448873.15 | N2: =E2*M2 -> 448873.15 | O2: 10452 | P2: 0.93 | Q2: 24.7 | R2: 137 | S2: 45.98
A3: 44932 | B3: =YEAR(A3) -> 2023 | C3: ="Q"&ROUNDUP(MONTH(A3)/3,0) -> Q1 | D3: =B3&" Q"&ROUNDUP(MONTH(A3)/3,0) -> 2023 Q1 | E3: 1 | F3: World Wrestling Entertainment | G3: Drew Mcintyre, The New Day, The Usos, Liv Morgan, Sami Zayn | H3: FedExForum | I3: Memphis | J3: Tennessee | K3: United States | L3: 9083 | M3: 437038.5 | N3: =E3*M3 -> 437038.5 | O3: 12619 | P3: 0.71 | Q3: 20 | R3: 115 | S3: 48.12
A4: 44935 | B4: =YEAR(A4) -> 2023 | C4: ="Q"&ROUNDUP(MONTH(A4)/3,0) -> Q1 | D4: =B4&" Q"&ROUNDUP(MONTH(A4)/3,0) -> 2023 Q1 | E4: 1 | F4: World Wrestling Entertainment | G4: Kevin Owens, Roman Reigns, Baron Corbin, Jey Uso | H4: Legacy Arena at the BJCC | I4: Birmingham | J4: Alabama | K4: United States | L4: 7094 | M4: 310592 | N4: =E4*M4 -> 310592 | O4: 7136 | P4: 0.99 | Q4: 20 | R4: 110 | S4: 43.78
A5: 44946 | B5: =YEAR(A5) -> 2023 | C5: ="Q"&ROUNDUP(MONTH(A5)/3,0) -> Q1 | D5: =B5&" Q"&ROUNDUP(MONTH(A5)/3,0) -> 2023 Q1 | E5: 1 | F5: World Wrestling Entertainment | H5: Little Caesars Arena | I5: Detroit | J5: Michigan | K5: United States | L5: 13466 | M5: 625642 | N5: =E5*M5 -> 625642 | O5: 14000 | P5: 0.96 | Q5: 25 | R5: 120 | S5: 46.46
A6: 44949 | B6: =YEAR(A6) -> 2023 | C6: ="Q"&ROUNDUP(MONTH(A6)/3,0) -> Q1 | D6: =B6&" Q"&ROUNDUP(MONTH(A6)/3,0) -> 2023 Q1 | E6: 1 | F6: World Wrestling Entertainment | H6: Wells Fargo Center | I6: Philadelphia | J6: Pennsylvania | K6: United States | L6: 13528 | M6: 1181835 | N6: =E6*M6 -> 1181835 | O6: 13528 | P6: 1 | Q6: 20 | R6: 500 | S6: 87.36
A7: 44956 | B7: =YEAR(A7) -> 2023 | C7: ="Q"&ROUNDUP(MONTH(A7)/3,0) -> Q1 | D7: =B7&" Q"&ROUNDUP(MONTH(A7)/3,0) -> 2023 Q1 | E7: 1 | F7: World Wrestling Entertainment | G7: Matt Riddle, Bobby Lashley, Seth Rollins, Bianca Belair | H7: BOK Center | I7: Tulsa | J7: Oklahoma | K7: United States | L7: 5734 | M7: 289938.5 | N7: =E7*M7 -> 289938.5 | O7: 11992 | P7: 0.47 | Q7: 24 | R7: 114 | S7: 50.56
A8: 44961 | B8: =YEAR(A8) -> 2023 | C8: ="Q"&ROUNDUP(MONTH(A8)/3,0) -> Q1 | D8: =B8&" Q"&ROUNDUP(MONTH(A8)/3,0) -> 2023 Q1 | E8: 1 | F8: World Wrestling Entertainment | G8: Bron Breakker, Grayson Waller | H8: Spectrum Center | I8: Charlotte | J8: North Carolina | K8: United States | L8: 5462 | M8: 245698.98 | N8: =E8*M8 -> 245698.98 | O8: 6008 | P8: 0.9 | Q8: 20 | R8: 150 | S8: 44.98
A9: 44963 | B9: =YEAR(A9) -> 2023 | C9: ="Q"&ROUNDUP(MONTH(A9)/3,0) -> Q1 | D9: =B9&" Q"&ROUNDUP(MONTH(A9)/3,0) -> 2023 Q1 | E9: 1 | F9: World Wrestling Entertainment | G9: Seth Rollins, Austin Theory, Bianca Belair, Becky Lynch | H9: Amway Center | I9: Orlando | J9: Florida | K9: United States | L9: 9453 | M9: 414498.5 | N9: =E9*M9 -> 414498.5 | O9: 11411 | P9: 0.82 | Q9: 20 | R9: 120 | S9: 43.85
A10: 44967 | B10: =YEAR(A10) -> 2023 | C10: ="Q"&ROUNDUP(MONTH(A10)/3,0) -> Q1 | D10: =B10&" Q"&ROUNDUP(MONTH(A10)/3,0) -> 2023 Q1 | E10: 1 | F10: World Wrestling Entertainment | H10: Mohegan Sun Arena | I10: Uncasville | J10: Connecticut | K10: United States | L10: 5752 | M10: 311110 | N10: =E10*M10 -> 311110 | O10: 5752 | P10: 1 | Q10: 20 | R10: 130 | S10: 54.09
A11: 44970 | B11: =YEAR(A11) -> 2023 | C11: ="Q"&ROUNDUP(MONTH(A11)/3,0) -> Q1 | D11: =B11&" Q"&ROUNDUP(MONTH(A11)/3,0) -> 2023 Q1 | E11: 1 | F11: World Wrestling Entertainment | G11: Seth Rollins, Austin Theory, Bobby Lashley, Bianca Belair | H11: Barclays Center | I11: Brooklyn | J11: New York | K11: United States | L11: 11739 | M11: 664282.5 | N11: =E11*M11 -> 664282.5 | O11: 13215 | P11: 0.88 | Q11: 20 | R11: 150 | S11: 56.59
A12: 44974 | B12: =YEAR(A12) -> 2023 | C12: ="Q"&ROUNDUP(MONTH(A12)/3,0) -> Q1 | D12: =B12&" Q"&ROUNDUP(MONTH(A12)/3,0) -> 2023 Q1 | E12: 1 | F12: World Wrestling Entertainment | G12: Asuka, Liv Morgan, Ronda Rousey, Sami Zayn | H12: Bell Centre | I12: Montreal | J12: Quebec | K12: Canada | L12: 11744 | M12: 649680.63 | N12: =E12*M12 -> 649680.63 | O12: 11746 | P12: 0.99 | Q12: 55.32 | R12: 55.32 | S12: 55.32
A13: 44975 | B13: =YEAR(A13) -> 2023 | C13: ="Q"&ROUNDUP(MONTH(A13)/3,0) -> Q1 | D13: =B13&" Q"&ROUNDUP(MONTH(A13)/3,0) -> 2023 Q1 | E13: 1 | F13: World Wrestling Entertainment | G13: Asuka, Liv Morgan, Brock Lesnar, Bobby Lashley | H13: Bell Centre | I13: Montreal | J13: Quebec | K13: Canada | L13: 13807 | M13: 997636.68 | N13: =E13*M13 -> 997636.68 | O13: 13809 | P13: 0.99 | Q13: 72.25 | R13: 72.25 | S13: 72.26
A14: 44977 | B14: =YEAR(A14) -> 2023 | C14: ="Q"&ROUNDUP(MONTH(A14)/3,0) -> Q1 | D14: =B14&" Q"&ROUNDUP(MONTH(A14)/3,0) -> 2023 Q1 | E14: 1 | F14: World Wrestling Entertainment | H14: Canadian Tire Centre | I14: Ottawa | J14: Ontario | K14: Canada | L14: 7663 | M14: 312662.09 | N14: =E14*M14 -> 312662.09 | O14: 8604 | P14: 0.89 | Q14: 18.55 | R14: 92.74 | S14: 40.8
A15: 44981 | B15: =YEAR(A15) -> 2023 | C15: ="Q"&ROUNDUP(MONTH(A15)/3,0) -> Q1 | D15: =B15&" Q"&ROUNDUP(MONTH(A15)/3,0) -> 2023 Q1 | E15: 1 | F15: World Wrestling Entertainment | G15: Charlotte Flair, Rhea Ripley, Rey Mysterio, Karrion Kross, Braun Strowmann, Ricochet | H15: Ford Center | I15: Evansville | J15: Indiana | K15: United States | L15: 7530 | M15: 334188 | N15: =E15*M15 -> 334188 | O15: 7530 | P15: 1 | Q15: 25 | R15: 115 | S15: 44.38
A16: 44983 | B16: =YEAR(A16) -> 2023 | C16: ="Q"&ROUNDUP(MONTH(A16)/3,0) -> Q1 | D16: =B16&" Q"&ROUNDUP(MONTH(A16)/3,0) -> 2023 Q1 | E16: 1 | F16: World Wrestling Entertainment | H16: BMO Harris Bank Center | I16: Rockford | J16: Illinois | K16: United States | L16: 4431 | M16: 231642.45 | N16: =E16*M16 -> 231642.45 | O16: 7307 | P16: 0.6 | Q16: 20 | R16: 110 | S16: 52.28
A17: 44988 | B17: =YEAR(A17) -> 2023 | C17: ="Q"&ROUNDUP(MONTH(A17)/3,0) -> Q1 | D17: =B17&" Q"&ROUNDUP(MONTH(A17)/3,0) -> 2023 Q1 | E17: 1 | F17: World Wrestling Entertainment | G17: Braun Strowmann, Bray Wyatt, Gunther, Ronda Rousey | H17: Capital One Arena | I17: Washington | J17: District of Columbia | K17: United States | L17: 11998 | M17: 727358.25 | N17: =E17*M17 -> 727358.25 | O17: 12676 | P17: 0.94 | Q17: 20 | R17: 125 | S17: 60.62
A18: 44989 | B18: =YEAR(A18) -> 2023 | C18: ="Q"&ROUNDUP(MONTH(A18)/3,0) -> Q1 | D18: =B18&" Q"&ROUNDUP(MONTH(A18)/3,0) -> 2023 Q1 | E18: 1 | F18: World Wrestling Entertainment | G18: Roman Reigns, Sami Zayn, Braun Strowmann, Drew Mcintyre | H18: Coca-Cola Coliseum | I18: Toronto | J18: Ontario | K18: Canada | L18: 7294 | M18: 349709.25 | N18: =E18*M18 -> 349709.25 | O18: 7294 | P18: 1 | Q18: 18.36 | R18: 117.5 | S18: 47.94
A19: 44991 | B19: =YEAR(A19) -> 2023 | C19: ="Q"&ROUNDUP(MONTH(A19)/3,0) -> Q1 | D19: =B19&" Q"&ROUNDUP(MONTH(A19)/3,0) -> 2023 Q1 | E19: 1 | F19: World Wrestling Entertainment | G19: John Cena, Kevin Owens, Dolph Ziggler, Austin Theory | H19: TD Garden | I19: Boston | J19: Massachusetts | K19: United States | L19: 12239 | M19: 884269 | N19: =E19*M19 -> 884269 | O19: 13169 | P19: 0.92 | Q19: 20 | R19: 150 | S19: 72.25
A20: 44995 | B20: =YEAR(A20) -> 2023 | C20: ="Q"&ROUNDUP(MONTH(A20)/3,0) -> Q1 | D20: =B20&" Q"&ROUNDUP(MONTH(A20)/3,0) -> 2023 Q1 | E20: 1 | F20: World Wrestling Entertainment | G20: Alexa Bliss, The Usos | H20: PPG Paints Arena | I20: Pittsburgh | J20: Pennsylvania | K20: United States | L20: 9019 | M20: 457689.1 | N20: =E20*M20 -> 457689.1 | O20: 13143 | P20: 0.68 | Q20: 20 | R20: 125 | S20: 50.75
A21: 44997 | B21: =YEAR(A21) -> 2023 | C21: ="Q"&ROUNDUP(MONTH(A21)/3,0) -> Q1 | D21: =B21&" Q"&ROUNDUP(MONTH(A21)/3,0) -> 2023 Q1 | E21: 1 | F21: World Wrestling Entertainment | G21: Drew Mcintyre, Braun Strowmann, Charlotte Flair, Sami Zayn | H21: MGM Grand Garden Arena | I21: Las Vegas | J21: Nevada | K21: United States | L21: 10529 | M21: 685715 | N21: =E21*M21 -> 685715 | O21: 13718 | P21: 0.76 | Q21: 26 | R21: 206 | S21: 65.13
A22: 44997 | B22: =YEAR(A22) -> 2023 | C22: ="Q"&ROUNDUP(MONTH(A22)/3,0) -> Q1 | D22: =B22&" Q"&ROUNDUP(MONTH(A22)/3,0) -> 2023 Q1 | E22: 1 | F22: World Wrestling Entertainment | H22: Madison Square Garden | I22: New York | J22: New York | K22: United States | L22: 10529 | M22: 685715 | N22: =E22*M22 -> 685715 | O22: 13718 | P22: 0.76 | Q22: 26 | R22: 206 | S22: 65.13
A23: 45003 | B23: =YEAR(A23) -> 2023 | C23: ="Q"&ROUNDUP(MONTH(A23)/3,0) -> Q1 | D23: =B23&" Q"&ROUNDUP(MONTH(A23)/3,0) -> 2023 Q1 | E23: 1 | F23: World Wrestling Entertainment | H23: Fiserv Forum | I23: Milwaukee | J23: Wisconsin | K23: United States | L23: 5953 | M23: 276757 | N23: =E23*M23 -> 276757 | O23: 11546 | P23: 0.51 | Q23: 30 | R23: 115 | S23: 46.49
A24: 45009 | B24: =YEAR(A24) -> 2023 | C24: ="Q"&ROUNDUP(MONTH(A24)/3,0) -> Q1 | D24: =B24&" Q"&ROUNDUP(MONTH(A24)/3,0) -> 2023 Q1 | E24: 1 | F24: World Wrestling Entertainment | G24: Cody Rhodes, Kevin Owens, Sami Zayn, Roman Reigns | H24: MGM Grand Garden Arena | I24: Las Vegas | J24: Nevada | K24: United States | L24: 9409 | M24: 439268 | N24: =E24*M24 -> 439268 | O24: 11088 | P24: 0.84 | Q24: 25.8 | R24: 140.25 | S24: 46.69
A25: 45009 | B25: =YEAR(A25) -> 2023 | C25: ="Q"&ROUNDUP(MONTH(A25)/3,0) -> Q1 | D25: =B25&" Q"&ROUNDUP(MONTH(A25)/3,0) -> 2023 Q1 | E25: 1 | F25: World Wrestling Entertainment | H25: BMO Harris Bank Center | I25: Rockford | J25: Illinois | K25: United States | L25: 5206 | M25: 285881 | N25: =E25*M25 -> 285881 | O25: 7306 | P25: 0.71 | Q25: 20 | R25: 115 | S25: 54.91
A26: 45012 | B26: =YEAR(A26) -> 2023 | C26: ="Q"&ROUNDUP(MONTH(A26)/3,0) -> Q1 | D26: =B26&" Q"&ROUNDUP(MONTH(A26)/3,0) -> 2023 Q1 | E26: 1 | F26: World Wrestling Entertainment | G26: "Stone Cold" Steve Austin, Triple H, Chris Jericho, Randy Orton | H26: Footprint Center | I26: Phoenix | J26: Arizona | K26: United States | L26: 10857 | M26: 572538 | N26: =E26*M26 -> 572538 | O26: 11001 | P26: 0.98 | Q26: 20 | R26: 500 | S26: 52.73
A27: 45016 | B27: =YEAR(A27) -> 2023 | C27: ="Q"&ROUNDUP(MONTH(A27)/3,0) -> Q1 | D27: =B27&" Q"&ROUNDUP(MONTH(A27)/3,0) -> 2023 Q1 | E27: 1 | F27: World Wrestling Entertainment | H27: Crypto.com Arena | I27: Los Angeles | J27: California | K27: United States | L27: 13050 | M27: 823440 | N27: =E27*M27 -> 823440 | O27: 13050 | P27: 1 | Q27: 25.9 | R27: 310.5 | S27: 63.1
A28: 45017 | B28: =YEAR(A28) -> 2023 | C28: ="Q"&ROUNDUP(MONTH(A28)/3,0) -> Q2 | D28: =B28&" Q"&ROUNDUP(MONTH(A28)/3,0) -> 2023 Q2 | E28: 1 | F28: World Wrestling Entertainment | H28: Crypto.com Arena | I28: Los Angeles | J28: California | K28: United States | L28: 7816 | M28: 307923 | N28: =E28*M28 -> 307923 | O28: 8989 | P28: 0.86 | Q28: 20.7 | R28: 103.5 | S28: 39.4
A29: 45017 | B29: =YEAR(A29) -> 2023 | C29: ="Q"&ROUNDUP(MONTH(A29)/3,0) -> Q2 | D29: =B29&" Q"&ROUNDUP(MONTH(A29)/3,0) -> 2023 Q2 | E29: 2 | F29: World Wrestling Entertainment | G29: Roman Reigns, Cody Rhodes, Asuka, Bianca Belair, Charlotte Flair, Rhea Ripley | H29: SoFi Stadium | I29: Inglewood | J29: California | K29: United States | L29: 68397 | M29: 9874535.5 | N29: =E29*M29 -> 19749071 | O29: 73252 | P29: 0.93 | Q29: 25 | R29: 5000 | S29: 144.37
A30: 45019 | B30: =YEAR(A30) -> 2023 | C30: ="Q"&ROUNDUP(MONTH(A30)/3,0) -> Q2 | D30: =B30&" Q"&ROUNDUP(MONTH(A30)/3,0) -> 2023 Q2 | E30: 1 | F30: World Wrestling Entertainment | H30: Crypto.com Arena | I30: Los Angeles | J30: California | K30: United States | L30: 13616 | M30: 920190 | N30: =E30*M30 -> 920190 | O30: 13616 | P30: 1 | Q30: 25.9 | R30: 310.5 | S30: 67.58
A31: 45023 | B31: =YEAR(A31) -> 2023 | C31: ="Q"&ROUNDUP(MONTH(A31)/3,0) -> Q2 | D31: =B31&" Q"&ROUNDUP(MONTH(A31)/3,0) -> 2023 Q2 | E31: 1 | F31: World Wrestling Entertainment | G31: Kevin Owens, Drew Mcintyre, Xavier Woods, Braun Strowmann, The Usos | H31: Moda Center | I31: Portland | J31: Oregon | K31: United States | L31: 9314 | M31: 482774 | N31: =E31*M31 -> 482774 | O31: 12071 | P31: 0.77 | Q31: 20 | R31: 110 | S31: 51.83
A32: 45026 | B32: =YEAR(A32) -> 2023 | C32: ="Q"&ROUNDUP(MONTH(A32)/3,0) -> Q2 | D32: =B32&" Q"&ROUNDUP(MONTH(A32)/3,0) -> 2023 Q2 | E32: 1 | F32: World Wrestling Entertainment | G32: Becky Lynch, Seth Rollins, Bianca Belair, Bobby Lashley, Kevin Ownes | H32: Climate Pledge Arena | I32: Seattle | J32: Washington | K32: United States | L32: 9906 | M32: 579150.5 | N32: =E32*M32 -> 579150.5 | O32: 10074 | P32: 0.98 | Q32: 25.5 | R32: 130.5 | S32: 58.46
A33: 45033 | B33: =YEAR(A33) -> 2023 | C33: ="Q"&ROUNDUP(MONTH(A33)/3,0) -> Q2 | D33: =B33&" Q"&ROUNDUP(MONTH(A33)/3,0) -> 2023 Q2 | E33: 1 | F33: World Wrestling Entertainment | G33: Brock Lesnar, Bianca Belair, Cody Rhodes, Austin Theory | H33: Simmons Bank Arena | I33: North Little Rock | J33: Arkansas | K33: United States | L33: 7640 | M33: 384749 | N33: =E33*M33 -> 384749 | O33: 12000 | P33: 0.63 | Q33: 24 | R33: 124 | S33: 50.36
A34: 45040 | B34: =YEAR(A34) -> 2023 | C34: ="Q"&ROUNDUP(MONTH(A34)/3,0) -> Q2 | D34: =B34&" Q"&ROUNDUP(MONTH(A34)/3,0) -> 2023 Q2 | E34: 1 | F34: World Wrestling Entertainment | G34: Damian Priest, Rey Mysterio, Cody Rhodes, Finn Balor | H34: Allstate Arena | I34: Rosemont | J34: Illinois | K34: United States | L34: 12446 | M34: 619116.5 | N34: =E34*M34 -> 619116.5 | O34: 12446 | P34: 1 | Q34: 20 | R34: 150 | S34: 49.74
A35: 45047 | B35: =YEAR(A35) -> 2023 | C35: ="Q"&ROUNDUP(MONTH(A35)/3,0) -> Q2 | D35: =B35&" Q"&ROUNDUP(MONTH(A35)/3,0) -> 2023 Q2 | E35: 1 | F35: World Wrestling Entertainment | G35: Cody Rhodes, Brock Lesnar, Seth Rollins, Bianca Belair, Becky Lynch | H35: Dickies Arena | I35: Fort Worth | J35: Texas | K35: United States | L35: 11199 | M35: 506369 | N35: =E35*M35 -> 506369 | O35: 11457 | P35: 0.97 | Q35: 24 | R35: 129 | S35: 45.22
A36: 45057 | B36: =YEAR(A36) -> 2023 | C36: ="Q"&ROUNDUP(MONTH(A36)/3,0) -> Q2 | D36: =B36&" Q"&ROUNDUP(MONTH(A36)/3,0) -> 2023 Q2 | E36: 1 | F36: World Wrestling Entertainment | H36: Thompson-Boling Arena | I36: Knoxville | J36: Tennessee | K36: United States | L36: 9379 | M36: 495462.5 | N36: =E36*M36 -> 495462.5 | O36: 9885 | P36: 0.94 | Q36: 20 | R36: 130 | S36: 52.83
A37: 45058 | B37: =YEAR(A37) -> 2023 | C37: ="Q"&ROUNDUP(MONTH(A37)/3,0) -> Q2 | D37: =B37&" Q"&ROUNDUP(MONTH(A37)/3,0) -> 2023 Q2 | E37: 1 | F37: World Wrestling Entertainment | H37: Thompson-Boling Arena | I37: Knoxville | J37: Tennessee | K37: United States | L37: 9379 | M37: 528902.5 | N37: =E37*M37 -> 528902.5 | O37: 9885 | P37: 0.94 | Q37: 20 | R37: 130 | S37: 56.39
A38: 45079 | B38: =YEAR(A38) -> 2023 | C38: ="Q"&ROUNDUP(MONTH(A38)/3,0) -> Q2 | D38: =B38&" Q"&ROUNDUP(MONTH(A38)/3,0) -> 2023 Q2 | E38: 1 | F38: World Wrestling Entertainment | G38: Zelina Vega, Lacey Evans, Bianca Belair, The Usos | H38: Mohegan Sun Arena At Casey Plaza | I38: Wilkes-Barre | J38: Pennsylvania | K38: United States | L38: 6828 | M38: 372623 | N38: =E38*M38 -> 372623 | O38: 6828 | P38: 1 | Q38: 24.5 | R38: 139.5 | S38: 54.57
A39: 45081 | B39: =YEAR(A39) -> 2023 | C39: ="Q"&ROUNDUP(MONTH(A39)/3,0) -> Q2 | D39: =B39&" Q"&ROUNDUP(MONTH(A39)/3,0) -> 2023 Q2 | E39: 1 | F39: World Wrestling Entertainment | H39: SNHU Arena | I39: Manchester | J39: New Hampshire | K39: United States | L39: 4861 | M39: 278707 | N39: =E39*M39 -> 278707 | O39: 5000 | P39: 0.97 | Q39: 25 | R39: 115 | S39: 57.34
A40: 45093 | B40: =YEAR(A40) -> 2023 | C40: ="Q"&ROUNDUP(MONTH(A40)/3,0) -> Q2 | D40: =B40&" Q"&ROUNDUP(MONTH(A40)/3,0) -> 2023 Q2 | E40: 1 | F40: World Wrestling Entertainment | G40: Bianca Belair, AJ Styles, The Usos, The Brawling Brutes | H40: Rupp Arena | I40: Lexington | J40: Kentucky | K40: United States | L40: 9084 | M40: 438042.5 | N40: =E40*M40 -> 438042.5 | O40: 9084 | P40: 1 | Q40: 20 | R40: 120 | S40: 48.22
...
